2024-12-12 15:07:43,281 [INFO] SB-4844: Attempting to connect.
2024-12-12 15:07:44,160 [INFO] SB-4844: Connected to Sphero.
2024-12-12 15:07:45,828 [INFO] Main: All processes started.
2024-12-12 15:07:47,334 [ERROR] WebSocket: Connection error: [WinError 1225] The remote computer refused the network connection
2024-12-12 15:07:47,335 [WARNING] WebSocket: Closing connection.
2024-12-12 15:07:47,350 [ERROR] WebSocket Sender: Connection error: [WinError 1225] The remote computer refused the network connection
2024-12-12 15:07:47,350 [WARNING] WebSocket Sender: Closing connection.
2024-12-12 15:07:49,001 [INFO] SB-4844: Calibrating compass.
2024-12-12 15:07:54,291 [INFO] SB-4844: Initialization complete.
2024-12-12 15:07:54,291 [INFO] SB-4844: Subscribed to message bus.
2024-12-12 21:43:54,218 [INFO] SB-D8B2: Attempting to connect.
2024-12-12 21:43:56,178 [INFO] SB-D8B2: Connected to Sphero.
2024-12-12 21:43:56,373 [INFO] Main: All processes started.
2024-12-12 21:43:58,262 [ERROR] WebSocket Sender: Connection error: [WinError 1225] The remote computer refused the network connection
2024-12-12 21:43:58,263 [WARNING] WebSocket Sender: Closing connection.
2024-12-12 21:43:58,309 [ERROR] WebSocket: Connection error: [WinError 1225] The remote computer refused the network connection
2024-12-12 21:43:58,310 [WARNING] WebSocket: Closing connection.
2024-12-12 21:44:01,923 [INFO] SB-D8B2: Calibrating compass.
2024-12-12 21:44:07,289 [INFO] SB-D8B2: Initialization complete.
2024-12-12 21:44:07,290 [INFO] SB-D8B2: Subscribed to message bus.
2024-12-12 22:20:54,407 [INFO] SB-D8B2: Attempting to connect.
2024-12-12 22:20:55,018 [INFO] Main: All processes started.
2024-12-12 22:20:55,633 [INFO] SB-D8B2: Connected to Sphero.
2024-12-12 22:20:58,545 [ERROR] WebSocket Sender: Connection error: [WinError 1225] The remote computer refused the network connection
2024-12-12 22:20:58,545 [WARNING] WebSocket Sender: Closing connection.
2024-12-12 22:20:58,715 [ERROR] WebSocket: Connection error: [WinError 1225] The remote computer refused the network connection
2024-12-12 22:20:58,715 [WARNING] WebSocket: Closing connection.
2024-12-12 22:21:01,119 [INFO] SB-D8B2: Calibrating compass.
2024-12-12 22:21:06,561 [INFO] SB-D8B2: Initialization complete.
2024-12-12 22:21:06,561 [INFO] SB-D8B2: Subscribed to message bus.
2024-12-12 22:22:42,254 [INFO] SB-2E86: Attempting to connect.
2024-12-12 22:22:42,458 [INFO] SB-2E86: Connected to Sphero.
2024-12-12 22:22:45,524 [INFO] SB-2E86: Calibrating compass.
2024-12-12 22:22:46,041 [INFO] SB-4844: Attempting to connect.
2024-12-12 22:22:46,353 [ERROR] WebSocket: Connection error: [WinError 1225] The remote computer refused the network connection
ction
2024-12-12 22:22:46,353 [WARNING] WebSocket Sender: Closing connection.
2024-12-12 22:22:46,353 [WARNING] WebSocket: Closing connection.
2024-12-12 22:22:46,373 [INFO] SB-4844: Connected to Sphero.
2024-12-12 22:22:49,894 [INFO] SB-7104: Attempting to connect.
2024-12-12 22:22:50,223 [INFO] SB-7104: Connected to Sphero.
2024-12-12 22:22:50,785 [INFO] SB-2E86: Initialization complete.
2024-12-12 22:22:50,785 [INFO] SB-2E86: Subscribed to message bus.
2024-12-12 22:22:52,418 [INFO] SB-4844: Calibrating compass.
2024-12-12 22:22:54,576 [INFO] SB-D8B2: Attempting to connect.
2024-12-12 22:22:55,087 [INFO] SB-D8B2: Connected to Sphero.
2024-12-12 22:22:56,881 [INFO] SB-7104: Calibrating compass.
2024-12-12 22:22:57,756 [INFO] SB-4844: Initialization complete.
2024-12-12 22:22:57,756 [INFO] SB-4844: Subscribed to message bus.
2024-12-12 22:22:58,577 [INFO] SB-E12C: Attempting to connect.
2024-12-12 22:23:00,570 [INFO] SB-E12C: Connected to Sphero.
2024-12-12 22:23:01,119 [INFO] SB-D8B2: Calibrating compass.
2024-12-12 22:23:01,634 [INFO] Main: All processes started.
2024-12-12 22:23:02,113 [INFO] SB-7104: Initialization complete.
2024-12-12 22:23:02,113 [INFO] SB-7104: Subscribed to message bus.
2024-12-12 22:23:06,415 [INFO] SB-E12C: Calibrating compass.
2024-12-12 22:23:06,624 [INFO] SB-D8B2: Initialization complete.
2024-12-12 22:23:06,628 [INFO] SB-D8B2: Subscribed to message bus.
2024-12-12 22:23:12,210 [INFO] SB-E12C: Initialization complete.
2024-12-12 22:23:12,211 [INFO] SB-E12C: Subscribed to message bus.
2024-12-12 23:26:06,827 [INFO] SB-2E86: Attempting to connect.
2024-12-12 23:26:08,346 [INFO] SB-2E86: Connected to Sphero.
2024-12-12 23:26:10,428 [INFO] Main: All processes started.
2024-12-12 23:26:10,928 [ERROR] WebSocket Sender: Connection error: [WinError 1225] The remote computer refused the network connection
2024-12-12 23:26:10,928 [WARNING] WebSocket: Closing connection.
2024-12-12 23:26:10,928 [WARNING] WebSocket Sender: Closing connection.
2024-12-12 23:26:11,417 [INFO] SB-2E86: Calibrating compass.
2024-12-12 23:26:16,683 [INFO] SB-2E86: Initialization complete.
2024-12-12 23:26:16,683 [INFO] SB-2E86: Subscribed to message bus.
2024-12-12 23:28:45,207 [INFO] SB-2E86: Attempting to connect.
2024-12-12 23:28:46,215 [INFO] SB-2E86: Connected to Sphero.
2024-12-12 23:28:49,173 [INFO] SB-4844: Attempting to connect.
2024-12-12 23:28:49,276 [ERROR] WebSocket Sender: Connection error: [WinError 1225] The remote computer refused the network connection
2024-12-12 23:28:49,276 [ERROR] WebSocket: Connection error: [WinError 1225] The remote computer refused the network connection
2024-12-12 23:28:49,277 [WARNING] WebSocket Sender: Closing connection.
2024-12-12 23:28:49,277 [WARNING] WebSocket: Closing connection.
2024-12-12 23:28:50,011 [INFO] SB-2E86: Calibrating compass.
2024-12-12 23:28:50,304 [INFO] SB-4844: Connected to Sphero.
2024-12-12 23:28:53,611 [INFO] SB-7104: Attempting to connect.
2024-12-12 23:28:53,959 [INFO] SB-4844: Calibrating compass.
2024-12-12 23:28:54,349 [INFO] SB-7104: Connected to Sphero.
2024-12-12 23:28:55,323 [INFO] SB-2E86: Initialization complete.
2024-12-12 23:28:55,323 [INFO] SB-2E86: Subscribed to message bus.
2024-12-12 23:28:58,824 [INFO] SB-D8B2: Attempting to connect.
2024-12-12 23:28:59,230 [ERROR] Exception in callback Toy.__api_read(<bleak.backen...002D1B76BAF90>)(bytearray(b'f\xc5\xd8'))
handle: <Handle Toy.__api_read(<bleak.backen...002D1B76BAF90>)(bytearray(b'f\xc5\xd8'))>
Traceback (most recent call last):
  File "C:\Python312\Lib\asyncio\events.py", line 88, in _run
    self._context.run(self._callback, *self._args)
  File "C:\Users\buiph\AppData\Roaming\Python\Python312\site-packages\spherov2\toy\__init__.py", line 106, in __api_read
    self.__decoder.add(data)
  File "C:\Users\buiph\AppData\Roaming\Python\Python312\site-packages\spherov2\controls\v2.py", line 174, in add
    self.__callback(Packet.parse_response(pkt))
                    ^^^^^^^^^^^^^^^^^^^^^^^^^^
  File "C:\Users\buiph\AppData\Roaming\Python\Python312\site-packages\spherov2\controls\v2.py", line 62, in parse_response
    raise PacketDecodingException('Unexpected start of packet')
spherov2.controls.PacketDecodingException: Unexpected start of packet
2024-12-12 23:28:59,226 [ERROR] Exception in callback Toy.__api_read(<bleak.backen...0027773DA6ED0>)(bytearray(b'C...\x99\xbc\xd8'))
handle: <Handle Toy.__api_read(<bleak.backen...0027773DA6ED0>)(bytearray(b'C...\x99\xbc\xd8'))>
Traceback (most recent call last):
  File "C:\Python312\Lib\asyncio\events.py", line 88, in _run
    self._context.run(self._callback, *self._args)
  File "C:\Users\buiph\AppData\Roaming\Python\Python312\site-packages\spherov2\toy\__init__.py", line 106, in __api_read
    self.__decoder.add(data)
  File "C:\Users\buiph\AppData\Roaming\Python\Python312\site-packages\spherov2\controls\v2.py", line 174, in add
    self.__callback(Packet.parse_response(pkt))
                    ^^^^^^^^^^^^^^^^^^^^^^^^^^
  File "C:\Users\buiph\AppData\Roaming\Python\Python312\site-packages\spherov2\controls\v2.py", line 67, in parse_response
    raise PacketDecodingException('Bad response checksum')
spherov2.controls.PacketDecodingException: Bad response checksum
2024-12-12 23:28:59,553 [INFO] SB-D8B2: Connected to Sphero.
2024-12-12 23:28:59,580 [INFO] SB-7104: Calibrating compass.
2024-12-12 23:28:59,861 [INFO] SB-4844: Initialization complete.
2024-12-12 23:28:59,862 [INFO] SB-4844: Subscribed to message bus.
2024-12-12 23:29:02,879 [INFO] SB-E12C: Attempting to connect.
2024-12-12 23:29:04,581 [INFO] Main: All processes started.
2024-12-12 23:29:04,753 [INFO] SB-D8B2: Calibrating compass.
2024-12-12 23:29:04,953 [INFO] SB-7104: Initialization complete.
2024-12-12 23:29:04,953 [INFO] SB-7104: Subscribed to message bus.
2024-12-12 23:29:07,113 [INFO] SB-E12C: Connected to Sphero.
2024-12-12 23:29:10,078 [INFO] SB-D8B2: Initialization complete.
2024-12-12 23:29:10,078 [INFO] SB-D8B2: Subscribed to message bus.
2024-12-12 23:29:12,527 [INFO] SB-E12C: Calibrating compass.
2024-12-12 23:29:18,199 [INFO] SB-E12C: Initialization complete.
2024-12-12 23:29:18,200 [INFO] SB-E12C: Subscribed to message bus.
2024-12-12 23:33:07,132 [ERROR] Exception in callback Toy.__api_read(<bleak.backen...0027773DA6ED0>)(bytearray(b'\xda\xe1M\xd8'))
handle: <Handle Toy.__api_read(<bleak.backen...0027773DA6ED0>)(bytearray(b'\xda\xe1M\xd8'))>
Traceback (most recent call last):
  File "C:\Python312\Lib\asyncio\events.py", line 88, in _run
    self._context.run(self._callback, *self._args)
  File "C:\Users\buiph\AppData\Roaming\Python\Python312\site-packages\spherov2\toy\__init__.py", line 106, in __api_read
    self.__decoder.add(data)
  File "C:\Users\buiph\AppData\Roaming\Python\Python312\site-packages\spherov2\controls\v2.py", line 174, in add
    self.__callback(Packet.parse_response(pkt))
                    ^^^^^^^^^^^^^^^^^^^^^^^^^^
  File "C:\Users\buiph\AppData\Roaming\Python\Python312\site-packages\spherov2\controls\v2.py", line 67, in parse_response
    raise PacketDecodingException('Bad response checksum')
spherov2.controls.PacketDecodingException: Bad response checksum
2024-12-12 23:33:07,133 [ERROR] Exception in callback Toy.__api_read(<bleak.backen...001B47FCE6E10>)(bytearray(b'\xd7\xd8'))
handle: <Handle Toy.__api_read(<bleak.backen...001B47FCE6E10>)(bytearray(b'\xd7\xd8'))>
Traceback (most recent call last):
  File "C:\Python312\Lib\asyncio\events.py", line 88, in _run
    self._context.run(self._callback, *self._args)
  File "C:\Users\buiph\AppData\Roaming\Python\Python312\site-packages\spherov2\toy\__init__.py", line 106, in __api_read
    self.__decoder.add(data)
  File "C:\Users\buiph\AppData\Roaming\Python\Python312\site-packages\spherov2\controls\v2.py", line 174, in add
    self.__callback(Packet.parse_response(pkt))
                    ^^^^^^^^^^^^^^^^^^^^^^^^^^
  File "C:\Users\buiph\AppData\Roaming\Python\Python312\site-packages\spherov2\controls\v2.py", line 67, in parse_response
    raise PacketDecodingException('Bad response checksum')
spherov2.controls.PacketDecodingException: Bad response checksum
2024-12-12 23:33:07,135 [ERROR] Exception in callback Toy.__api_read(<bleak.backen...00164DC99EC30>)(bytearray(b'\xac\xd8'))
handle: <Handle Toy.__api_read(<bleak.backen...00164DC99EC30>)(bytearray(b'\xac\xd8'))>
Traceback (most recent call last):
  File "C:\Python312\Lib\asyncio\events.py", line 88, in _run
    self._context.run(self._callback, *self._args)
  File "C:\Users\buiph\AppData\Roaming\Python\Python312\site-packages\spherov2\toy\__init__.py", line 106, in __api_read
    self.__decoder.add(data)
  File "C:\Users\buiph\AppData\Roaming\Python\Python312\site-packages\spherov2\controls\v2.py", line 174, in add
    self.__callback(Packet.parse_response(pkt))
                    ^^^^^^^^^^^^^^^^^^^^^^^^^^
  File "C:\Users\buiph\AppData\Roaming\Python\Python312\site-packages\spherov2\controls\v2.py", line 67, in parse_response
    raise PacketDecodingException('Bad response checksum')
spherov2.controls.PacketDecodingException: Bad response checksum
2024-12-12 23:33:07,188 [ERROR] Exception in callback Toy.__api_read(<bleak.backen...00280D665B140>)(bytearray(b'\\\xcc"\xd8'))
handle: <Handle Toy.__api_read(<bleak.backen...00280D665B140>)(bytearray(b'\\\xcc"\xd8'))>
Traceback (most recent call last):
  File "C:\Python312\Lib\asyncio\events.py", line 88, in _run
    self._context.run(self._callback, *self._args)
  File "C:\Users\buiph\AppData\Roaming\Python\Python312\site-packages\spherov2\toy\__init__.py", line 106, in __api_read
    self.__decoder.add(data)
  File "C:\Users\buiph\AppData\Roaming\Python\Python312\site-packages\spherov2\controls\v2.py", line 174, in add
    self.__callback(Packet.parse_response(pkt))
                    ^^^^^^^^^^^^^^^^^^^^^^^^^^
  File "C:\Users\buiph\AppData\Roaming\Python\Python312\site-packages\spherov2\controls\v2.py", line 67, in parse_response
    raise PacketDecodingException('Bad response checksum')
spherov2.controls.PacketDecodingException: Bad response checksum
2024-12-12 23:33:07,204 [ERROR] Exception in callback Toy.__api_read(<bleak.backen...002D1B76BAF90>)(bytearray(b':\xd8'))
handle: <Handle Toy.__api_read(<bleak.backen...002D1B76BAF90>)(bytearray(b':\xd8'))>
Traceback (most recent call last):
  File "C:\Python312\Lib\asyncio\events.py", line 88, in _run
    self._context.run(self._callback, *self._args)
  File "C:\Users\buiph\AppData\Roaming\Python\Python312\site-packages\spherov2\toy\__init__.py", line 106, in __api_read
    self.__decoder.add(data)
  File "C:\Users\buiph\AppData\Roaming\Python\Python312\site-packages\spherov2\controls\v2.py", line 174, in add
    self.__callback(Packet.parse_response(pkt))
                    ^^^^^^^^^^^^^^^^^^^^^^^^^^
  File "C:\Users\buiph\AppData\Roaming\Python\Python312\site-packages\spherov2\controls\v2.py", line 67, in parse_response
    raise PacketDecodingException('Bad response checksum')
spherov2.controls.PacketDecodingException: Bad response checksum
2024-12-12 23:35:07,036 [ERROR] Exception in callback Toy.__api_read(<bleak.backen...00280D665B140>)(bytearray(b'\\\xcc\xd7\xd8'))
handle: <Handle Toy.__api_read(<bleak.backen...00280D665B140>)(bytearray(b'\\\xcc\xd7\xd8'))>
Traceback (most recent call last):
  File "C:\Python312\Lib\asyncio\events.py", line 88, in _run
    self._context.run(self._callback, *self._args)
  File "C:\Users\buiph\AppData\Roaming\Python\Python312\site-packages\spherov2\toy\__init__.py", line 106, in __api_read
    self.__decoder.add(data)
  File "C:\Users\buiph\AppData\Roaming\Python\Python312\site-packages\spherov2\controls\v2.py", line 174, in add
    self.__callback(Packet.parse_response(pkt))
                    ^^^^^^^^^^^^^^^^^^^^^^^^^^
  File "C:\Users\buiph\AppData\Roaming\Python\Python312\site-packages\spherov2\controls\v2.py", line 67, in parse_response
    raise PacketDecodingException('Bad response checksum')
spherov2.controls.PacketDecodingException: Bad response checksum
2024-12-12 23:35:07,068 [ERROR] Exception in callback Toy.__api_read(<bleak.backen...0027773DA6ED0>)(bytearray(b'=\xb2\xd8'))
handle: <Handle Toy.__api_read(<bleak.backen...0027773DA6ED0>)(bytearray(b'=\xb2\xd8'))>
Traceback (most recent call last):
  File "C:\Python312\Lib\asyncio\events.py", line 88, in _run
    self._context.run(self._callback, *self._args)
  File "C:\Users\buiph\AppData\Roaming\Python\Python312\site-packages\spherov2\toy\__init__.py", line 106, in __api_read
    self.__decoder.add(data)
  File "C:\Users\buiph\AppData\Roaming\Python\Python312\site-packages\spherov2\controls\v2.py", line 174, in add
    self.__callback(Packet.parse_response(pkt))
                    ^^^^^^^^^^^^^^^^^^^^^^^^^^
  File "C:\Users\buiph\AppData\Roaming\Python\Python312\site-packages\spherov2\controls\v2.py", line 62, in parse_response
    raise PacketDecodingException('Unexpected start of packet')
spherov2.controls.PacketDecodingException: Unexpected start of packet
2024-12-12 23:35:07,069 [ERROR] Exception in callback Toy.__api_read(<bleak.backen...002D1B76BAF90>)(bytearray(b'x\xd8'))
handle: <Handle Toy.__api_read(<bleak.backen...002D1B76BAF90>)(bytearray(b'x\xd8'))>
Traceback (most recent call last):
  File "C:\Python312\Lib\asyncio\events.py", line 88, in _run
    self._context.run(self._callback, *self._args)
  File "C:\Users\buiph\AppData\Roaming\Python\Python312\site-packages\spherov2\toy\__init__.py", line 106, in __api_read
    self.__decoder.add(data)
  File "C:\Users\buiph\AppData\Roaming\Python\Python312\site-packages\spherov2\controls\v2.py", line 174, in add
    self.__callback(Packet.parse_response(pkt))
                    ^^^^^^^^^^^^^^^^^^^^^^^^^^
  File "C:\Users\buiph\AppData\Roaming\Python\Python312\site-packages\spherov2\controls\v2.py", line 67, in parse_response
    raise PacketDecodingException('Bad response checksum')
spherov2.controls.PacketDecodingException: Bad response checksum
2024-12-12 23:35:07,071 [ERROR] Exception in callback Toy.__api_read(<bleak.backen...0027773DA6ED0>)(bytearray(b'\x13Z=}\xd8'))
handle: <Handle Toy.__api_read(<bleak.backen...0027773DA6ED0>)(bytearray(b'\x13Z=}\xd8'))>
Traceback (most recent call last):
  File "C:\Python312\Lib\asyncio\events.py", line 88, in _run
    self._context.run(self._callback, *self._args)
  File "C:\Users\buiph\AppData\Roaming\Python\Python312\site-packages\spherov2\toy\__init__.py", line 106, in __api_read
    self.__decoder.add(data)
  File "C:\Users\buiph\AppData\Roaming\Python\Python312\site-packages\spherov2\controls\v2.py", line 174, in add
    self.__callback(Packet.parse_response(pkt))
                    ^^^^^^^^^^^^^^^^^^^^^^^^^^
  File "C:\Users\buiph\AppData\Roaming\Python\Python312\site-packages\spherov2\controls\v2.py", line 62, in parse_response
    raise PacketDecodingException('Unexpected start of packet')
spherov2.controls.PacketDecodingException: Unexpected start of packet
2024-12-12 23:35:07,079 [ERROR] Exception in callback Toy.__api_read(<bleak.backen...00280D665B140>)(bytearray(b'\...xddp\xd5\xd8'))
handle: <Handle Toy.__api_read(<bleak.backen...00280D665B140>)(bytearray(b'\...xddp\xd5\xd8'))>
Traceback (most recent call last):
  File "C:\Python312\Lib\asyncio\events.py", line 88, in _run
    self._context.run(self._callback, *self._args)
  File "C:\Users\buiph\AppData\Roaming\Python\Python312\site-packages\spherov2\toy\__init__.py", line 106, in __api_read
    self.__decoder.add(data)
  File "C:\Users\buiph\AppData\Roaming\Python\Python312\site-packages\spherov2\controls\v2.py", line 174, in add
    self.__callback(Packet.parse_response(pkt))
                    ^^^^^^^^^^^^^^^^^^^^^^^^^^
  File "C:\Users\buiph\AppData\Roaming\Python\Python312\site-packages\spherov2\controls\v2.py", line 62, in parse_response
    raise PacketDecodingException('Unexpected start of packet')
spherov2.controls.PacketDecodingException: Unexpected start of packet
2024-12-12 23:35:07,371 [ERROR] Exception in callback Toy.__api_read(<bleak.backen...00164DC99EC30>)(bytearray(b'k\xd8'))
handle: <Handle Toy.__api_read(<bleak.backen...00164DC99EC30>)(bytearray(b'k\xd8'))>
Traceback (most recent call last):
  File "C:\Python312\Lib\asyncio\events.py", line 88, in _run
    self._context.run(self._callback, *self._args)
  File "C:\Users\buiph\AppData\Roaming\Python\Python312\site-packages\spherov2\toy\__init__.py", line 106, in __api_read
    self.__decoder.add(data)
  File "C:\Users\buiph\AppData\Roaming\Python\Python312\site-packages\spherov2\controls\v2.py", line 174, in add
    self.__callback(Packet.parse_response(pkt))
                    ^^^^^^^^^^^^^^^^^^^^^^^^^^
  File "C:\Users\buiph\AppData\Roaming\Python\Python312\site-packages\spherov2\controls\v2.py", line 62, in parse_response
    raise PacketDecodingException('Unexpected start of packet')
spherov2.controls.PacketDecodingException: Unexpected start of packet
2024-12-12 23:35:12,998 [ERROR] Exception in callback Toy.__api_read(<bleak.backen...0027773DA6ED0>)(bytearray(b'\xe1\xec\xd8'))
handle: <Handle Toy.__api_read(<bleak.backen...0027773DA6ED0>)(bytearray(b'\xe1\xec\xd8'))>
Traceback (most recent call last):
  File "C:\Python312\Lib\asyncio\events.py", line 88, in _run
    self._context.run(self._callback, *self._args)
  File "C:\Users\buiph\AppData\Roaming\Python\Python312\site-packages\spherov2\toy\__init__.py", line 106, in __api_read
    self.__decoder.add(data)
  File "C:\Users\buiph\AppData\Roaming\Python\Python312\site-packages\spherov2\controls\v2.py", line 174, in add
    self.__callback(Packet.parse_response(pkt))
                    ^^^^^^^^^^^^^^^^^^^^^^^^^^
  File "C:\Users\buiph\AppData\Roaming\Python\Python312\site-packages\spherov2\controls\v2.py", line 67, in parse_response
    raise PacketDecodingException('Bad response checksum')
spherov2.controls.PacketDecodingException: Bad response checksum
2024-12-12 23:35:13,005 [ERROR] Exception in callback Toy.__api_read(<bleak.backen...0027773DA6ED0>)(bytearray(b'\x13Z=\r\xd8'))
handle: <Handle Toy.__api_read(<bleak.backen...0027773DA6ED0>)(bytearray(b'\x13Z=\r\xd8'))>
Traceback (most recent call last):
  File "C:\Python312\Lib\asyncio\events.py", line 88, in _run
    self._context.run(self._callback, *self._args)
  File "C:\Users\buiph\AppData\Roaming\Python\Python312\site-packages\spherov2\toy\__init__.py", line 106, in __api_read
    self.__decoder.add(data)
  File "C:\Users\buiph\AppData\Roaming\Python\Python312\site-packages\spherov2\controls\v2.py", line 174, in add
    self.__callback(Packet.parse_response(pkt))
                    ^^^^^^^^^^^^^^^^^^^^^^^^^^
  File "C:\Users\buiph\AppData\Roaming\Python\Python312\site-packages\spherov2\controls\v2.py", line 62, in parse_response
    raise PacketDecodingException('Unexpected start of packet')
spherov2.controls.PacketDecodingException: Unexpected start of packet
2024-12-12 23:35:13,008 [ERROR] Exception in callback Toy.__api_read(<bleak.backen...00280D665B140>)(bytearray(b'^\x14\xaa\xd8'))
handle: <Handle Toy.__api_read(<bleak.backen...00280D665B140>)(bytearray(b'^\x14\xaa\xd8'))>
Traceback (most recent call last):
  File "C:\Python312\Lib\asyncio\events.py", line 88, in _run
    self._context.run(self._callback, *self._args)
  File "C:\Users\buiph\AppData\Roaming\Python\Python312\site-packages\spherov2\toy\__init__.py", line 106, in __api_read
    self.__decoder.add(data)
  File "C:\Users\buiph\AppData\Roaming\Python\Python312\site-packages\spherov2\controls\v2.py", line 174, in add
    self.__callback(Packet.parse_response(pkt))
                    ^^^^^^^^^^^^^^^^^^^^^^^^^^
  File "C:\Users\buiph\AppData\Roaming\Python\Python312\site-packages\spherov2\controls\v2.py", line 67, in parse_response
    raise PacketDecodingException('Bad response checksum')
spherov2.controls.PacketDecodingException: Bad response checksum
2024-12-12 23:35:13,015 [ERROR] Exception in callback Toy.__api_read(<bleak.backen...00164DC99EC30>)(bytearray(b'm\xd8'))
handle: <Handle Toy.__api_read(<bleak.backen...00164DC99EC30>)(bytearray(b'm\xd8'))>
Traceback (most recent call last):
  File "C:\Python312\Lib\asyncio\events.py", line 88, in _run
    self._context.run(self._callback, *self._args)
  File "C:\Users\buiph\AppData\Roaming\Python\Python312\site-packages\spherov2\toy\__init__.py", line 106, in __api_read
    self.__decoder.add(data)
  File "C:\Users\buiph\AppData\Roaming\Python\Python312\site-packages\spherov2\controls\v2.py", line 174, in add
    self.__callback(Packet.parse_response(pkt))
                    ^^^^^^^^^^^^^^^^^^^^^^^^^^
  File "C:\Users\buiph\AppData\Roaming\Python\Python312\site-packages\spherov2\controls\v2.py", line 62, in parse_response
    raise PacketDecodingException('Unexpected start of packet')
spherov2.controls.PacketDecodingException: Unexpected start of packet
2024-12-12 23:35:13,017 [ERROR] Exception in callback Toy.__api_read(<bleak.backen...001B47FCE6E10>)(bytearray(b'\xcc\x97\xd8'))
handle: <Handle Toy.__api_read(<bleak.backen...001B47FCE6E10>)(bytearray(b'\xcc\x97\xd8'))>
Traceback (most recent call last):
  File "C:\Python312\Lib\asyncio\events.py", line 88, in _run
    self._context.run(self._callback, *self._args)
  File "C:\Users\buiph\AppData\Roaming\Python\Python312\site-packages\spherov2\toy\__init__.py", line 106, in __api_read
    self.__decoder.add(data)
  File "C:\Users\buiph\AppData\Roaming\Python\Python312\site-packages\spherov2\controls\v2.py", line 174, in add
    self.__callback(Packet.parse_response(pkt))
                    ^^^^^^^^^^^^^^^^^^^^^^^^^^
  File "C:\Users\buiph\AppData\Roaming\Python\Python312\site-packages\spherov2\controls\v2.py", line 62, in parse_response
    raise PacketDecodingException('Unexpected start of packet')
spherov2.controls.PacketDecodingException: Unexpected start of packet
2024-12-12 23:35:13,038 [ERROR] Exception in callback Toy.__api_read(<bleak.backen...002D1B76BAF90>)(bytearray(b'\xb8[\xd8'))
handle: <Handle Toy.__api_read(<bleak.backen...002D1B76BAF90>)(bytearray(b'\xb8[\xd8'))>
Traceback (most recent call last):
  File "C:\Python312\Lib\asyncio\events.py", line 88, in _run
    self._context.run(self._callback, *self._args)
  File "C:\Users\buiph\AppData\Roaming\Python\Python312\site-packages\spherov2\toy\__init__.py", line 106, in __api_read
    self.__decoder.add(data)
  File "C:\Users\buiph\AppData\Roaming\Python\Python312\site-packages\spherov2\controls\v2.py", line 174, in add
    self.__callback(Packet.parse_response(pkt))
                    ^^^^^^^^^^^^^^^^^^^^^^^^^^
  File "C:\Users\buiph\AppData\Roaming\Python\Python312\site-packages\spherov2\controls\v2.py", line 67, in parse_response
    raise PacketDecodingException('Bad response checksum')
spherov2.controls.PacketDecodingException: Bad response checksum
2024-12-12 23:35:15,433 [ERROR] Exception in callback Toy.__api_read(<bleak.backen...001B47FCE6E10>)(bytearray(b'E\xd8'))
handle: <Handle Toy.__api_read(<bleak.backen...001B47FCE6E10>)(bytearray(b'E\xd8'))>
Traceback (most recent call last):
  File "C:\Python312\Lib\asyncio\events.py", line 88, in _run
    self._context.run(self._callback, *self._args)
  File "C:\Users\buiph\AppData\Roaming\Python\Python312\site-packages\spherov2\toy\__init__.py", line 106, in __api_read
    self.__decoder.add(data)
  File "C:\Users\buiph\AppData\Roaming\Python\Python312\site-packages\spherov2\controls\v2.py", line 173, in add
    raise PacketDecodingException(f'Very small packet {[hex(x) for x in pkt]}')
spherov2.controls.PacketDecodingException: Very small packet ['0x45', '0xd8']
2024-12-12 23:35:15,592 [ERROR] Exception in callback Toy.__api_read(<bleak.backen...001B47FCE6E10>)(bytearray(b')\x88\xd8'))
handle: <Handle Toy.__api_read(<bleak.backen...001B47FCE6E10>)(bytearray(b')\x88\xd8'))>
Traceback (most recent call last):
  File "C:\Python312\Lib\asyncio\events.py", line 88, in _run
    self._context.run(self._callback, *self._args)
  File "C:\Users\buiph\AppData\Roaming\Python\Python312\site-packages\spherov2\toy\__init__.py", line 106, in __api_read
    self.__decoder.add(data)
  File "C:\Users\buiph\AppData\Roaming\Python\Python312\site-packages\spherov2\controls\v2.py", line 173, in add
    raise PacketDecodingException(f'Very small packet {[hex(x) for x in pkt]}')
spherov2.controls.PacketDecodingException: Very small packet ['0x29', '0x88', '0xd8']
2024-12-12 23:35:15,685 [ERROR] Exception in callback Toy.__api_read(<bleak.backen...001B47FCE6E10>)(bytearray(b'\x82\xd8'))
handle: <Handle Toy.__api_read(<bleak.backen...001B47FCE6E10>)(bytearray(b'\x82\xd8'))>
Traceback (most recent call last):
  File "C:\Python312\Lib\asyncio\events.py", line 88, in _run
    self._context.run(self._callback, *self._args)
  File "C:\Users\buiph\AppData\Roaming\Python\Python312\site-packages\spherov2\toy\__init__.py", line 106, in __api_read
    self.__decoder.add(data)
  File "C:\Users\buiph\AppData\Roaming\Python\Python312\site-packages\spherov2\controls\v2.py", line 173, in add
    raise PacketDecodingException(f'Very small packet {[hex(x) for x in pkt]}')
spherov2.controls.PacketDecodingException: Very small packet ['0x82', '0xd8']
2024-12-12 23:35:15,983 [ERROR] Exception in callback Toy.__api_read(<bleak.backen...001B47FCE6E10>)(bytearray(b'\x01\xd8'))
handle: <Handle Toy.__api_read(<bleak.backen...001B47FCE6E10>)(bytearray(b'\x01\xd8'))>
Traceback (most recent call last):
  File "C:\Python312\Lib\asyncio\events.py", line 88, in _run
    self._context.run(self._callback, *self._args)
  File "C:\Users\buiph\AppData\Roaming\Python\Python312\site-packages\spherov2\toy\__init__.py", line 106, in __api_read
    self.__decoder.add(data)
  File "C:\Users\buiph\AppData\Roaming\Python\Python312\site-packages\spherov2\controls\v2.py", line 173, in add
    raise PacketDecodingException(f'Very small packet {[hex(x) for x in pkt]}')
spherov2.controls.PacketDecodingException: Very small packet ['0xff', '0x1', '0xd8']
2024-12-12 23:35:16,032 [ERROR] Exception in callback Toy.__api_read(<bleak.backen...00280D665B140>)(bytearray(b'\...xddp\x8b\xd8'))
handle: <Handle Toy.__api_read(<bleak.backen...00280D665B140>)(bytearray(b'\...xddp\x8b\xd8'))>
Traceback (most recent call last):
  File "C:\Python312\Lib\asyncio\events.py", line 88, in _run
    self._context.run(self._callback, *self._args)
  File "C:\Users\buiph\AppData\Roaming\Python\Python312\site-packages\spherov2\toy\__init__.py", line 106, in __api_read
    self.__decoder.add(data)
  File "C:\Users\buiph\AppData\Roaming\Python\Python312\site-packages\spherov2\controls\v2.py", line 174, in add
    self.__callback(Packet.parse_response(pkt))
                    ^^^^^^^^^^^^^^^^^^^^^^^^^^
  File "C:\Users\buiph\AppData\Roaming\Python\Python312\site-packages\spherov2\controls\v2.py", line 67, in parse_response
    raise PacketDecodingException('Bad response checksum')
spherov2.controls.PacketDecodingException: Bad response checksum
2024-12-12 23:35:16,079 [ERROR] Exception in callback Toy.__api_read(<bleak.backen...0027773DA6ED0>)(bytearray(b'\xe1\xa1\xd8'))
handle: <Handle Toy.__api_read(<bleak.backen...0027773DA6ED0>)(bytearray(b'\xe1\xa1\xd8'))>
Traceback (most recent call last):
  File "C:\Python312\Lib\asyncio\events.py", line 88, in _run
    self._context.run(self._callback, *self._args)
  File "C:\Users\buiph\AppData\Roaming\Python\Python312\site-packages\spherov2\toy\__init__.py", line 106, in __api_read
    self.__decoder.add(data)
  File "C:\Users\buiph\AppData\Roaming\Python\Python312\site-packages\spherov2\controls\v2.py", line 174, in add
    self.__callback(Packet.parse_response(pkt))
                    ^^^^^^^^^^^^^^^^^^^^^^^^^^
  File "C:\Users\buiph\AppData\Roaming\Python\Python312\site-packages\spherov2\controls\v2.py", line 67, in parse_response
    raise PacketDecodingException('Bad response checksum')
spherov2.controls.PacketDecodingException: Bad response checksum
2024-12-12 23:35:16,168 [ERROR] Exception in callback Toy.__api_read(<bleak.backen...001B47FCE6E10>)(bytearray(b'\xf0\xd8'))
handle: <Handle Toy.__api_read(<bleak.backen...001B47FCE6E10>)(bytearray(b'\xf0\xd8'))>
Traceback (most recent call last):
  File "C:\Python312\Lib\asyncio\events.py", line 88, in _run
    self._context.run(self._callback, *self._args)
  File "C:\Users\buiph\AppData\Roaming\Python\Python312\site-packages\spherov2\toy\__init__.py", line 106, in __api_read
    self.__decoder.add(data)
  File "C:\Users\buiph\AppData\Roaming\Python\Python312\site-packages\spherov2\controls\v2.py", line 174, in add
    self.__callback(Packet.parse_response(pkt))
                    ^^^^^^^^^^^^^^^^^^^^^^^^^^
  File "C:\Users\buiph\AppData\Roaming\Python\Python312\site-packages\spherov2\controls\v2.py", line 62, in parse_response
    raise PacketDecodingException('Unexpected start of packet')
spherov2.controls.PacketDecodingException: Unexpected start of packet
2024-12-12 23:35:16,197 [ERROR] Exception in callback Toy.__api_read(<bleak.backen...0027773DA6ED0>)(bytearray(b'C...da\xe1\t\xd8'))
handle: <Handle Toy.__api_read(<bleak.backen...0027773DA6ED0>)(bytearray(b'C...da\xe1\t\xd8'))>
Traceback (most recent call last):
  File "C:\Python312\Lib\asyncio\events.py", line 88, in _run
    self._context.run(self._callback, *self._args)
  File "C:\Users\buiph\AppData\Roaming\Python\Python312\site-packages\spherov2\toy\__init__.py", line 106, in __api_read
    self.__decoder.add(data)
  File "C:\Users\buiph\AppData\Roaming\Python\Python312\site-packages\spherov2\controls\v2.py", line 174, in add
    self.__callback(Packet.parse_response(pkt))
                    ^^^^^^^^^^^^^^^^^^^^^^^^^^
  File "C:\Users\buiph\AppData\Roaming\Python\Python312\site-packages\spherov2\controls\v2.py", line 67, in parse_response
    raise PacketDecodingException('Bad response checksum')
spherov2.controls.PacketDecodingException: Bad response checksum
2024-12-12 23:35:16,214 [ERROR] Exception in callback Toy.__api_read(<bleak.backen...00164DC99EC30>)(bytearray(b'\xd5\xd8'))
handle: <Handle Toy.__api_read(<bleak.backen...00164DC99EC30>)(bytearray(b'\xd5\xd8'))>
Traceback (most recent call last):
  File "C:\Python312\Lib\asyncio\events.py", line 88, in _run
    self._context.run(self._callback, *self._args)
  File "C:\Users\buiph\AppData\Roaming\Python\Python312\site-packages\spherov2\toy\__init__.py", line 106, in __api_read
    self.__decoder.add(data)
  File "C:\Users\buiph\AppData\Roaming\Python\Python312\site-packages\spherov2\controls\v2.py", line 174, in add
    self.__callback(Packet.parse_response(pkt))
                    ^^^^^^^^^^^^^^^^^^^^^^^^^^
  File "C:\Users\buiph\AppData\Roaming\Python\Python312\site-packages\spherov2\controls\v2.py", line 67, in parse_response
    raise PacketDecodingException('Bad response checksum')
spherov2.controls.PacketDecodingException: Bad response checksum
2024-12-12 23:35:16,237 [ERROR] Exception in callback Toy.__api_read(<bleak.backen...0027773DA6ED0>)(bytearray(b'=\xec\xd8'))
handle: <Handle Toy.__api_read(<bleak.backen...0027773DA6ED0>)(bytearray(b'=\xec\xd8'))>
Traceback (most recent call last):
  File "C:\Python312\Lib\asyncio\events.py", line 88, in _run
    self._context.run(self._callback, *self._args)
  File "C:\Users\buiph\AppData\Roaming\Python\Python312\site-packages\spherov2\toy\__init__.py", line 106, in __api_read
    self.__decoder.add(data)
  File "C:\Users\buiph\AppData\Roaming\Python\Python312\site-packages\spherov2\controls\v2.py", line 174, in add
    self.__callback(Packet.parse_response(pkt))
                    ^^^^^^^^^^^^^^^^^^^^^^^^^^
  File "C:\Users\buiph\AppData\Roaming\Python\Python312\site-packages\spherov2\controls\v2.py", line 62, in parse_response
    raise PacketDecodingException('Unexpected start of packet')
spherov2.controls.PacketDecodingException: Unexpected start of packet
2024-12-12 23:35:16,272 [ERROR] Exception in callback Toy.__api_read(<bleak.backen...00164DC99EC30>)(bytearray(b'\xb9\xd8'))
handle: <Handle Toy.__api_read(<bleak.backen...00164DC99EC30>)(bytearray(b'\xb9\xd8'))>
Traceback (most recent call last):
  File "C:\Python312\Lib\asyncio\events.py", line 88, in _run
    self._context.run(self._callback, *self._args)
  File "C:\Users\buiph\AppData\Roaming\Python\Python312\site-packages\spherov2\toy\__init__.py", line 106, in __api_read
    self.__decoder.add(data)
  File "C:\Users\buiph\AppData\Roaming\Python\Python312\site-packages\spherov2\controls\v2.py", line 174, in add
    self.__callback(Packet.parse_response(pkt))
                    ^^^^^^^^^^^^^^^^^^^^^^^^^^
  File "C:\Users\buiph\AppData\Roaming\Python\Python312\site-packages\spherov2\controls\v2.py", line 62, in parse_response
    raise PacketDecodingException('Unexpected start of packet')
spherov2.controls.PacketDecodingException: Unexpected start of packet
2024-12-12 23:35:16,401 [ERROR] Exception in callback Toy.__api_read(<bleak.backen...0027773DA6ED0>)(bytearray(b'Z=y\xd8'))
handle: <Handle Toy.__api_read(<bleak.backen...0027773DA6ED0>)(bytearray(b'Z=y\xd8'))>
Traceback (most recent call last):
  File "C:\Python312\Lib\asyncio\events.py", line 88, in _run
    self._context.run(self._callback, *self._args)
  File "C:\Users\buiph\AppData\Roaming\Python\Python312\site-packages\spherov2\toy\__init__.py", line 106, in __api_read
    self.__decoder.add(data)
  File "C:\Users\buiph\AppData\Roaming\Python\Python312\site-packages\spherov2\controls\v2.py", line 174, in add
    self.__callback(Packet.parse_response(pkt))
                    ^^^^^^^^^^^^^^^^^^^^^^^^^^
  File "C:\Users\buiph\AppData\Roaming\Python\Python312\site-packages\spherov2\controls\v2.py", line 67, in parse_response
    raise PacketDecodingException('Bad response checksum')
spherov2.controls.PacketDecodingException: Bad response checksum
2024-12-12 23:35:16,455 [ERROR] Exception in callback Toy.__api_read(<bleak.backen...00280D665B140>)(bytearray(b'^\x141\xd8'))
handle: <Handle Toy.__api_read(<bleak.backen...00280D665B140>)(bytearray(b'^\x141\xd8'))>
Traceback (most recent call last):
  File "C:\Python312\Lib\asyncio\events.py", line 88, in _run
    self._context.run(self._callback, *self._args)
  File "C:\Users\buiph\AppData\Roaming\Python\Python312\site-packages\spherov2\toy\__init__.py", line 106, in __api_read
    self.__decoder.add(data)
  File "C:\Users\buiph\AppData\Roaming\Python\Python312\site-packages\spherov2\controls\v2.py", line 174, in add
    self.__callback(Packet.parse_response(pkt))
                    ^^^^^^^^^^^^^^^^^^^^^^^^^^
  File "C:\Users\buiph\AppData\Roaming\Python\Python312\site-packages\spherov2\controls\v2.py", line 67, in parse_response
    raise PacketDecodingException('Bad response checksum')
spherov2.controls.PacketDecodingException: Bad response checksum
2024-12-12 23:35:16,650 [ERROR] Exception in callback Toy.__api_read(<bleak.backen...00164DC99EC30>)(bytearray(b'N\xd8'))
handle: <Handle Toy.__api_read(<bleak.backen...00164DC99EC30>)(bytearray(b'N\xd8'))>
Traceback (most recent call last):
  File "C:\Python312\Lib\asyncio\events.py", line 88, in _run
    self._context.run(self._callback, *self._args)
  File "C:\Users\buiph\AppData\Roaming\Python\Python312\site-packages\spherov2\toy\__init__.py", line 106, in __api_read
    self.__decoder.add(data)
  File "C:\Users\buiph\AppData\Roaming\Python\Python312\site-packages\spherov2\controls\v2.py", line 174, in add
    self.__callback(Packet.parse_response(pkt))
                    ^^^^^^^^^^^^^^^^^^^^^^^^^^
  File "C:\Users\buiph\AppData\Roaming\Python\Python312\site-packages\spherov2\controls\v2.py", line 62, in parse_response
    raise PacketDecodingException('Unexpected start of packet')
spherov2.controls.PacketDecodingException: Unexpected start of packet
2024-12-12 23:35:16,700 [ERROR] Exception in callback Toy.__api_read(<bleak.backen...0027773DA6ED0>)(bytearray(b'Z=\x81\xd8'))
handle: <Handle Toy.__api_read(<bleak.backen...0027773DA6ED0>)(bytearray(b'Z=\x81\xd8'))>
Traceback (most recent call last):
  File "C:\Python312\Lib\asyncio\events.py", line 88, in _run
    self._context.run(self._callback, *self._args)
  File "C:\Users\buiph\AppData\Roaming\Python\Python312\site-packages\spherov2\toy\__init__.py", line 106, in __api_read
    self.__decoder.add(data)
  File "C:\Users\buiph\AppData\Roaming\Python\Python312\site-packages\spherov2\controls\v2.py", line 174, in add
    self.__callback(Packet.parse_response(pkt))
                    ^^^^^^^^^^^^^^^^^^^^^^^^^^
  File "C:\Users\buiph\AppData\Roaming\Python\Python312\site-packages\spherov2\controls\v2.py", line 62, in parse_response
    raise PacketDecodingException('Unexpected start of packet')
spherov2.controls.PacketDecodingException: Unexpected start of packet
2024-12-12 23:35:16,709 [ERROR] Exception in callback Toy.__api_read(<bleak.backen...001B47FCE6E10>)(bytearray(b'x\xd8'))
handle: <Handle Toy.__api_read(<bleak.backen...001B47FCE6E10>)(bytearray(b'x\xd8'))>
Traceback (most recent call last):
  File "C:\Python312\Lib\asyncio\events.py", line 88, in _run
    self._context.run(self._callback, *self._args)
  File "C:\Users\buiph\AppData\Roaming\Python\Python312\site-packages\spherov2\toy\__init__.py", line 106, in __api_read
    self.__decoder.add(data)
  File "C:\Users\buiph\AppData\Roaming\Python\Python312\site-packages\spherov2\controls\v2.py", line 174, in add
    self.__callback(Packet.parse_response(pkt))
                    ^^^^^^^^^^^^^^^^^^^^^^^^^^
  File "C:\Users\buiph\AppData\Roaming\Python\Python312\site-packages\spherov2\controls\v2.py", line 62, in parse_response
    raise PacketDecodingException('Unexpected start of packet')
spherov2.controls.PacketDecodingException: Unexpected start of packet
2024-12-12 23:35:16,731 [ERROR] Exception in callback Toy.__api_read(<bleak.backen...001B47FCE6E10>)(bytearray(b'g\xd8'))
handle: <Handle Toy.__api_read(<bleak.backen...001B47FCE6E10>)(bytearray(b'g\xd8'))>
Traceback (most recent call last):
  File "C:\Python312\Lib\asyncio\events.py", line 88, in _run
    self._context.run(self._callback, *self._args)
  File "C:\Users\buiph\AppData\Roaming\Python\Python312\site-packages\spherov2\toy\__init__.py", line 106, in __api_read
    self.__decoder.add(data)
  File "C:\Users\buiph\AppData\Roaming\Python\Python312\site-packages\spherov2\controls\v2.py", line 173, in add
    raise PacketDecodingException(f'Very small packet {[hex(x) for x in pkt]}')
spherov2.controls.PacketDecodingException: Very small packet ['0x67', '0xd8']
2024-12-12 23:35:16,776 [ERROR] Exception in callback Toy.__api_read(<bleak.backen...0027773DA6ED0>)(bytearray(b'\...xda\xe1t\xd8'))
handle: <Handle Toy.__api_read(<bleak.backen...0027773DA6ED0>)(bytearray(b'\...xda\xe1t\xd8'))>
Traceback (most recent call last):
  File "C:\Python312\Lib\asyncio\events.py", line 88, in _run
    self._context.run(self._callback, *self._args)
  File "C:\Users\buiph\AppData\Roaming\Python\Python312\site-packages\spherov2\toy\__init__.py", line 106, in __api_read
    self.__decoder.add(data)
  File "C:\Users\buiph\AppData\Roaming\Python\Python312\site-packages\spherov2\controls\v2.py", line 174, in add
    self.__callback(Packet.parse_response(pkt))
                    ^^^^^^^^^^^^^^^^^^^^^^^^^^
  File "C:\Users\buiph\AppData\Roaming\Python\Python312\site-packages\spherov2\controls\v2.py", line 62, in parse_response
    raise PacketDecodingException('Unexpected start of packet')
spherov2.controls.PacketDecodingException: Unexpected start of packet
2024-12-12 23:35:17,028 [ERROR] Exception in callback Toy.__api_read(<bleak.backen...00164DC99EC30>)(bytearray(b'\xfe\xd8'))
handle: <Handle Toy.__api_read(<bleak.backen...00164DC99EC30>)(bytearray(b'\xfe\xd8'))>
Traceback (most recent call last):
  File "C:\Python312\Lib\asyncio\events.py", line 88, in _run
    self._context.run(self._callback, *self._args)
  File "C:\Users\buiph\AppData\Roaming\Python\Python312\site-packages\spherov2\toy\__init__.py", line 106, in __api_read
    self.__decoder.add(data)
  File "C:\Users\buiph\AppData\Roaming\Python\Python312\site-packages\spherov2\controls\v2.py", line 174, in add
    self.__callback(Packet.parse_response(pkt))
                    ^^^^^^^^^^^^^^^^^^^^^^^^^^
  File "C:\Users\buiph\AppData\Roaming\Python\Python312\site-packages\spherov2\controls\v2.py", line 62, in parse_response
    raise PacketDecodingException('Unexpected start of packet')
spherov2.controls.PacketDecodingException: Unexpected start of packet
2024-12-12 23:35:17,159 [ERROR] Exception in callback Toy.__api_read(<bleak.backen...0027773DA6ED0>)(bytearray(b'\xe1\x8a\xd8'))
handle: <Handle Toy.__api_read(<bleak.backen...0027773DA6ED0>)(bytearray(b'\xe1\x8a\xd8'))>
Traceback (most recent call last):
  File "C:\Python312\Lib\asyncio\events.py", line 88, in _run
    self._context.run(self._callback, *self._args)
  File "C:\Users\buiph\AppData\Roaming\Python\Python312\site-packages\spherov2\toy\__init__.py", line 106, in __api_read
    self.__decoder.add(data)
  File "C:\Users\buiph\AppData\Roaming\Python\Python312\site-packages\spherov2\controls\v2.py", line 174, in add
    self.__callback(Packet.parse_response(pkt))
                    ^^^^^^^^^^^^^^^^^^^^^^^^^^
  File "C:\Users\buiph\AppData\Roaming\Python\Python312\site-packages\spherov2\controls\v2.py", line 67, in parse_response
    raise PacketDecodingException('Bad response checksum')
spherov2.controls.PacketDecodingException: Bad response checksum
2024-12-12 23:35:17,252 [ERROR] Exception in callback Toy.__api_read(<bleak.backen...001B47FCE6E10>)(bytearray(b'\x96\xd8'))
handle: <Handle Toy.__api_read(<bleak.backen...001B47FCE6E10>)(bytearray(b'\x96\xd8'))>
Traceback (most recent call last):
  File "C:\Python312\Lib\asyncio\events.py", line 88, in _run
    self._context.run(self._callback, *self._args)
  File "C:\Users\buiph\AppData\Roaming\Python\Python312\site-packages\spherov2\toy\__init__.py", line 106, in __api_read
    self.__decoder.add(data)
  File "C:\Users\buiph\AppData\Roaming\Python\Python312\site-packages\spherov2\controls\v2.py", line 174, in add
    self.__callback(Packet.parse_response(pkt))
                    ^^^^^^^^^^^^^^^^^^^^^^^^^^
  File "C:\Users\buiph\AppData\Roaming\Python\Python312\site-packages\spherov2\controls\v2.py", line 62, in parse_response
    raise PacketDecodingException('Unexpected start of packet')
spherov2.controls.PacketDecodingException: Unexpected start of packet
2024-12-12 23:35:17,265 [ERROR] Exception in callback Toy.__api_read(<bleak.backen...0027773DA6ED0>)(bytearray(b'\xda\xe15\xd8'))
handle: <Handle Toy.__api_read(<bleak.backen...0027773DA6ED0>)(bytearray(b'\xda\xe15\xd8'))>
Traceback (most recent call last):
  File "C:\Python312\Lib\asyncio\events.py", line 88, in _run
    self._context.run(self._callback, *self._args)
  File "C:\Users\buiph\AppData\Roaming\Python\Python312\site-packages\spherov2\toy\__init__.py", line 106, in __api_read
    self.__decoder.add(data)
  File "C:\Users\buiph\AppData\Roaming\Python\Python312\site-packages\spherov2\controls\v2.py", line 174, in add
    self.__callback(Packet.parse_response(pkt))
                    ^^^^^^^^^^^^^^^^^^^^^^^^^^
  File "C:\Users\buiph\AppData\Roaming\Python\Python312\site-packages\spherov2\controls\v2.py", line 67, in parse_response
    raise PacketDecodingException('Bad response checksum')
spherov2.controls.PacketDecodingException: Bad response checksum
2024-12-12 23:35:17,346 [ERROR] Exception in callback Toy.__api_read(<bleak.backen...001B47FCE6E10>)(bytearray(b'\...xdc)\xe2\xd8'))
handle: <Handle Toy.__api_read(<bleak.backen...001B47FCE6E10>)(bytearray(b'\...xdc)\xe2\xd8'))>
Traceback (most recent call last):
  File "C:\Python312\Lib\asyncio\events.py", line 88, in _run
    self._context.run(self._callback, *self._args)
  File "C:\Users\buiph\AppData\Roaming\Python\Python312\site-packages\spherov2\toy\__init__.py", line 106, in __api_read
    self.__decoder.add(data)
  File "C:\Users\buiph\AppData\Roaming\Python\Python312\site-packages\spherov2\controls\v2.py", line 174, in add
    self.__callback(Packet.parse_response(pkt))
                    ^^^^^^^^^^^^^^^^^^^^^^^^^^
  File "C:\Users\buiph\AppData\Roaming\Python\Python312\site-packages\spherov2\controls\v2.py", line 62, in parse_response
    raise PacketDecodingException('Unexpected start of packet')
spherov2.controls.PacketDecodingException: Unexpected start of packet
2024-12-12 23:35:17,382 [ERROR] Exception in callback Toy.__api_read(<bleak.backen...0027773DA6ED0>)(bytearray(b'\xda\xe1\xbd\xd8'))
handle: <Handle Toy.__api_read(<bleak.backen...0027773DA6ED0>)(bytearray(b'\xda\xe1\xbd\xd8'))>
Traceback (most recent call last):
  File "C:\Python312\Lib\asyncio\events.py", line 88, in _run
    self._context.run(self._callback, *self._args)
  File "C:\Users\buiph\AppData\Roaming\Python\Python312\site-packages\spherov2\toy\__init__.py", line 106, in __api_read
    self.__decoder.add(data)
  File "C:\Users\buiph\AppData\Roaming\Python\Python312\site-packages\spherov2\controls\v2.py", line 174, in add
    self.__callback(Packet.parse_response(pkt))
                    ^^^^^^^^^^^^^^^^^^^^^^^^^^
  File "C:\Users\buiph\AppData\Roaming\Python\Python312\site-packages\spherov2\controls\v2.py", line 62, in parse_response
    raise PacketDecodingException('Unexpected start of packet')
spherov2.controls.PacketDecodingException: Unexpected start of packet
2024-12-12 23:35:17,386 [ERROR] Exception in callback Toy.__api_read(<bleak.backen...00280D665B140>)(bytearray(b'\...xddp\x0e\xd8'))
handle: <Handle Toy.__api_read(<bleak.backen...00280D665B140>)(bytearray(b'\...xddp\x0e\xd8'))>
Traceback (most recent call last):
  File "C:\Python312\Lib\asyncio\events.py", line 88, in _run
    self._context.run(self._callback, *self._args)
  File "C:\Users\buiph\AppData\Roaming\Python\Python312\site-packages\spherov2\toy\__init__.py", line 106, in __api_read
    self.__decoder.add(data)
  File "C:\Users\buiph\AppData\Roaming\Python\Python312\site-packages\spherov2\controls\v2.py", line 174, in add
    self.__callback(Packet.parse_response(pkt))
                    ^^^^^^^^^^^^^^^^^^^^^^^^^^
  File "C:\Users\buiph\AppData\Roaming\Python\Python312\site-packages\spherov2\controls\v2.py", line 62, in parse_response
    raise PacketDecodingException('Unexpected start of packet')
spherov2.controls.PacketDecodingException: Unexpected start of packet
2024-12-12 23:35:17,397 [ERROR] Exception in callback Toy.__api_read(<bleak.backen...002D1B76BAF90>)(bytearray(b'\xe7\xd8'))
handle: <Handle Toy.__api_read(<bleak.backen...002D1B76BAF90>)(bytearray(b'\xe7\xd8'))>
Traceback (most recent call last):
  File "C:\Python312\Lib\asyncio\events.py", line 88, in _run
    self._context.run(self._callback, *self._args)
  File "C:\Users\buiph\AppData\Roaming\Python\Python312\site-packages\spherov2\toy\__init__.py", line 106, in __api_read
    self.__decoder.add(data)
  File "C:\Users\buiph\AppData\Roaming\Python\Python312\site-packages\spherov2\controls\v2.py", line 174, in add
    self.__callback(Packet.parse_response(pkt))
                    ^^^^^^^^^^^^^^^^^^^^^^^^^^
  File "C:\Users\buiph\AppData\Roaming\Python\Python312\site-packages\spherov2\controls\v2.py", line 67, in parse_response
    raise PacketDecodingException('Bad response checksum')
spherov2.controls.PacketDecodingException: Bad response checksum
2024-12-12 23:35:17,429 [ERROR] Exception in callback Toy.__api_read(<bleak.backen...00164DC99EC30>)(bytearray(b'C...\x85\x8b\xd8'))
handle: <Handle Toy.__api_read(<bleak.backen...00164DC99EC30>)(bytearray(b'C...\x85\x8b\xd8'))>
Traceback (most recent call last):
  File "C:\Python312\Lib\asyncio\events.py", line 88, in _run
    self._context.run(self._callback, *self._args)
  File "C:\Users\buiph\AppData\Roaming\Python\Python312\site-packages\spherov2\toy\__init__.py", line 106, in __api_read
    self.__decoder.add(data)
  File "C:\Users\buiph\AppData\Roaming\Python\Python312\site-packages\spherov2\controls\v2.py", line 174, in add
    self.__callback(Packet.parse_response(pkt))
                    ^^^^^^^^^^^^^^^^^^^^^^^^^^
  File "C:\Users\buiph\AppData\Roaming\Python\Python312\site-packages\spherov2\controls\v2.py", line 62, in parse_response
    raise PacketDecodingException('Unexpected start of packet')
spherov2.controls.PacketDecodingException: Unexpected start of packet
2024-12-12 23:35:17,444 [ERROR] Exception in callback Toy.__api_read(<bleak.backen...001B47FCE6E10>)(bytearray(b'i\xd8'))
handle: <Handle Toy.__api_read(<bleak.backen...001B47FCE6E10>)(bytearray(b'i\xd8'))>
Traceback (most recent call last):
  File "C:\Python312\Lib\asyncio\events.py", line 88, in _run
    self._context.run(self._callback, *self._args)
  File "C:\Users\buiph\AppData\Roaming\Python\Python312\site-packages\spherov2\toy\__init__.py", line 106, in __api_read
    self.__decoder.add(data)
  File "C:\Users\buiph\AppData\Roaming\Python\Python312\site-packages\spherov2\controls\v2.py", line 174, in add
    self.__callback(Packet.parse_response(pkt))
                    ^^^^^^^^^^^^^^^^^^^^^^^^^^
  File "C:\Users\buiph\AppData\Roaming\Python\Python312\site-packages\spherov2\controls\v2.py", line 67, in parse_response
    raise PacketDecodingException('Bad response checksum')
spherov2.controls.PacketDecodingException: Bad response checksum
2024-12-12 23:35:17,495 [ERROR] Exception in callback Toy.__api_read(<bleak.backen...00280D665B140>)(bytearray(b'\xddpS\xd8'))
handle: <Handle Toy.__api_read(<bleak.backen...00280D665B140>)(bytearray(b'\xddpS\xd8'))>
Traceback (most recent call last):
  File "C:\Python312\Lib\asyncio\events.py", line 88, in _run
    self._context.run(self._callback, *self._args)
  File "C:\Users\buiph\AppData\Roaming\Python\Python312\site-packages\spherov2\toy\__init__.py", line 106, in __api_read
    self.__decoder.add(data)
  File "C:\Users\buiph\AppData\Roaming\Python\Python312\site-packages\spherov2\controls\v2.py", line 174, in add
    self.__callback(Packet.parse_response(pkt))
                    ^^^^^^^^^^^^^^^^^^^^^^^^^^
  File "C:\Users\buiph\AppData\Roaming\Python\Python312\site-packages\spherov2\controls\v2.py", line 62, in parse_response
    raise PacketDecodingException('Unexpected start of packet')
spherov2.controls.PacketDecodingException: Unexpected start of packet
2024-12-12 23:35:17,532 [ERROR] Exception in callback Toy.__api_read(<bleak.backen...0027773DA6ED0>)(bytearray(b'\xd9\x99C\xd8'))
handle: <Handle Toy.__api_read(<bleak.backen...0027773DA6ED0>)(bytearray(b'\xd9\x99C\xd8'))>
Traceback (most recent call last):
  File "C:\Python312\Lib\asyncio\events.py", line 88, in _run
    self._context.run(self._callback, *self._args)
  File "C:\Users\buiph\AppData\Roaming\Python\Python312\site-packages\spherov2\toy\__init__.py", line 106, in __api_read
    self.__decoder.add(data)
  File "C:\Users\buiph\AppData\Roaming\Python\Python312\site-packages\spherov2\controls\v2.py", line 174, in add
    self.__callback(Packet.parse_response(pkt))
                    ^^^^^^^^^^^^^^^^^^^^^^^^^^
  File "C:\Users\buiph\AppData\Roaming\Python\Python312\site-packages\spherov2\controls\v2.py", line 67, in parse_response
    raise PacketDecodingException('Bad response checksum')
spherov2.controls.PacketDecodingException: Bad response checksum
2024-12-12 23:35:17,574 [ERROR] Exception in callback Toy.__api_read(<bleak.backen...001B47FCE6E10>)(bytearray(b')I\xd8'))
handle: <Handle Toy.__api_read(<bleak.backen...001B47FCE6E10>)(bytearray(b')I\xd8'))>
Traceback (most recent call last):
  File "C:\Python312\Lib\asyncio\events.py", line 88, in _run
    self._context.run(self._callback, *self._args)
  File "C:\Users\buiph\AppData\Roaming\Python\Python312\site-packages\spherov2\toy\__init__.py", line 106, in __api_read
    self.__decoder.add(data)
  File "C:\Users\buiph\AppData\Roaming\Python\Python312\site-packages\spherov2\controls\v2.py", line 173, in add
    raise PacketDecodingException(f'Very small packet {[hex(x) for x in pkt]}')
spherov2.controls.PacketDecodingException: Very small packet ['0x29', '0x49', '0xd8']
2024-12-12 23:35:17,620 [ERROR] Exception in callback Toy.__api_read(<bleak.backen...00280D665B140>)(bytearray(b'\xdc)\xfa\xd8'))
handle: <Handle Toy.__api_read(<bleak.backen...00280D665B140>)(bytearray(b'\xdc)\xfa\xd8'))>
Traceback (most recent call last):
  File "C:\Python312\Lib\asyncio\events.py", line 88, in _run
    self._context.run(self._callback, *self._args)
  File "C:\Users\buiph\AppData\Roaming\Python\Python312\site-packages\spherov2\toy\__init__.py", line 106, in __api_read
    self.__decoder.add(data)
  File "C:\Users\buiph\AppData\Roaming\Python\Python312\site-packages\spherov2\controls\v2.py", line 174, in add
    self.__callback(Packet.parse_response(pkt))
                    ^^^^^^^^^^^^^^^^^^^^^^^^^^
  File "C:\Users\buiph\AppData\Roaming\Python\Python312\site-packages\spherov2\controls\v2.py", line 62, in parse_response
    raise PacketDecodingException('Unexpected start of packet')
spherov2.controls.PacketDecodingException: Unexpected start of packet
2024-12-12 23:35:17,623 [ERROR] Exception in callback Toy.__api_read(<bleak.backen...0027773DA6ED0>)(bytearray(b'\xd9\x99\xe0\xd8'))
handle: <Handle Toy.__api_read(<bleak.backen...0027773DA6ED0>)(bytearray(b'\xd9\x99\xe0\xd8'))>
Traceback (most recent call last):
  File "C:\Python312\Lib\asyncio\events.py", line 88, in _run
    self._context.run(self._callback, *self._args)
  File "C:\Users\buiph\AppData\Roaming\Python\Python312\site-packages\spherov2\toy\__init__.py", line 106, in __api_read
    self.__decoder.add(data)
  File "C:\Users\buiph\AppData\Roaming\Python\Python312\site-packages\spherov2\controls\v2.py", line 174, in add
    self.__callback(Packet.parse_response(pkt))
                    ^^^^^^^^^^^^^^^^^^^^^^^^^^
  File "C:\Users\buiph\AppData\Roaming\Python\Python312\site-packages\spherov2\controls\v2.py", line 62, in parse_response
    raise PacketDecodingException('Unexpected start of packet')
spherov2.controls.PacketDecodingException: Unexpected start of packet
2024-12-12 23:35:17,640 [ERROR] Exception in callback Toy.__api_read(<bleak.backen...002D1B76BAF90>)(bytearray(b'\xb8v\xd8'))
handle: <Handle Toy.__api_read(<bleak.backen...002D1B76BAF90>)(bytearray(b'\xb8v\xd8'))>
Traceback (most recent call last):
  File "C:\Python312\Lib\asyncio\events.py", line 88, in _run
    self._context.run(self._callback, *self._args)
  File "C:\Users\buiph\AppData\Roaming\Python\Python312\site-packages\spherov2\toy\__init__.py", line 106, in __api_read
    self.__decoder.add(data)
  File "C:\Users\buiph\AppData\Roaming\Python\Python312\site-packages\spherov2\controls\v2.py", line 174, in add
    self.__callback(Packet.parse_response(pkt))
                    ^^^^^^^^^^^^^^^^^^^^^^^^^^
  File "C:\Users\buiph\AppData\Roaming\Python\Python312\site-packages\spherov2\controls\v2.py", line 67, in parse_response
    raise PacketDecodingException('Bad response checksum')
spherov2.controls.PacketDecodingException: Bad response checksum
2024-12-12 23:35:17,726 [ERROR] Exception in callback Toy.__api_read(<bleak.backen...001B47FCE6E10>)(bytearray(b'e\xd8'))
handle: <Handle Toy.__api_read(<bleak.backen...001B47FCE6E10>)(bytearray(b'e\xd8'))>
Traceback (most recent call last):
  File "C:\Python312\Lib\asyncio\events.py", line 88, in _run
    self._context.run(self._callback, *self._args)
  File "C:\Users\buiph\AppData\Roaming\Python\Python312\site-packages\spherov2\toy\__init__.py", line 106, in __api_read
    self.__decoder.add(data)
  File "C:\Users\buiph\AppData\Roaming\Python\Python312\site-packages\spherov2\controls\v2.py", line 173, in add
    raise PacketDecodingException(f'Very small packet {[hex(x) for x in pkt]}')
spherov2.controls.PacketDecodingException: Very small packet ['0x65', '0xd8']
2024-12-12 23:35:17,882 [ERROR] Exception in callback Toy.__api_read(<bleak.backen...0027773DA6ED0>)(bytearray(b'\xda\xe1\x99\xd8'))
handle: <Handle Toy.__api_read(<bleak.backen...0027773DA6ED0>)(bytearray(b'\xda\xe1\x99\xd8'))>
Traceback (most recent call last):
  File "C:\Python312\Lib\asyncio\events.py", line 88, in _run
    self._context.run(self._callback, *self._args)
  File "C:\Users\buiph\AppData\Roaming\Python\Python312\site-packages\spherov2\toy\__init__.py", line 106, in __api_read
    self.__decoder.add(data)
  File "C:\Users\buiph\AppData\Roaming\Python\Python312\site-packages\spherov2\controls\v2.py", line 174, in add
    self.__callback(Packet.parse_response(pkt))
                    ^^^^^^^^^^^^^^^^^^^^^^^^^^
  File "C:\Users\buiph\AppData\Roaming\Python\Python312\site-packages\spherov2\controls\v2.py", line 67, in parse_response
    raise PacketDecodingException('Bad response checksum')
spherov2.controls.PacketDecodingException: Bad response checksum
2024-12-12 23:35:17,923 [ERROR] Exception in callback Toy.__api_read(<bleak.backen...00280D665B140>)(bytearray(b'\...xddp\xe8\xd8'))
handle: <Handle Toy.__api_read(<bleak.backen...00280D665B140>)(bytearray(b'\...xddp\xe8\xd8'))>
Traceback (most recent call last):
  File "C:\Python312\Lib\asyncio\events.py", line 88, in _run
    self._context.run(self._callback, *self._args)
  File "C:\Users\buiph\AppData\Roaming\Python\Python312\site-packages\spherov2\toy\__init__.py", line 106, in __api_read
    self.__decoder.add(data)
  File "C:\Users\buiph\AppData\Roaming\Python\Python312\site-packages\spherov2\controls\v2.py", line 174, in add
    self.__callback(Packet.parse_response(pkt))
                    ^^^^^^^^^^^^^^^^^^^^^^^^^^
  File "C:\Users\buiph\AppData\Roaming\Python\Python312\site-packages\spherov2\controls\v2.py", line 62, in parse_response
    raise PacketDecodingException('Unexpected start of packet')
spherov2.controls.PacketDecodingException: Unexpected start of packet
2024-12-12 23:35:18,127 [ERROR] Exception in callback Toy.__api_read(<bleak.backen...001B47FCE6E10>)(bytearray(b'\x88\xd8'))
handle: <Handle Toy.__api_read(<bleak.backen...001B47FCE6E10>)(bytearray(b'\x88\xd8'))>
Traceback (most recent call last):
  File "C:\Python312\Lib\asyncio\events.py", line 88, in _run
    self._context.run(self._callback, *self._args)
  File "C:\Users\buiph\AppData\Roaming\Python\Python312\site-packages\spherov2\toy\__init__.py", line 106, in __api_read
    self.__decoder.add(data)
  File "C:\Users\buiph\AppData\Roaming\Python\Python312\site-packages\spherov2\controls\v2.py", line 174, in add
    self.__callback(Packet.parse_response(pkt))
                    ^^^^^^^^^^^^^^^^^^^^^^^^^^
  File "C:\Users\buiph\AppData\Roaming\Python\Python312\site-packages\spherov2\controls\v2.py", line 62, in parse_response
    raise PacketDecodingException('Unexpected start of packet')
spherov2.controls.PacketDecodingException: Unexpected start of packet
2024-12-12 23:35:18,183 [ERROR] Exception in callback Toy.__api_read(<bleak.backen...00280D665B140>)(bytearray(b'\xddp\xf1\xd8'))
handle: <Handle Toy.__api_read(<bleak.backen...00280D665B140>)(bytearray(b'\xddp\xf1\xd8'))>
Traceback (most recent call last):
  File "C:\Python312\Lib\asyncio\events.py", line 88, in _run
    self._context.run(self._callback, *self._args)
  File "C:\Users\buiph\AppData\Roaming\Python\Python312\site-packages\spherov2\toy\__init__.py", line 106, in __api_read
    self.__decoder.add(data)
  File "C:\Users\buiph\AppData\Roaming\Python\Python312\site-packages\spherov2\controls\v2.py", line 174, in add
    self.__callback(Packet.parse_response(pkt))
                    ^^^^^^^^^^^^^^^^^^^^^^^^^^
  File "C:\Users\buiph\AppData\Roaming\Python\Python312\site-packages\spherov2\controls\v2.py", line 67, in parse_response
    raise PacketDecodingException('Bad response checksum')
spherov2.controls.PacketDecodingException: Bad response checksum
2024-12-12 23:35:18,204 [ERROR] Exception in callback Toy.__api_read(<bleak.backen...0027773DA6ED0>)(bytearray(b'\xda\xe1\xde\xd8'))
handle: <Handle Toy.__api_read(<bleak.backen...0027773DA6ED0>)(bytearray(b'\xda\xe1\xde\xd8'))>
Traceback (most recent call last):
  File "C:\Python312\Lib\asyncio\events.py", line 88, in _run
    self._context.run(self._callback, *self._args)
  File "C:\Users\buiph\AppData\Roaming\Python\Python312\site-packages\spherov2\toy\__init__.py", line 106, in __api_read
    self.__decoder.add(data)
  File "C:\Users\buiph\AppData\Roaming\Python\Python312\site-packages\spherov2\controls\v2.py", line 174, in add
    self.__callback(Packet.parse_response(pkt))
                    ^^^^^^^^^^^^^^^^^^^^^^^^^^
  File "C:\Users\buiph\AppData\Roaming\Python\Python312\site-packages\spherov2\controls\v2.py", line 67, in parse_response
    raise PacketDecodingException('Bad response checksum')
spherov2.controls.PacketDecodingException: Bad response checksum
2024-12-12 23:35:18,326 [ERROR] Exception in callback Toy.__api_read(<bleak.backen...002D1B76BAF90>)(bytearray(b'\xb8\xe8\xd8'))
handle: <Handle Toy.__api_read(<bleak.backen...002D1B76BAF90>)(bytearray(b'\xb8\xe8\xd8'))>
Traceback (most recent call last):
  File "C:\Python312\Lib\asyncio\events.py", line 88, in _run
    self._context.run(self._callback, *self._args)
  File "C:\Users\buiph\AppData\Roaming\Python\Python312\site-packages\spherov2\toy\__init__.py", line 106, in __api_read
    self.__decoder.add(data)
  File "C:\Users\buiph\AppData\Roaming\Python\Python312\site-packages\spherov2\controls\v2.py", line 174, in add
    self.__callback(Packet.parse_response(pkt))
                    ^^^^^^^^^^^^^^^^^^^^^^^^^^
  File "C:\Users\buiph\AppData\Roaming\Python\Python312\site-packages\spherov2\controls\v2.py", line 67, in parse_response
    raise PacketDecodingException('Bad response checksum')
spherov2.controls.PacketDecodingException: Bad response checksum
2024-12-12 23:35:18,376 [ERROR] Exception in callback Toy.__api_read(<bleak.backen...00164DC99EC30>)(bytearray(b'\x93\xd8'))
handle: <Handle Toy.__api_read(<bleak.backen...00164DC99EC30>)(bytearray(b'\x93\xd8'))>
Traceback (most recent call last):
  File "C:\Python312\Lib\asyncio\events.py", line 88, in _run
    self._context.run(self._callback, *self._args)
  File "C:\Users\buiph\AppData\Roaming\Python\Python312\site-packages\spherov2\toy\__init__.py", line 106, in __api_read
    self.__decoder.add(data)
  File "C:\Users\buiph\AppData\Roaming\Python\Python312\site-packages\spherov2\controls\v2.py", line 174, in add
    self.__callback(Packet.parse_response(pkt))
                    ^^^^^^^^^^^^^^^^^^^^^^^^^^
  File "C:\Users\buiph\AppData\Roaming\Python\Python312\site-packages\spherov2\controls\v2.py", line 62, in parse_response
    raise PacketDecodingException('Unexpected start of packet')
spherov2.controls.PacketDecodingException: Unexpected start of packet
2024-12-12 23:35:18,415 [ERROR] Exception in callback Toy.__api_read(<bleak.backen...00280D665B140>)(bytearray(b'p\xab#\xd8'))
handle: <Handle Toy.__api_read(<bleak.backen...00280D665B140>)(bytearray(b'p\xab#\xd8'))>
Traceback (most recent call last):
  File "C:\Python312\Lib\asyncio\events.py", line 88, in _run
    self._context.run(self._callback, *self._args)
  File "C:\Users\buiph\AppData\Roaming\Python\Python312\site-packages\spherov2\toy\__init__.py", line 106, in __api_read
    self.__decoder.add(data)
  File "C:\Users\buiph\AppData\Roaming\Python\Python312\site-packages\spherov2\controls\v2.py", line 174, in add
    self.__callback(Packet.parse_response(pkt))
                    ^^^^^^^^^^^^^^^^^^^^^^^^^^
  File "C:\Users\buiph\AppData\Roaming\Python\Python312\site-packages\spherov2\controls\v2.py", line 67, in parse_response
    raise PacketDecodingException('Bad response checksum')
spherov2.controls.PacketDecodingException: Bad response checksum
2024-12-12 23:35:18,423 [ERROR] Exception in callback Toy.__api_read(<bleak.backen...0027773DA6ED0>)(bytearray(b'\xe1\xde\xd8'))
handle: <Handle Toy.__api_read(<bleak.backen...0027773DA6ED0>)(bytearray(b'\xe1\xde\xd8'))>
Traceback (most recent call last):
  File "C:\Python312\Lib\asyncio\events.py", line 88, in _run
    self._context.run(self._callback, *self._args)
  File "C:\Users\buiph\AppData\Roaming\Python\Python312\site-packages\spherov2\toy\__init__.py", line 106, in __api_read
    self.__decoder.add(data)
  File "C:\Users\buiph\AppData\Roaming\Python\Python312\site-packages\spherov2\controls\v2.py", line 174, in add
    self.__callback(Packet.parse_response(pkt))
                    ^^^^^^^^^^^^^^^^^^^^^^^^^^
  File "C:\Users\buiph\AppData\Roaming\Python\Python312\site-packages\spherov2\controls\v2.py", line 67, in parse_response
    raise PacketDecodingException('Bad response checksum')
spherov2.controls.PacketDecodingException: Bad response checksum
2024-12-12 23:35:18,460 [ERROR] Exception in callback Toy.__api_read(<bleak.backen...00164DC99EC30>)(bytearray(b'T\xd8'))
handle: <Handle Toy.__api_read(<bleak.backen...00164DC99EC30>)(bytearray(b'T\xd8'))>
Traceback (most recent call last):
  File "C:\Python312\Lib\asyncio\events.py", line 88, in _run
    self._context.run(self._callback, *self._args)
  File "C:\Users\buiph\AppData\Roaming\Python\Python312\site-packages\spherov2\toy\__init__.py", line 106, in __api_read
    self.__decoder.add(data)
  File "C:\Users\buiph\AppData\Roaming\Python\Python312\site-packages\spherov2\controls\v2.py", line 173, in add
    raise PacketDecodingException(f'Very small packet {[hex(x) for x in pkt]}')
spherov2.controls.PacketDecodingException: Very small packet ['0x8d', '0x2', '0x54', '0xd8']
2024-12-12 23:35:18,464 [ERROR] Exception in callback Toy.__api_read(<bleak.backen...001B47FCE6E10>)(bytearray(b'Z\xd8'))
handle: <Handle Toy.__api_read(<bleak.backen...001B47FCE6E10>)(bytearray(b'Z\xd8'))>
Traceback (most recent call last):
  File "C:\Python312\Lib\asyncio\events.py", line 88, in _run
    self._context.run(self._callback, *self._args)
  File "C:\Users\buiph\AppData\Roaming\Python\Python312\site-packages\spherov2\toy\__init__.py", line 106, in __api_read
    self.__decoder.add(data)
  File "C:\Users\buiph\AppData\Roaming\Python\Python312\site-packages\spherov2\controls\v2.py", line 174, in add
    self.__callback(Packet.parse_response(pkt))
                    ^^^^^^^^^^^^^^^^^^^^^^^^^^
  File "C:\Users\buiph\AppData\Roaming\Python\Python312\site-packages\spherov2\controls\v2.py", line 67, in parse_response
    raise PacketDecodingException('Bad response checksum')
spherov2.controls.PacketDecodingException: Bad response checksum
2024-12-12 23:35:18,465 [ERROR] Exception in callback Toy.__api_read(<bleak.backen...00164DC99EC30>)(bytearray(b'\x85\xda\xd8'))
handle: <Handle Toy.__api_read(<bleak.backen...00164DC99EC30>)(bytearray(b'\x85\xda\xd8'))>
Traceback (most recent call last):
  File "C:\Python312\Lib\asyncio\events.py", line 88, in _run
    self._context.run(self._callback, *self._args)
  File "C:\Users\buiph\AppData\Roaming\Python\Python312\site-packages\spherov2\toy\__init__.py", line 106, in __api_read
    self.__decoder.add(data)
  File "C:\Users\buiph\AppData\Roaming\Python\Python312\site-packages\spherov2\controls\v2.py", line 173, in add
    raise PacketDecodingException(f'Very small packet {[hex(x) for x in pkt]}')
spherov2.controls.PacketDecodingException: Very small packet ['0x85', '0xda', '0xd8']
2024-12-12 23:35:18,467 [ERROR] Exception in callback Toy.__api_read(<bleak.backen...00280D665B140>)(bytearray(b'\xddp \xd8'))
handle: <Handle Toy.__api_read(<bleak.backen...00280D665B140>)(bytearray(b'\xddp \xd8'))>
Traceback (most recent call last):
  File "C:\Python312\Lib\asyncio\events.py", line 88, in _run
    self._context.run(self._callback, *self._args)
  File "C:\Users\buiph\AppData\Roaming\Python\Python312\site-packages\spherov2\toy\__init__.py", line 106, in __api_read
    self.__decoder.add(data)
  File "C:\Users\buiph\AppData\Roaming\Python\Python312\site-packages\spherov2\controls\v2.py", line 174, in add
    self.__callback(Packet.parse_response(pkt))
                    ^^^^^^^^^^^^^^^^^^^^^^^^^^
  File "C:\Users\buiph\AppData\Roaming\Python\Python312\site-packages\spherov2\controls\v2.py", line 62, in parse_response
    raise PacketDecodingException('Unexpected start of packet')
spherov2.controls.PacketDecodingException: Unexpected start of packet
2024-12-12 23:35:18,469 [ERROR] Exception in callback Toy.__api_read(<bleak.backen...002D1B76BAF90>)(bytearray(b'y\xd8'))
handle: <Handle Toy.__api_read(<bleak.backen...002D1B76BAF90>)(bytearray(b'y\xd8'))>
Traceback (most recent call last):
  File "C:\Python312\Lib\asyncio\events.py", line 88, in _run
    self._context.run(self._callback, *self._args)
  File "C:\Users\buiph\AppData\Roaming\Python\Python312\site-packages\spherov2\toy\__init__.py", line 106, in __api_read
    self.__decoder.add(data)
  File "C:\Users\buiph\AppData\Roaming\Python\Python312\site-packages\spherov2\controls\v2.py", line 174, in add
    self.__callback(Packet.parse_response(pkt))
                    ^^^^^^^^^^^^^^^^^^^^^^^^^^
  File "C:\Users\buiph\AppData\Roaming\Python\Python312\site-packages\spherov2\controls\v2.py", line 67, in parse_response
    raise PacketDecodingException('Bad response checksum')
spherov2.controls.PacketDecodingException: Bad response checksum
2024-12-12 23:35:18,470 [ERROR] Exception in callback Toy.__api_read(<bleak.backen...0027773DA6ED0>)(bytearray(b'\xda\xe1\xd2\xd8'))
handle: <Handle Toy.__api_read(<bleak.backen...0027773DA6ED0>)(bytearray(b'\xda\xe1\xd2\xd8'))>
Traceback (most recent call last):
  File "C:\Python312\Lib\asyncio\events.py", line 88, in _run
    self._context.run(self._callback, *self._args)
  File "C:\Users\buiph\AppData\Roaming\Python\Python312\site-packages\spherov2\toy\__init__.py", line 106, in __api_read
    self.__decoder.add(data)
  File "C:\Users\buiph\AppData\Roaming\Python\Python312\site-packages\spherov2\controls\v2.py", line 174, in add
    self.__callback(Packet.parse_response(pkt))
                    ^^^^^^^^^^^^^^^^^^^^^^^^^^
  File "C:\Users\buiph\AppData\Roaming\Python\Python312\site-packages\spherov2\controls\v2.py", line 67, in parse_response
    raise PacketDecodingException('Bad response checksum')
spherov2.controls.PacketDecodingException: Bad response checksum
2024-12-12 23:35:18,473 [ERROR] Exception in callback Toy.__api_read(<bleak.backen...0027773DA6ED0>)(bytearray(b'=\x9d\xd8'))
handle: <Handle Toy.__api_read(<bleak.backen...0027773DA6ED0>)(bytearray(b'=\x9d\xd8'))>
Traceback (most recent call last):
  File "C:\Python312\Lib\asyncio\events.py", line 88, in _run
    self._context.run(self._callback, *self._args)
  File "C:\Users\buiph\AppData\Roaming\Python\Python312\site-packages\spherov2\toy\__init__.py", line 106, in __api_read
    self.__decoder.add(data)
  File "C:\Users\buiph\AppData\Roaming\Python\Python312\site-packages\spherov2\controls\v2.py", line 174, in add
    self.__callback(Packet.parse_response(pkt))
                    ^^^^^^^^^^^^^^^^^^^^^^^^^^
  File "C:\Users\buiph\AppData\Roaming\Python\Python312\site-packages\spherov2\controls\v2.py", line 67, in parse_response
    raise PacketDecodingException('Bad response checksum')
spherov2.controls.PacketDecodingException: Bad response checksum
2024-12-12 23:35:18,475 [ERROR] Exception in callback Toy.__api_read(<bleak.backen...001B47FCE6E10>)(bytearray(b'\xb6\xd8'))
handle: <Handle Toy.__api_read(<bleak.backen...001B47FCE6E10>)(bytearray(b'\xb6\xd8'))>
Traceback (most recent call last):
  File "C:\Python312\Lib\asyncio\events.py", line 88, in _run
    self._context.run(self._callback, *self._args)
  File "C:\Users\buiph\AppData\Roaming\Python\Python312\site-packages\spherov2\toy\__init__.py", line 106, in __api_read
    self.__decoder.add(data)
  File "C:\Users\buiph\AppData\Roaming\Python\Python312\site-packages\spherov2\controls\v2.py", line 174, in add
    self.__callback(Packet.parse_response(pkt))
                    ^^^^^^^^^^^^^^^^^^^^^^^^^^
  File "C:\Users\buiph\AppData\Roaming\Python\Python312\site-packages\spherov2\controls\v2.py", line 62, in parse_response
    raise PacketDecodingException('Unexpected start of packet')
spherov2.controls.PacketDecodingException: Unexpected start of packet
2024-12-12 23:35:18,475 [ERROR] Exception in callback Toy.__api_read(<bleak.backen...0027773DA6ED0>)(bytearray(b"C\x13Z=\'\xd8"))
handle: <Handle Toy.__api_read(<bleak.backen...0027773DA6ED0>)(bytearray(b"C\x13Z=\'\xd8"))>
Traceback (most recent call last):
  File "C:\Python312\Lib\asyncio\events.py", line 88, in _run
    self._context.run(self._callback, *self._args)
  File "C:\Users\buiph\AppData\Roaming\Python\Python312\site-packages\spherov2\toy\__init__.py", line 106, in __api_read
    self.__decoder.add(data)
  File "C:\Users\buiph\AppData\Roaming\Python\Python312\site-packages\spherov2\controls\v2.py", line 174, in add
    self.__callback(Packet.parse_response(pkt))
                    ^^^^^^^^^^^^^^^^^^^^^^^^^^
  File "C:\Users\buiph\AppData\Roaming\Python\Python312\site-packages\spherov2\controls\v2.py", line 67, in parse_response
    raise PacketDecodingException('Bad response checksum')
spherov2.controls.PacketDecodingException: Bad response checksum
2024-12-12 23:35:18,475 [ERROR] Exception in callback Toy.__api_read(<bleak.backen...00280D665B140>)(bytearray(b'^\x14\xed\xd8'))
handle: <Handle Toy.__api_read(<bleak.backen...00280D665B140>)(bytearray(b'^\x14\xed\xd8'))>
Traceback (most recent call last):
  File "C:\Python312\Lib\asyncio\events.py", line 88, in _run
    self._context.run(self._callback, *self._args)
  File "C:\Users\buiph\AppData\Roaming\Python\Python312\site-packages\spherov2\toy\__init__.py", line 106, in __api_read
    self.__decoder.add(data)
  File "C:\Users\buiph\AppData\Roaming\Python\Python312\site-packages\spherov2\controls\v2.py", line 174, in add
    self.__callback(Packet.parse_response(pkt))
                    ^^^^^^^^^^^^^^^^^^^^^^^^^^
  File "C:\Users\buiph\AppData\Roaming\Python\Python312\site-packages\spherov2\controls\v2.py", line 62, in parse_response
    raise PacketDecodingException('Unexpected start of packet')
spherov2.controls.PacketDecodingException: Unexpected start of packet
2024-12-12 23:35:18,476 [ERROR] Exception in callback Toy.__api_read(<bleak.backen...001B47FCE6E10>)(bytearray(b'\xf6\xd8'))
handle: <Handle Toy.__api_read(<bleak.backen...001B47FCE6E10>)(bytearray(b'\xf6\xd8'))>
Traceback (most recent call last):
  File "C:\Python312\Lib\asyncio\events.py", line 88, in _run
    self._context.run(self._callback, *self._args)
  File "C:\Users\buiph\AppData\Roaming\Python\Python312\site-packages\spherov2\toy\__init__.py", line 106, in __api_read
    self.__decoder.add(data)
  File "C:\Users\buiph\AppData\Roaming\Python\Python312\site-packages\spherov2\controls\v2.py", line 174, in add
    self.__callback(Packet.parse_response(pkt))
                    ^^^^^^^^^^^^^^^^^^^^^^^^^^
  File "C:\Users\buiph\AppData\Roaming\Python\Python312\site-packages\spherov2\controls\v2.py", line 62, in parse_response
    raise PacketDecodingException('Unexpected start of packet')
spherov2.controls.PacketDecodingException: Unexpected start of packet
2024-12-12 23:35:18,479 [ERROR] Exception in callback Toy.__api_read(<bleak.backen...00164DC99EC30>)(bytearray(b'=...\x85\xa6\xd8'))
handle: <Handle Toy.__api_read(<bleak.backen...00164DC99EC30>)(bytearray(b'=...\x85\xa6\xd8'))>
Traceback (most recent call last):
  File "C:\Python312\Lib\asyncio\events.py", line 88, in _run
    self._context.run(self._callback, *self._args)
  File "C:\Users\buiph\AppData\Roaming\Python\Python312\site-packages\spherov2\toy\__init__.py", line 106, in __api_read
    self.__decoder.add(data)
  File "C:\Users\buiph\AppData\Roaming\Python\Python312\site-packages\spherov2\controls\v2.py", line 174, in add
    self.__callback(Packet.parse_response(pkt))
                    ^^^^^^^^^^^^^^^^^^^^^^^^^^
  File "C:\Users\buiph\AppData\Roaming\Python\Python312\site-packages\spherov2\controls\v2.py", line 67, in parse_response
    raise PacketDecodingException('Bad response checksum')
spherov2.controls.PacketDecodingException: Bad response checksum
2024-12-12 23:35:18,481 [ERROR] Exception in callback Toy.__api_read(<bleak.backen...00164DC99EC30>)(bytearray(b'\x83\xd8'))
handle: <Handle Toy.__api_read(<bleak.backen...00164DC99EC30>)(bytearray(b'\x83\xd8'))>
Traceback (most recent call last):
  File "C:\Python312\Lib\asyncio\events.py", line 88, in _run
    self._context.run(self._callback, *self._args)
  File "C:\Users\buiph\AppData\Roaming\Python\Python312\site-packages\spherov2\toy\__init__.py", line 106, in __api_read
    self.__decoder.add(data)
  File "C:\Users\buiph\AppData\Roaming\Python\Python312\site-packages\spherov2\controls\v2.py", line 174, in add
    self.__callback(Packet.parse_response(pkt))
                    ^^^^^^^^^^^^^^^^^^^^^^^^^^
  File "C:\Users\buiph\AppData\Roaming\Python\Python312\site-packages\spherov2\controls\v2.py", line 62, in parse_response
    raise PacketDecodingException('Unexpected start of packet')
spherov2.controls.PacketDecodingException: Unexpected start of packet
2024-12-12 23:35:18,482 [ERROR] Exception in callback Toy.__api_read(<bleak.backen...0027773DA6ED0>)(bytearray(b'\x13Z=\x93\xd8'))
handle: <Handle Toy.__api_read(<bleak.backen...0027773DA6ED0>)(bytearray(b'\x13Z=\x93\xd8'))>
Traceback (most recent call last):
  File "C:\Python312\Lib\asyncio\events.py", line 88, in _run
    self._context.run(self._callback, *self._args)
  File "C:\Users\buiph\AppData\Roaming\Python\Python312\site-packages\spherov2\toy\__init__.py", line 106, in __api_read
    self.__decoder.add(data)
  File "C:\Users\buiph\AppData\Roaming\Python\Python312\site-packages\spherov2\controls\v2.py", line 174, in add
    self.__callback(Packet.parse_response(pkt))
                    ^^^^^^^^^^^^^^^^^^^^^^^^^^
  File "C:\Users\buiph\AppData\Roaming\Python\Python312\site-packages\spherov2\controls\v2.py", line 62, in parse_response
    raise PacketDecodingException('Unexpected start of packet')
spherov2.controls.PacketDecodingException: Unexpected start of packet
2024-12-12 23:35:18,483 [ERROR] Exception in callback Toy.__api_read(<bleak.backen...00164DC99EC30>)(bytearray(b'\xd7\xd8'))
handle: <Handle Toy.__api_read(<bleak.backen...00164DC99EC30>)(bytearray(b'\xd7\xd8'))>
Traceback (most recent call last):
  File "C:\Python312\Lib\asyncio\events.py", line 88, in _run
    self._context.run(self._callback, *self._args)
  File "C:\Users\buiph\AppData\Roaming\Python\Python312\site-packages\spherov2\toy\__init__.py", line 106, in __api_read
    self.__decoder.add(data)
  File "C:\Users\buiph\AppData\Roaming\Python\Python312\site-packages\spherov2\controls\v2.py", line 174, in add
    self.__callback(Packet.parse_response(pkt))
                    ^^^^^^^^^^^^^^^^^^^^^^^^^^
  File "C:\Users\buiph\AppData\Roaming\Python\Python312\site-packages\spherov2\controls\v2.py", line 67, in parse_response
    raise PacketDecodingException('Bad response checksum')
spherov2.controls.PacketDecodingException: Bad response checksum
2024-12-12 23:35:18,490 [ERROR] Exception in callback Toy.__api_read(<bleak.backen...001B47FCE6E10>)(bytearray(b')=\xd8'))
handle: <Handle Toy.__api_read(<bleak.backen...001B47FCE6E10>)(bytearray(b')=\xd8'))>
Traceback (most recent call last):
  File "C:\Python312\Lib\asyncio\events.py", line 88, in _run
    self._context.run(self._callback, *self._args)
  File "C:\Users\buiph\AppData\Roaming\Python\Python312\site-packages\spherov2\toy\__init__.py", line 106, in __api_read
    self.__decoder.add(data)
  File "C:\Users\buiph\AppData\Roaming\Python\Python312\site-packages\spherov2\controls\v2.py", line 174, in add
    self.__callback(Packet.parse_response(pkt))
                    ^^^^^^^^^^^^^^^^^^^^^^^^^^
  File "C:\Users\buiph\AppData\Roaming\Python\Python312\site-packages\spherov2\controls\v2.py", line 62, in parse_response
    raise PacketDecodingException('Unexpected start of packet')
spherov2.controls.PacketDecodingException: Unexpected start of packet
2024-12-12 23:35:18,558 [ERROR] Exception in callback Toy.__api_read(<bleak.backen...00280D665B140>)(bytearray(b'\xddp\x1a\xd8'))
handle: <Handle Toy.__api_read(<bleak.backen...00280D665B140>)(bytearray(b'\xddp\x1a\xd8'))>
Traceback (most recent call last):
  File "C:\Python312\Lib\asyncio\events.py", line 88, in _run
    self._context.run(self._callback, *self._args)
  File "C:\Users\buiph\AppData\Roaming\Python\Python312\site-packages\spherov2\toy\__init__.py", line 106, in __api_read
    self.__decoder.add(data)
  File "C:\Users\buiph\AppData\Roaming\Python\Python312\site-packages\spherov2\controls\v2.py", line 174, in add
    self.__callback(Packet.parse_response(pkt))
                    ^^^^^^^^^^^^^^^^^^^^^^^^^^
  File "C:\Users\buiph\AppData\Roaming\Python\Python312\site-packages\spherov2\controls\v2.py", line 67, in parse_response
    raise PacketDecodingException('Bad response checksum')
spherov2.controls.PacketDecodingException: Bad response checksum
2024-12-12 23:35:18,571 [ERROR] Exception in callback Toy.__api_read(<bleak.backen...0027773DA6ED0>)(bytearray(b'=\xa2\xd8'))
handle: <Handle Toy.__api_read(<bleak.backen...0027773DA6ED0>)(bytearray(b'=\xa2\xd8'))>
Traceback (most recent call last):
  File "C:\Python312\Lib\asyncio\events.py", line 88, in _run
    self._context.run(self._callback, *self._args)
  File "C:\Users\buiph\AppData\Roaming\Python\Python312\site-packages\spherov2\toy\__init__.py", line 106, in __api_read
    self.__decoder.add(data)
  File "C:\Users\buiph\AppData\Roaming\Python\Python312\site-packages\spherov2\controls\v2.py", line 174, in add
    self.__callback(Packet.parse_response(pkt))
                    ^^^^^^^^^^^^^^^^^^^^^^^^^^
  File "C:\Users\buiph\AppData\Roaming\Python\Python312\site-packages\spherov2\controls\v2.py", line 67, in parse_response
    raise PacketDecodingException('Bad response checksum')
spherov2.controls.PacketDecodingException: Bad response checksum
2024-12-12 23:35:18,604 [ERROR] Exception in callback Toy.__api_read(<bleak.backen...002D1B76BAF90>)(bytearray(b'=...\x14\xaa\xd8'))
handle: <Handle Toy.__api_read(<bleak.backen...002D1B76BAF90>)(bytearray(b'=...\x14\xaa\xd8'))>
Traceback (most recent call last):
  File "C:\Python312\Lib\asyncio\events.py", line 88, in _run
    self._context.run(self._callback, *self._args)
  File "C:\Users\buiph\AppData\Roaming\Python\Python312\site-packages\spherov2\toy\__init__.py", line 106, in __api_read
    self.__decoder.add(data)
  File "C:\Users\buiph\AppData\Roaming\Python\Python312\site-packages\spherov2\controls\v2.py", line 174, in add
    self.__callback(Packet.parse_response(pkt))
                    ^^^^^^^^^^^^^^^^^^^^^^^^^^
  File "C:\Users\buiph\AppData\Roaming\Python\Python312\site-packages\spherov2\controls\v2.py", line 67, in parse_response
    raise PacketDecodingException('Bad response checksum')
spherov2.controls.PacketDecodingException: Bad response checksum
2024-12-12 23:35:19,795 [ERROR] Exception in callback Toy.__api_read(<bleak.backen...0027773DA6ED0>)(bytearray(b'\...\xe1\x97\xd8'))
handle: <Handle Toy.__api_read(<bleak.backen...0027773DA6ED0>)(bytearray(b'\...\xe1\x97\xd8'))>
Traceback (most recent call last):
  File "C:\Python312\Lib\asyncio\events.py", line 88, in _run
    self._context.run(self._callback, *self._args)
  File "C:\Users\buiph\AppData\Roaming\Python\Python312\site-packages\spherov2\toy\__init__.py", line 106, in __api_read
    self.__decoder.add(data)
  File "C:\Users\buiph\AppData\Roaming\Python\Python312\site-packages\spherov2\controls\v2.py", line 174, in add
    self.__callback(Packet.parse_response(pkt))
                    ^^^^^^^^^^^^^^^^^^^^^^^^^^
  File "C:\Users\buiph\AppData\Roaming\Python\Python312\site-packages\spherov2\controls\v2.py", line 67, in parse_response
    raise PacketDecodingException('Bad response checksum')
spherov2.controls.PacketDecodingException: Bad response checksum
2024-12-12 23:35:19,824 [ERROR] Exception in callback Toy.__api_read(<bleak.backen...00164DC99EC30>)(bytearray(b'\x85^\xd8'))
handle: <Handle Toy.__api_read(<bleak.backen...00164DC99EC30>)(bytearray(b'\x85^\xd8'))>
Traceback (most recent call last):
  File "C:\Python312\Lib\asyncio\events.py", line 88, in _run
    self._context.run(self._callback, *self._args)
  File "C:\Users\buiph\AppData\Roaming\Python\Python312\site-packages\spherov2\toy\__init__.py", line 106, in __api_read
    self.__decoder.add(data)
  File "C:\Users\buiph\AppData\Roaming\Python\Python312\site-packages\spherov2\controls\v2.py", line 174, in add
    self.__callback(Packet.parse_response(pkt))
                    ^^^^^^^^^^^^^^^^^^^^^^^^^^
  File "C:\Users\buiph\AppData\Roaming\Python\Python312\site-packages\spherov2\controls\v2.py", line 65, in parse_response
    *data, chk = Packet.__unescape_data(data)
                 ^^^^^^^^^^^^^^^^^^^^^^^^^^^^
  File "C:\Users\buiph\AppData\Roaming\Python\Python312\site-packages\spherov2\controls\v2.py", line 102, in __unescape_data
    raise PacketDecodingException('Unexpected escaping byte')
spherov2.controls.PacketDecodingException: Unexpected escaping byte
2024-12-12 23:35:19,867 [ERROR] Exception in callback Toy.__api_read(<bleak.backen...00280D665B140>)(bytearray(b'\xddpe\xd8'))
handle: <Handle Toy.__api_read(<bleak.backen...00280D665B140>)(bytearray(b'\xddpe\xd8'))>
Traceback (most recent call last):
  File "C:\Python312\Lib\asyncio\events.py", line 88, in _run
    self._context.run(self._callback, *self._args)
  File "C:\Users\buiph\AppData\Roaming\Python\Python312\site-packages\spherov2\toy\__init__.py", line 106, in __api_read
    self.__decoder.add(data)
  File "C:\Users\buiph\AppData\Roaming\Python\Python312\site-packages\spherov2\controls\v2.py", line 174, in add
    self.__callback(Packet.parse_response(pkt))
                    ^^^^^^^^^^^^^^^^^^^^^^^^^^
  File "C:\Users\buiph\AppData\Roaming\Python\Python312\site-packages\spherov2\controls\v2.py", line 67, in parse_response
    raise PacketDecodingException('Bad response checksum')
spherov2.controls.PacketDecodingException: Bad response checksum
2024-12-12 23:35:19,873 [ERROR] Exception in callback Toy.__api_read(<bleak.backen...002D1B76BAF90>)(bytearray(b'\xa7\xd8'))
handle: <Handle Toy.__api_read(<bleak.backen...002D1B76BAF90>)(bytearray(b'\xa7\xd8'))>
Traceback (most recent call last):
  File "C:\Python312\Lib\asyncio\events.py", line 88, in _run
    self._context.run(self._callback, *self._args)
  File "C:\Users\buiph\AppData\Roaming\Python\Python312\site-packages\spherov2\toy\__init__.py", line 106, in __api_read
    self.__decoder.add(data)
  File "C:\Users\buiph\AppData\Roaming\Python\Python312\site-packages\spherov2\controls\v2.py", line 174, in add
    self.__callback(Packet.parse_response(pkt))
                    ^^^^^^^^^^^^^^^^^^^^^^^^^^
  File "C:\Users\buiph\AppData\Roaming\Python\Python312\site-packages\spherov2\controls\v2.py", line 62, in parse_response
    raise PacketDecodingException('Unexpected start of packet')
spherov2.controls.PacketDecodingException: Unexpected start of packet
2024-12-12 23:35:19,876 [ERROR] Exception in callback Toy.__api_read(<bleak.backen...0027773DA6ED0>)(bytearray(b'\...\xe1\x0c\xd8'))
handle: <Handle Toy.__api_read(<bleak.backen...0027773DA6ED0>)(bytearray(b'\...\xe1\x0c\xd8'))>
Traceback (most recent call last):
  File "C:\Python312\Lib\asyncio\events.py", line 88, in _run
    self._context.run(self._callback, *self._args)
  File "C:\Users\buiph\AppData\Roaming\Python\Python312\site-packages\spherov2\toy\__init__.py", line 106, in __api_read
    self.__decoder.add(data)
  File "C:\Users\buiph\AppData\Roaming\Python\Python312\site-packages\spherov2\controls\v2.py", line 174, in add
    self.__callback(Packet.parse_response(pkt))
                    ^^^^^^^^^^^^^^^^^^^^^^^^^^
  File "C:\Users\buiph\AppData\Roaming\Python\Python312\site-packages\spherov2\controls\v2.py", line 67, in parse_response
    raise PacketDecodingException('Bad response checksum')
spherov2.controls.PacketDecodingException: Bad response checksum
2024-12-12 23:35:20,067 [ERROR] Exception in callback Toy.__api_read(<bleak.backen...00280D665B140>)(bytearray(b'p\x99\xd8'))
handle: <Handle Toy.__api_read(<bleak.backen...00280D665B140>)(bytearray(b'p\x99\xd8'))>
Traceback (most recent call last):
  File "C:\Python312\Lib\asyncio\events.py", line 88, in _run
    self._context.run(self._callback, *self._args)
  File "C:\Users\buiph\AppData\Roaming\Python\Python312\site-packages\spherov2\toy\__init__.py", line 106, in __api_read
    self.__decoder.add(data)
  File "C:\Users\buiph\AppData\Roaming\Python\Python312\site-packages\spherov2\controls\v2.py", line 174, in add
    self.__callback(Packet.parse_response(pkt))
                    ^^^^^^^^^^^^^^^^^^^^^^^^^^
  File "C:\Users\buiph\AppData\Roaming\Python\Python312\site-packages\spherov2\controls\v2.py", line 67, in parse_response
    raise PacketDecodingException('Bad response checksum')
spherov2.controls.PacketDecodingException: Bad response checksum
2024-12-12 23:35:20,146 [ERROR] Exception in callback Toy.__api_read(<bleak.backen...001B47FCE6E10>)(bytearray(b'U\xd8'))
handle: <Handle Toy.__api_read(<bleak.backen...001B47FCE6E10>)(bytearray(b'U\xd8'))>
Traceback (most recent call last):
  File "C:\Python312\Lib\asyncio\events.py", line 88, in _run
    self._context.run(self._callback, *self._args)
  File "C:\Users\buiph\AppData\Roaming\Python\Python312\site-packages\spherov2\toy\__init__.py", line 106, in __api_read
    self.__decoder.add(data)
  File "C:\Users\buiph\AppData\Roaming\Python\Python312\site-packages\spherov2\controls\v2.py", line 174, in add
    self.__callback(Packet.parse_response(pkt))
                    ^^^^^^^^^^^^^^^^^^^^^^^^^^
  File "C:\Users\buiph\AppData\Roaming\Python\Python312\site-packages\spherov2\controls\v2.py", line 67, in parse_response
    raise PacketDecodingException('Bad response checksum')
spherov2.controls.PacketDecodingException: Bad response checksum
2024-12-12 23:35:20,715 [ERROR] Exception in callback Toy.__api_read(<bleak.backen...00164DC99EC30>)(bytearray(b'\...\x85\x1c\xd8'))
handle: <Handle Toy.__api_read(<bleak.backen...00164DC99EC30>)(bytearray(b'\...\x85\x1c\xd8'))>
Traceback (most recent call last):
  File "C:\Python312\Lib\asyncio\events.py", line 88, in _run
    self._context.run(self._callback, *self._args)
  File "C:\Users\buiph\AppData\Roaming\Python\Python312\site-packages\spherov2\toy\__init__.py", line 106, in __api_read
    self.__decoder.add(data)
  File "C:\Users\buiph\AppData\Roaming\Python\Python312\site-packages\spherov2\controls\v2.py", line 174, in add
    self.__callback(Packet.parse_response(pkt))
                    ^^^^^^^^^^^^^^^^^^^^^^^^^^
  File "C:\Users\buiph\AppData\Roaming\Python\Python312\site-packages\spherov2\controls\v2.py", line 67, in parse_response
    raise PacketDecodingException('Bad response checksum')
spherov2.controls.PacketDecodingException: Bad response checksum
2024-12-12 23:35:20,751 [ERROR] Exception in callback Toy.__api_read(<bleak.backen...00280D665B140>)(bytearray(b'\\\xcc\xf9\xd8'))
handle: <Handle Toy.__api_read(<bleak.backen...00280D665B140>)(bytearray(b'\\\xcc\xf9\xd8'))>
Traceback (most recent call last):
  File "C:\Python312\Lib\asyncio\events.py", line 88, in _run
    self._context.run(self._callback, *self._args)
  File "C:\Users\buiph\AppData\Roaming\Python\Python312\site-packages\spherov2\toy\__init__.py", line 106, in __api_read
    self.__decoder.add(data)
  File "C:\Users\buiph\AppData\Roaming\Python\Python312\site-packages\spherov2\controls\v2.py", line 174, in add
    self.__callback(Packet.parse_response(pkt))
                    ^^^^^^^^^^^^^^^^^^^^^^^^^^
  File "C:\Users\buiph\AppData\Roaming\Python\Python312\site-packages\spherov2\controls\v2.py", line 67, in parse_response
    raise PacketDecodingException('Bad response checksum')
spherov2.controls.PacketDecodingException: Bad response checksum
2024-12-12 23:35:20,758 [ERROR] Exception in callback Toy.__api_read(<bleak.backen...0027773DA6ED0>)(bytearray(b'\x99[\xd8'))
handle: <Handle Toy.__api_read(<bleak.backen...0027773DA6ED0>)(bytearray(b'\x99[\xd8'))>
Traceback (most recent call last):
  File "C:\Python312\Lib\asyncio\events.py", line 88, in _run
    self._context.run(self._callback, *self._args)
  File "C:\Users\buiph\AppData\Roaming\Python\Python312\site-packages\spherov2\toy\__init__.py", line 106, in __api_read
    self.__decoder.add(data)
  File "C:\Users\buiph\AppData\Roaming\Python\Python312\site-packages\spherov2\controls\v2.py", line 174, in add
    self.__callback(Packet.parse_response(pkt))
                    ^^^^^^^^^^^^^^^^^^^^^^^^^^
  File "C:\Users\buiph\AppData\Roaming\Python\Python312\site-packages\spherov2\controls\v2.py", line 67, in parse_response
    raise PacketDecodingException('Bad response checksum')
spherov2.controls.PacketDecodingException: Bad response checksum
2024-12-12 23:35:20,862 [ERROR] Exception in callback Toy.__api_read(<bleak.backen...001B47FCE6E10>)(bytearray(b')\xa4\xd8'))
handle: <Handle Toy.__api_read(<bleak.backen...001B47FCE6E10>)(bytearray(b')\xa4\xd8'))>
Traceback (most recent call last):
  File "C:\Python312\Lib\asyncio\events.py", line 88, in _run
    self._context.run(self._callback, *self._args)
  File "C:\Users\buiph\AppData\Roaming\Python\Python312\site-packages\spherov2\toy\__init__.py", line 106, in __api_read
    self.__decoder.add(data)
  File "C:\Users\buiph\AppData\Roaming\Python\Python312\site-packages\spherov2\controls\v2.py", line 174, in add
    self.__callback(Packet.parse_response(pkt))
                    ^^^^^^^^^^^^^^^^^^^^^^^^^^
  File "C:\Users\buiph\AppData\Roaming\Python\Python312\site-packages\spherov2\controls\v2.py", line 67, in parse_response
    raise PacketDecodingException('Bad response checksum')
spherov2.controls.PacketDecodingException: Bad response checksum
2024-12-12 23:35:20,899 [ERROR] Exception in callback Toy.__api_read(<bleak.backen...00280D665B140>)(bytearray(b'^\x14f\xd8'))
handle: <Handle Toy.__api_read(<bleak.backen...00280D665B140>)(bytearray(b'^\x14f\xd8'))>
Traceback (most recent call last):
  File "C:\Python312\Lib\asyncio\events.py", line 88, in _run
    self._context.run(self._callback, *self._args)
  File "C:\Users\buiph\AppData\Roaming\Python\Python312\site-packages\spherov2\toy\__init__.py", line 106, in __api_read
    self.__decoder.add(data)
  File "C:\Users\buiph\AppData\Roaming\Python\Python312\site-packages\spherov2\controls\v2.py", line 174, in add
    self.__callback(Packet.parse_response(pkt))
                    ^^^^^^^^^^^^^^^^^^^^^^^^^^
  File "C:\Users\buiph\AppData\Roaming\Python\Python312\site-packages\spherov2\controls\v2.py", line 67, in parse_response
    raise PacketDecodingException('Bad response checksum')
spherov2.controls.PacketDecodingException: Bad response checksum
2024-12-12 23:35:20,905 [ERROR] Exception in callback Toy.__api_read(<bleak.backen...0027773DA6ED0>)(bytearray(b'Z=1\xd8'))
handle: <Handle Toy.__api_read(<bleak.backen...0027773DA6ED0>)(bytearray(b'Z=1\xd8'))>
Traceback (most recent call last):
  File "C:\Python312\Lib\asyncio\events.py", line 88, in _run
    self._context.run(self._callback, *self._args)
  File "C:\Users\buiph\AppData\Roaming\Python\Python312\site-packages\spherov2\toy\__init__.py", line 106, in __api_read
    self.__decoder.add(data)
  File "C:\Users\buiph\AppData\Roaming\Python\Python312\site-packages\spherov2\controls\v2.py", line 174, in add
    self.__callback(Packet.parse_response(pkt))
                    ^^^^^^^^^^^^^^^^^^^^^^^^^^
  File "C:\Users\buiph\AppData\Roaming\Python\Python312\site-packages\spherov2\controls\v2.py", line 67, in parse_response
    raise PacketDecodingException('Bad response checksum')
spherov2.controls.PacketDecodingException: Bad response checksum
2024-12-12 23:35:20,984 [ERROR] Exception in callback Toy.__api_read(<bleak.backen...00164DC99EC30>)(bytearray(b'\...xda\xe1Z\xd8'))
handle: <Handle Toy.__api_read(<bleak.backen...00164DC99EC30>)(bytearray(b'\...xda\xe1Z\xd8'))>
Traceback (most recent call last):
  File "C:\Python312\Lib\asyncio\events.py", line 88, in _run
    self._context.run(self._callback, *self._args)
  File "C:\Users\buiph\AppData\Roaming\Python\Python312\site-packages\spherov2\toy\__init__.py", line 106, in __api_read
    self.__decoder.add(data)
  File "C:\Users\buiph\AppData\Roaming\Python\Python312\site-packages\spherov2\controls\v2.py", line 174, in add
    self.__callback(Packet.parse_response(pkt))
                    ^^^^^^^^^^^^^^^^^^^^^^^^^^
  File "C:\Users\buiph\AppData\Roaming\Python\Python312\site-packages\spherov2\controls\v2.py", line 67, in parse_response
    raise PacketDecodingException('Bad response checksum')
spherov2.controls.PacketDecodingException: Bad response checksum
2024-12-12 23:35:21,015 [ERROR] Exception in callback Toy.__api_read(<bleak.backen...001B47FCE6E10>)(bytearray(b'\xaa\xd8'))
handle: <Handle Toy.__api_read(<bleak.backen...001B47FCE6E10>)(bytearray(b'\xaa\xd8'))>
Traceback (most recent call last):
  File "C:\Python312\Lib\asyncio\events.py", line 88, in _run
    self._context.run(self._callback, *self._args)
  File "C:\Users\buiph\AppData\Roaming\Python\Python312\site-packages\spherov2\toy\__init__.py", line 106, in __api_read
    self.__decoder.add(data)
  File "C:\Users\buiph\AppData\Roaming\Python\Python312\site-packages\spherov2\controls\v2.py", line 174, in add
    self.__callback(Packet.parse_response(pkt))
                    ^^^^^^^^^^^^^^^^^^^^^^^^^^
  File "C:\Users\buiph\AppData\Roaming\Python\Python312\site-packages\spherov2\controls\v2.py", line 62, in parse_response
    raise PacketDecodingException('Unexpected start of packet')
spherov2.controls.PacketDecodingException: Unexpected start of packet
2024-12-12 23:35:21,343 [ERROR] Exception in callback Toy.__api_read(<bleak.backen...002D1B76BAF90>)(bytearray(b'\xf3\xd8'))
handle: <Handle Toy.__api_read(<bleak.backen...002D1B76BAF90>)(bytearray(b'\xf3\xd8'))>
Traceback (most recent call last):
  File "C:\Python312\Lib\asyncio\events.py", line 88, in _run
    self._context.run(self._callback, *self._args)
  File "C:\Users\buiph\AppData\Roaming\Python\Python312\site-packages\spherov2\toy\__init__.py", line 106, in __api_read
    self.__decoder.add(data)
  File "C:\Users\buiph\AppData\Roaming\Python\Python312\site-packages\spherov2\controls\v2.py", line 174, in add
    self.__callback(Packet.parse_response(pkt))
                    ^^^^^^^^^^^^^^^^^^^^^^^^^^
  File "C:\Users\buiph\AppData\Roaming\Python\Python312\site-packages\spherov2\controls\v2.py", line 67, in parse_response
    raise PacketDecodingException('Bad response checksum')
spherov2.controls.PacketDecodingException: Bad response checksum
2024-12-12 23:35:22,676 [ERROR] Exception in callback Toy.__api_read(<bleak.backen...001B47FCE6E10>)(bytearray(b'\t\xd8'))
handle: <Handle Toy.__api_read(<bleak.backen...001B47FCE6E10>)(bytearray(b'\t\xd8'))>
Traceback (most recent call last):
  File "C:\Python312\Lib\asyncio\events.py", line 88, in _run
    self._context.run(self._callback, *self._args)
  File "C:\Users\buiph\AppData\Roaming\Python\Python312\site-packages\spherov2\toy\__init__.py", line 106, in __api_read
    self.__decoder.add(data)
  File "C:\Users\buiph\AppData\Roaming\Python\Python312\site-packages\spherov2\controls\v2.py", line 173, in add
    raise PacketDecodingException(f'Very small packet {[hex(x) for x in pkt]}')
spherov2.controls.PacketDecodingException: Very small packet ['0x8d', '0x2', '0xff', '0x9', '0xd8']
2024-12-12 23:35:23,201 [ERROR] Exception in callback Toy.__api_read(<bleak.backen...00280D665B140>)(bytearray(b'\...xddp\xa8\xd8'))
handle: <Handle Toy.__api_read(<bleak.backen...00280D665B140>)(bytearray(b'\...xddp\xa8\xd8'))>
Traceback (most recent call last):
  File "C:\Python312\Lib\asyncio\events.py", line 88, in _run
    self._context.run(self._callback, *self._args)
  File "C:\Users\buiph\AppData\Roaming\Python\Python312\site-packages\spherov2\toy\__init__.py", line 106, in __api_read
    self.__decoder.add(data)
  File "C:\Users\buiph\AppData\Roaming\Python\Python312\site-packages\spherov2\controls\v2.py", line 174, in add
    self.__callback(Packet.parse_response(pkt))
                    ^^^^^^^^^^^^^^^^^^^^^^^^^^
  File "C:\Users\buiph\AppData\Roaming\Python\Python312\site-packages\spherov2\controls\v2.py", line 67, in parse_response
    raise PacketDecodingException('Bad response checksum')
spherov2.controls.PacketDecodingException: Bad response checksum
2024-12-12 23:35:23,290 [ERROR] Exception in callback Toy.__api_read(<bleak.backen...00164DC99EC30>)(bytearray(b'\xe1\x85\xd8'))
handle: <Handle Toy.__api_read(<bleak.backen...00164DC99EC30>)(bytearray(b'\xe1\x85\xd8'))>
Traceback (most recent call last):
  File "C:\Python312\Lib\asyncio\events.py", line 88, in _run
    self._context.run(self._callback, *self._args)
  File "C:\Users\buiph\AppData\Roaming\Python\Python312\site-packages\spherov2\toy\__init__.py", line 106, in __api_read
    self.__decoder.add(data)
  File "C:\Users\buiph\AppData\Roaming\Python\Python312\site-packages\spherov2\controls\v2.py", line 174, in add
    self.__callback(Packet.parse_response(pkt))
                    ^^^^^^^^^^^^^^^^^^^^^^^^^^
  File "C:\Users\buiph\AppData\Roaming\Python\Python312\site-packages\spherov2\controls\v2.py", line 67, in parse_response
    raise PacketDecodingException('Bad response checksum')
spherov2.controls.PacketDecodingException: Bad response checksum
2024-12-12 23:35:23,425 [ERROR] Exception in callback Toy.__api_read(<bleak.backen...001B47FCE6E10>)(bytearray(b'w\xd8'))
handle: <Handle Toy.__api_read(<bleak.backen...001B47FCE6E10>)(bytearray(b'w\xd8'))>
Traceback (most recent call last):
  File "C:\Python312\Lib\asyncio\events.py", line 88, in _run
    self._context.run(self._callback, *self._args)
  File "C:\Users\buiph\AppData\Roaming\Python\Python312\site-packages\spherov2\toy\__init__.py", line 106, in __api_read
    self.__decoder.add(data)
  File "C:\Users\buiph\AppData\Roaming\Python\Python312\site-packages\spherov2\controls\v2.py", line 173, in add
    raise PacketDecodingException(f'Very small packet {[hex(x) for x in pkt]}')
spherov2.controls.PacketDecodingException: Very small packet ['0x2', '0x77', '0xd8']
2024-12-12 23:35:23,654 [ERROR] Exception in callback Toy.__api_read(<bleak.backen...00164DC99EC30>)(bytearray(b'\...xda\xe1D\xd8'))
handle: <Handle Toy.__api_read(<bleak.backen...00164DC99EC30>)(bytearray(b'\...xda\xe1D\xd8'))>
Traceback (most recent call last):
  File "C:\Python312\Lib\asyncio\events.py", line 88, in _run
    self._context.run(self._callback, *self._args)
  File "C:\Users\buiph\AppData\Roaming\Python\Python312\site-packages\spherov2\toy\__init__.py", line 106, in __api_read
    self.__decoder.add(data)
  File "C:\Users\buiph\AppData\Roaming\Python\Python312\site-packages\spherov2\controls\v2.py", line 174, in add
    self.__callback(Packet.parse_response(pkt))
                    ^^^^^^^^^^^^^^^^^^^^^^^^^^
  File "C:\Users\buiph\AppData\Roaming\Python\Python312\site-packages\spherov2\controls\v2.py", line 67, in parse_response
    raise PacketDecodingException('Bad response checksum')
spherov2.controls.PacketDecodingException: Bad response checksum
2024-12-12 23:35:23,742 [ERROR] Exception in callback Toy.__api_read(<bleak.backen...001B47FCE6E10>)(bytearray(b'\xe6\xd8'))
handle: <Handle Toy.__api_read(<bleak.backen...001B47FCE6E10>)(bytearray(b'\xe6\xd8'))>
Traceback (most recent call last):
  File "C:\Python312\Lib\asyncio\events.py", line 88, in _run
    self._context.run(self._callback, *self._args)
  File "C:\Users\buiph\AppData\Roaming\Python\Python312\site-packages\spherov2\toy\__init__.py", line 106, in __api_read
    self.__decoder.add(data)
  File "C:\Users\buiph\AppData\Roaming\Python\Python312\site-packages\spherov2\controls\v2.py", line 174, in add
    self.__callback(Packet.parse_response(pkt))
                    ^^^^^^^^^^^^^^^^^^^^^^^^^^
  File "C:\Users\buiph\AppData\Roaming\Python\Python312\site-packages\spherov2\controls\v2.py", line 62, in parse_response
    raise PacketDecodingException('Unexpected start of packet')
spherov2.controls.PacketDecodingException: Unexpected start of packet
2024-12-12 23:35:24,888 [ERROR] Exception in callback Toy.__api_read(<bleak.backen...0027773DA6ED0>)(bytearray(b'\...\xe1\xa3\xd8'))
handle: <Handle Toy.__api_read(<bleak.backen...0027773DA6ED0>)(bytearray(b'\...\xe1\xa3\xd8'))>
Traceback (most recent call last):
  File "C:\Python312\Lib\asyncio\events.py", line 88, in _run
    self._context.run(self._callback, *self._args)
  File "C:\Users\buiph\AppData\Roaming\Python\Python312\site-packages\spherov2\toy\__init__.py", line 106, in __api_read
    self.__decoder.add(data)
  File "C:\Users\buiph\AppData\Roaming\Python\Python312\site-packages\spherov2\controls\v2.py", line 174, in add
    self.__callback(Packet.parse_response(pkt))
                    ^^^^^^^^^^^^^^^^^^^^^^^^^^
  File "C:\Users\buiph\AppData\Roaming\Python\Python312\site-packages\spherov2\controls\v2.py", line 62, in parse_response
    raise PacketDecodingException('Unexpected start of packet')
spherov2.controls.PacketDecodingException: Unexpected start of packet
2024-12-12 23:35:24,972 [ERROR] Exception in callback Toy.__api_read(<bleak.backen...002D1B76BAF90>)(bytearray(b'\xf9\xd8'))
handle: <Handle Toy.__api_read(<bleak.backen...002D1B76BAF90>)(bytearray(b'\xf9\xd8'))>
Traceback (most recent call last):
  File "C:\Python312\Lib\asyncio\events.py", line 88, in _run
    self._context.run(self._callback, *self._args)
  File "C:\Users\buiph\AppData\Roaming\Python\Python312\site-packages\spherov2\toy\__init__.py", line 106, in __api_read
    self.__decoder.add(data)
  File "C:\Users\buiph\AppData\Roaming\Python\Python312\site-packages\spherov2\controls\v2.py", line 174, in add
    self.__callback(Packet.parse_response(pkt))
                    ^^^^^^^^^^^^^^^^^^^^^^^^^^
  File "C:\Users\buiph\AppData\Roaming\Python\Python312\site-packages\spherov2\controls\v2.py", line 67, in parse_response
    raise PacketDecodingException('Bad response checksum')
spherov2.controls.PacketDecodingException: Bad response checksum
2024-12-12 23:35:25,244 [ERROR] Exception in callback Toy.__api_read(<bleak.backen...00164DC99EC30>)(bytearray(b'*\xd8'))
handle: <Handle Toy.__api_read(<bleak.backen...00164DC99EC30>)(bytearray(b'*\xd8'))>
Traceback (most recent call last):
  File "C:\Python312\Lib\asyncio\events.py", line 88, in _run
    self._context.run(self._callback, *self._args)
  File "C:\Users\buiph\AppData\Roaming\Python\Python312\site-packages\spherov2\toy\__init__.py", line 106, in __api_read
    self.__decoder.add(data)
  File "C:\Users\buiph\AppData\Roaming\Python\Python312\site-packages\spherov2\controls\v2.py", line 174, in add
    self.__callback(Packet.parse_response(pkt))
                    ^^^^^^^^^^^^^^^^^^^^^^^^^^
  File "C:\Users\buiph\AppData\Roaming\Python\Python312\site-packages\spherov2\controls\v2.py", line 62, in parse_response
    raise PacketDecodingException('Unexpected start of packet')
spherov2.controls.PacketDecodingException: Unexpected start of packet
2024-12-12 23:35:25,394 [ERROR] Exception in callback Toy.__api_read(<bleak.backen...0027773DA6ED0>)(bytearray(b'="\xd8'))
handle: <Handle Toy.__api_read(<bleak.backen...0027773DA6ED0>)(bytearray(b'="\xd8'))>
Traceback (most recent call last):
  File "C:\Python312\Lib\asyncio\events.py", line 88, in _run
    self._context.run(self._callback, *self._args)
  File "C:\Users\buiph\AppData\Roaming\Python\Python312\site-packages\spherov2\toy\__init__.py", line 106, in __api_read
    self.__decoder.add(data)
  File "C:\Users\buiph\AppData\Roaming\Python\Python312\site-packages\spherov2\controls\v2.py", line 174, in add
    self.__callback(Packet.parse_response(pkt))
                    ^^^^^^^^^^^^^^^^^^^^^^^^^^
  File "C:\Users\buiph\AppData\Roaming\Python\Python312\site-packages\spherov2\controls\v2.py", line 62, in parse_response
    raise PacketDecodingException('Unexpected start of packet')
spherov2.controls.PacketDecodingException: Unexpected start of packet
2024-12-12 23:35:25,454 [ERROR] Exception in callback Toy.__api_read(<bleak.backen...00164DC99EC30>)(bytearray(b'\xb7\xd8'))
handle: <Handle Toy.__api_read(<bleak.backen...00164DC99EC30>)(bytearray(b'\xb7\xd8'))>
Traceback (most recent call last):
  File "C:\Python312\Lib\asyncio\events.py", line 88, in _run
    self._context.run(self._callback, *self._args)
  File "C:\Users\buiph\AppData\Roaming\Python\Python312\site-packages\spherov2\toy\__init__.py", line 106, in __api_read
    self.__decoder.add(data)
  File "C:\Users\buiph\AppData\Roaming\Python\Python312\site-packages\spherov2\controls\v2.py", line 174, in add
    self.__callback(Packet.parse_response(pkt))
                    ^^^^^^^^^^^^^^^^^^^^^^^^^^
  File "C:\Users\buiph\AppData\Roaming\Python\Python312\site-packages\spherov2\controls\v2.py", line 62, in parse_response
    raise PacketDecodingException('Unexpected start of packet')
spherov2.controls.PacketDecodingException: Unexpected start of packet
2024-12-12 23:35:25,492 [ERROR] Exception in callback Toy.__api_read(<bleak.backen...00280D665B140>)(bytearray(b'\x14_\xd8'))
handle: <Handle Toy.__api_read(<bleak.backen...00280D665B140>)(bytearray(b'\x14_\xd8'))>
Traceback (most recent call last):
  File "C:\Python312\Lib\asyncio\events.py", line 88, in _run
    self._context.run(self._callback, *self._args)
  File "C:\Users\buiph\AppData\Roaming\Python\Python312\site-packages\spherov2\toy\__init__.py", line 106, in __api_read
    self.__decoder.add(data)
  File "C:\Users\buiph\AppData\Roaming\Python\Python312\site-packages\spherov2\controls\v2.py", line 174, in add
    self.__callback(Packet.parse_response(pkt))
                    ^^^^^^^^^^^^^^^^^^^^^^^^^^
  File "C:\Users\buiph\AppData\Roaming\Python\Python312\site-packages\spherov2\controls\v2.py", line 62, in parse_response
    raise PacketDecodingException('Unexpected start of packet')
spherov2.controls.PacketDecodingException: Unexpected start of packet
2024-12-12 23:35:25,497 [ERROR] Exception in callback Toy.__api_read(<bleak.backen...00280D665B140>)(bytearray(b'\...xddp\x93\xd8'))
handle: <Handle Toy.__api_read(<bleak.backen...00280D665B140>)(bytearray(b'\...xddp\x93\xd8'))>
Traceback (most recent call last):
  File "C:\Python312\Lib\asyncio\events.py", line 88, in _run
    self._context.run(self._callback, *self._args)
  File "C:\Users\buiph\AppData\Roaming\Python\Python312\site-packages\spherov2\toy\__init__.py", line 106, in __api_read
    self.__decoder.add(data)
  File "C:\Users\buiph\AppData\Roaming\Python\Python312\site-packages\spherov2\controls\v2.py", line 174, in add
    self.__callback(Packet.parse_response(pkt))
                    ^^^^^^^^^^^^^^^^^^^^^^^^^^
  File "C:\Users\buiph\AppData\Roaming\Python\Python312\site-packages\spherov2\controls\v2.py", line 62, in parse_response
    raise PacketDecodingException('Unexpected start of packet')
spherov2.controls.PacketDecodingException: Unexpected start of packet
2024-12-12 23:35:25,503 [ERROR] Exception in callback Toy.__api_read(<bleak.backen...0027773DA6ED0>)(bytearray(b'\...xda\xe1I\xd8'))
handle: <Handle Toy.__api_read(<bleak.backen...0027773DA6ED0>)(bytearray(b'\...xda\xe1I\xd8'))>
Traceback (most recent call last):
  File "C:\Python312\Lib\asyncio\events.py", line 88, in _run
    self._context.run(self._callback, *self._args)
  File "C:\Users\buiph\AppData\Roaming\Python\Python312\site-packages\spherov2\toy\__init__.py", line 106, in __api_read
    self.__decoder.add(data)
  File "C:\Users\buiph\AppData\Roaming\Python\Python312\site-packages\spherov2\controls\v2.py", line 174, in add
    self.__callback(Packet.parse_response(pkt))
                    ^^^^^^^^^^^^^^^^^^^^^^^^^^
  File "C:\Users\buiph\AppData\Roaming\Python\Python312\site-packages\spherov2\controls\v2.py", line 62, in parse_response
    raise PacketDecodingException('Unexpected start of packet')
spherov2.controls.PacketDecodingException: Unexpected start of packet
2024-12-12 23:35:25,507 [ERROR] Exception in callback Toy.__api_read(<bleak.backen...00164DC99EC30>)(bytearray(b'\xc7\xd8'))
handle: <Handle Toy.__api_read(<bleak.backen...00164DC99EC30>)(bytearray(b'\xc7\xd8'))>
Traceback (most recent call last):
  File "C:\Python312\Lib\asyncio\events.py", line 88, in _run
    self._context.run(self._callback, *self._args)
  File "C:\Users\buiph\AppData\Roaming\Python\Python312\site-packages\spherov2\toy\__init__.py", line 106, in __api_read
    self.__decoder.add(data)
  File "C:\Users\buiph\AppData\Roaming\Python\Python312\site-packages\spherov2\controls\v2.py", line 174, in add
    self.__callback(Packet.parse_response(pkt))
                    ^^^^^^^^^^^^^^^^^^^^^^^^^^
  File "C:\Users\buiph\AppData\Roaming\Python\Python312\site-packages\spherov2\controls\v2.py", line 62, in parse_response
    raise PacketDecodingException('Unexpected start of packet')
spherov2.controls.PacketDecodingException: Unexpected start of packet
2024-12-12 23:35:25,510 [ERROR] Exception in callback Toy.__api_read(<bleak.backen...00164DC99EC30>)(bytearray(b'h\xd8'))
handle: <Handle Toy.__api_read(<bleak.backen...00164DC99EC30>)(bytearray(b'h\xd8'))>
Traceback (most recent call last):
  File "C:\Python312\Lib\asyncio\events.py", line 88, in _run
    self._context.run(self._callback, *self._args)
  File "C:\Users\buiph\AppData\Roaming\Python\Python312\site-packages\spherov2\toy\__init__.py", line 106, in __api_read
    self.__decoder.add(data)
  File "C:\Users\buiph\AppData\Roaming\Python\Python312\site-packages\spherov2\controls\v2.py", line 174, in add
    self.__callback(Packet.parse_response(pkt))
                    ^^^^^^^^^^^^^^^^^^^^^^^^^^
  File "C:\Users\buiph\AppData\Roaming\Python\Python312\site-packages\spherov2\controls\v2.py", line 62, in parse_response
    raise PacketDecodingException('Unexpected start of packet')
spherov2.controls.PacketDecodingException: Unexpected start of packet
2024-12-12 23:35:25,512 [ERROR] Exception in callback Toy.__api_read(<bleak.backen...002D1B76BAF90>)(bytearray(b'1\xd8'))
handle: <Handle Toy.__api_read(<bleak.backen...002D1B76BAF90>)(bytearray(b'1\xd8'))>
Traceback (most recent call last):
  File "C:\Python312\Lib\asyncio\events.py", line 88, in _run
    self._context.run(self._callback, *self._args)
  File "C:\Users\buiph\AppData\Roaming\Python\Python312\site-packages\spherov2\toy\__init__.py", line 106, in __api_read
    self.__decoder.add(data)
  File "C:\Users\buiph\AppData\Roaming\Python\Python312\site-packages\spherov2\controls\v2.py", line 173, in add
    raise PacketDecodingException(f'Very small packet {[hex(x) for x in pkt]}')
spherov2.controls.PacketDecodingException: Very small packet ['0x8d', '0x30', '0x11', '0x31', '0xd8']
2024-12-12 23:35:25,515 [ERROR] Exception in callback Toy.__api_read(<bleak.backen...001B47FCE6E10>)(bytearray(b'u...xdc)\xb2\xd8'))
handle: <Handle Toy.__api_read(<bleak.backen...001B47FCE6E10>)(bytearray(b'u...xdc)\xb2\xd8'))>
Traceback (most recent call last):
  File "C:\Python312\Lib\asyncio\events.py", line 88, in _run
    self._context.run(self._callback, *self._args)
  File "C:\Users\buiph\AppData\Roaming\Python\Python312\site-packages\spherov2\toy\__init__.py", line 106, in __api_read
    self.__decoder.add(data)
  File "C:\Users\buiph\AppData\Roaming\Python\Python312\site-packages\spherov2\controls\v2.py", line 174, in add
    self.__callback(Packet.parse_response(pkt))
                    ^^^^^^^^^^^^^^^^^^^^^^^^^^
  File "C:\Users\buiph\AppData\Roaming\Python\Python312\site-packages\spherov2\controls\v2.py", line 62, in parse_response
    raise PacketDecodingException('Unexpected start of packet')
spherov2.controls.PacketDecodingException: Unexpected start of packet
2024-12-12 23:35:25,521 [ERROR] Exception in callback Toy.__api_read(<bleak.backen...00164DC99EC30>)(bytearray(b'.\xd8'))
handle: <Handle Toy.__api_read(<bleak.backen...00164DC99EC30>)(bytearray(b'.\xd8'))>
Traceback (most recent call last):
  File "C:\Python312\Lib\asyncio\events.py", line 88, in _run
    self._context.run(self._callback, *self._args)
  File "C:\Users\buiph\AppData\Roaming\Python\Python312\site-packages\spherov2\toy\__init__.py", line 106, in __api_read
    self.__decoder.add(data)
  File "C:\Users\buiph\AppData\Roaming\Python\Python312\site-packages\spherov2\controls\v2.py", line 173, in add
    raise PacketDecodingException(f'Very small packet {[hex(x) for x in pkt]}')
spherov2.controls.PacketDecodingException: Very small packet ['0xff', '0x2e', '0xd8']
2024-12-12 23:35:25,532 [ERROR] Exception in callback Toy.__api_read(<bleak.backen...00280D665B140>)(bytearray(b'\x14\xd7\xd8'))
handle: <Handle Toy.__api_read(<bleak.backen...00280D665B140>)(bytearray(b'\x14\xd7\xd8'))>
Traceback (most recent call last):
  File "C:\Python312\Lib\asyncio\events.py", line 88, in _run
    self._context.run(self._callback, *self._args)
  File "C:\Users\buiph\AppData\Roaming\Python\Python312\site-packages\spherov2\toy\__init__.py", line 106, in __api_read
    self.__decoder.add(data)
  File "C:\Users\buiph\AppData\Roaming\Python\Python312\site-packages\spherov2\controls\v2.py", line 174, in add
    self.__callback(Packet.parse_response(pkt))
                    ^^^^^^^^^^^^^^^^^^^^^^^^^^
  File "C:\Users\buiph\AppData\Roaming\Python\Python312\site-packages\spherov2\controls\v2.py", line 62, in parse_response
    raise PacketDecodingException('Unexpected start of packet')
spherov2.controls.PacketDecodingException: Unexpected start of packet
2024-12-12 23:35:25,534 [ERROR] Exception in callback Toy.__api_read(<bleak.backen...0027773DA6ED0>)(bytearray(b'\xe1\xa0\xd8'))
handle: <Handle Toy.__api_read(<bleak.backen...0027773DA6ED0>)(bytearray(b'\xe1\xa0\xd8'))>
Traceback (most recent call last):
  File "C:\Python312\Lib\asyncio\events.py", line 88, in _run
    self._context.run(self._callback, *self._args)
  File "C:\Users\buiph\AppData\Roaming\Python\Python312\site-packages\spherov2\toy\__init__.py", line 106, in __api_read
    self.__decoder.add(data)
  File "C:\Users\buiph\AppData\Roaming\Python\Python312\site-packages\spherov2\controls\v2.py", line 174, in add
    self.__callback(Packet.parse_response(pkt))
                    ^^^^^^^^^^^^^^^^^^^^^^^^^^
  File "C:\Users\buiph\AppData\Roaming\Python\Python312\site-packages\spherov2\controls\v2.py", line 62, in parse_response
    raise PacketDecodingException('Unexpected start of packet')
spherov2.controls.PacketDecodingException: Unexpected start of packet
2024-12-12 23:35:25,536 [ERROR] Exception in callback Toy.__api_read(<bleak.backen...002D1B76BAF90>)(bytearray(b'\xaf\xd8'))
handle: <Handle Toy.__api_read(<bleak.backen...002D1B76BAF90>)(bytearray(b'\xaf\xd8'))>
Traceback (most recent call last):
  File "C:\Python312\Lib\asyncio\events.py", line 88, in _run
    self._context.run(self._callback, *self._args)
  File "C:\Users\buiph\AppData\Roaming\Python\Python312\site-packages\spherov2\toy\__init__.py", line 106, in __api_read
    self.__decoder.add(data)
  File "C:\Users\buiph\AppData\Roaming\Python\Python312\site-packages\spherov2\controls\v2.py", line 174, in add
    self.__callback(Packet.parse_response(pkt))
                    ^^^^^^^^^^^^^^^^^^^^^^^^^^
  File "C:\Users\buiph\AppData\Roaming\Python\Python312\site-packages\spherov2\controls\v2.py", line 67, in parse_response
    raise PacketDecodingException('Bad response checksum')
spherov2.controls.PacketDecodingException: Bad response checksum
2024-12-12 23:35:25,538 [ERROR] Exception in callback Toy.__api_read(<bleak.backen...0027773DA6ED0>)(bytearray(b'\xda\xe1\xc5\xd8'))
handle: <Handle Toy.__api_read(<bleak.backen...0027773DA6ED0>)(bytearray(b'\xda\xe1\xc5\xd8'))>
Traceback (most recent call last):
  File "C:\Python312\Lib\asyncio\events.py", line 88, in _run
    self._context.run(self._callback, *self._args)
  File "C:\Users\buiph\AppData\Roaming\Python\Python312\site-packages\spherov2\toy\__init__.py", line 106, in __api_read
    self.__decoder.add(data)
  File "C:\Users\buiph\AppData\Roaming\Python\Python312\site-packages\spherov2\controls\v2.py", line 174, in add
    self.__callback(Packet.parse_response(pkt))
                    ^^^^^^^^^^^^^^^^^^^^^^^^^^
  File "C:\Users\buiph\AppData\Roaming\Python\Python312\site-packages\spherov2\controls\v2.py", line 62, in parse_response
    raise PacketDecodingException('Unexpected start of packet')
spherov2.controls.PacketDecodingException: Unexpected start of packet
2024-12-12 23:35:25,541 [ERROR] Exception in callback Toy.__api_read(<bleak.backen...0027773DA6ED0>)(bytearray(b'Z=\xc7\xd8'))
handle: <Handle Toy.__api_read(<bleak.backen...0027773DA6ED0>)(bytearray(b'Z=\xc7\xd8'))>
Traceback (most recent call last):
  File "C:\Python312\Lib\asyncio\events.py", line 88, in _run
    self._context.run(self._callback, *self._args)
  File "C:\Users\buiph\AppData\Roaming\Python\Python312\site-packages\spherov2\toy\__init__.py", line 106, in __api_read
    self.__decoder.add(data)
  File "C:\Users\buiph\AppData\Roaming\Python\Python312\site-packages\spherov2\controls\v2.py", line 174, in add
    self.__callback(Packet.parse_response(pkt))
                    ^^^^^^^^^^^^^^^^^^^^^^^^^^
  File "C:\Users\buiph\AppData\Roaming\Python\Python312\site-packages\spherov2\controls\v2.py", line 62, in parse_response
    raise PacketDecodingException('Unexpected start of packet')
spherov2.controls.PacketDecodingException: Unexpected start of packet
2024-12-12 23:35:25,544 [ERROR] Exception in callback Toy.__api_read(<bleak.backen...0027773DA6ED0>)(bytearray(b'\xe1\xdc\xd8'))
handle: <Handle Toy.__api_read(<bleak.backen...0027773DA6ED0>)(bytearray(b'\xe1\xdc\xd8'))>
Traceback (most recent call last):
  File "C:\Python312\Lib\asyncio\events.py", line 88, in _run
    self._context.run(self._callback, *self._args)
  File "C:\Users\buiph\AppData\Roaming\Python\Python312\site-packages\spherov2\toy\__init__.py", line 106, in __api_read
    self.__decoder.add(data)
  File "C:\Users\buiph\AppData\Roaming\Python\Python312\site-packages\spherov2\controls\v2.py", line 174, in add
    self.__callback(Packet.parse_response(pkt))
                    ^^^^^^^^^^^^^^^^^^^^^^^^^^
  File "C:\Users\buiph\AppData\Roaming\Python\Python312\site-packages\spherov2\controls\v2.py", line 62, in parse_response
    raise PacketDecodingException('Unexpected start of packet')
spherov2.controls.PacketDecodingException: Unexpected start of packet
2024-12-12 23:35:25,556 [ERROR] Exception in callback Toy.__api_read(<bleak.backen...00280D665B140>)(bytearray(b'\...xddp\xbc\xd8'))
handle: <Handle Toy.__api_read(<bleak.backen...00280D665B140>)(bytearray(b'\...xddp\xbc\xd8'))>
Traceback (most recent call last):
  File "C:\Python312\Lib\asyncio\events.py", line 88, in _run
    self._context.run(self._callback, *self._args)
  File "C:\Users\buiph\AppData\Roaming\Python\Python312\site-packages\spherov2\toy\__init__.py", line 106, in __api_read
    self.__decoder.add(data)
  File "C:\Users\buiph\AppData\Roaming\Python\Python312\site-packages\spherov2\controls\v2.py", line 174, in add
    self.__callback(Packet.parse_response(pkt))
                    ^^^^^^^^^^^^^^^^^^^^^^^^^^
  File "C:\Users\buiph\AppData\Roaming\Python\Python312\site-packages\spherov2\controls\v2.py", line 62, in parse_response
    raise PacketDecodingException('Unexpected start of packet')
spherov2.controls.PacketDecodingException: Unexpected start of packet
2024-12-12 23:35:25,573 [ERROR] Exception in callback Toy.__api_read(<bleak.backen...00164DC99EC30>)(bytearray(b'\x85\xe2\xd8'))
handle: <Handle Toy.__api_read(<bleak.backen...00164DC99EC30>)(bytearray(b'\x85\xe2\xd8'))>
Traceback (most recent call last):
  File "C:\Python312\Lib\asyncio\events.py", line 88, in _run
    self._context.run(self._callback, *self._args)
  File "C:\Users\buiph\AppData\Roaming\Python\Python312\site-packages\spherov2\toy\__init__.py", line 106, in __api_read
    self.__decoder.add(data)
  File "C:\Users\buiph\AppData\Roaming\Python\Python312\site-packages\spherov2\controls\v2.py", line 174, in add
    self.__callback(Packet.parse_response(pkt))
                    ^^^^^^^^^^^^^^^^^^^^^^^^^^
  File "C:\Users\buiph\AppData\Roaming\Python\Python312\site-packages\spherov2\controls\v2.py", line 62, in parse_response
    raise PacketDecodingException('Unexpected start of packet')
spherov2.controls.PacketDecodingException: Unexpected start of packet
2024-12-12 23:35:25,589 [ERROR] Exception in callback Toy.__api_read(<bleak.backen...001B47FCE6E10>)(bytearray(b'\xb6\xd8'))
handle: <Handle Toy.__api_read(<bleak.backen...001B47FCE6E10>)(bytearray(b'\xb6\xd8'))>
Traceback (most recent call last):
  File "C:\Python312\Lib\asyncio\events.py", line 88, in _run
    self._context.run(self._callback, *self._args)
  File "C:\Users\buiph\AppData\Roaming\Python\Python312\site-packages\spherov2\toy\__init__.py", line 106, in __api_read
    self.__decoder.add(data)
  File "C:\Users\buiph\AppData\Roaming\Python\Python312\site-packages\spherov2\controls\v2.py", line 174, in add
    self.__callback(Packet.parse_response(pkt))
                    ^^^^^^^^^^^^^^^^^^^^^^^^^^
  File "C:\Users\buiph\AppData\Roaming\Python\Python312\site-packages\spherov2\controls\v2.py", line 62, in parse_response
    raise PacketDecodingException('Unexpected start of packet')
spherov2.controls.PacketDecodingException: Unexpected start of packet
2024-12-12 23:35:25,594 [ERROR] Exception in callback Toy.__api_read(<bleak.backen...0027773DA6ED0>)(bytearray(b'\...\xe1\xbc\xd8'))
handle: <Handle Toy.__api_read(<bleak.backen...0027773DA6ED0>)(bytearray(b'\...\xe1\xbc\xd8'))>
Traceback (most recent call last):
  File "C:\Python312\Lib\asyncio\events.py", line 88, in _run
    self._context.run(self._callback, *self._args)
  File "C:\Users\buiph\AppData\Roaming\Python\Python312\site-packages\spherov2\toy\__init__.py", line 106, in __api_read
    self.__decoder.add(data)
  File "C:\Users\buiph\AppData\Roaming\Python\Python312\site-packages\spherov2\controls\v2.py", line 174, in add
    self.__callback(Packet.parse_response(pkt))
                    ^^^^^^^^^^^^^^^^^^^^^^^^^^
  File "C:\Users\buiph\AppData\Roaming\Python\Python312\site-packages\spherov2\controls\v2.py", line 67, in parse_response
    raise PacketDecodingException('Bad response checksum')
spherov2.controls.PacketDecodingException: Bad response checksum
2024-12-12 23:35:25,604 [ERROR] Exception in callback Toy.__api_read(<bleak.backen...0027773DA6ED0>)(bytearray(b'\x99\t\xd8'))
handle: <Handle Toy.__api_read(<bleak.backen...0027773DA6ED0>)(bytearray(b'\x99\t\xd8'))>
Traceback (most recent call last):
  File "C:\Python312\Lib\asyncio\events.py", line 88, in _run
    self._context.run(self._callback, *self._args)
  File "C:\Users\buiph\AppData\Roaming\Python\Python312\site-packages\spherov2\toy\__init__.py", line 106, in __api_read
    self.__decoder.add(data)
  File "C:\Users\buiph\AppData\Roaming\Python\Python312\site-packages\spherov2\controls\v2.py", line 174, in add
    self.__callback(Packet.parse_response(pkt))
                    ^^^^^^^^^^^^^^^^^^^^^^^^^^
  File "C:\Users\buiph\AppData\Roaming\Python\Python312\site-packages\spherov2\controls\v2.py", line 67, in parse_response
    raise PacketDecodingException('Bad response checksum')
spherov2.controls.PacketDecodingException: Bad response checksum
2024-12-12 23:35:29,387 [ERROR] Exception in callback Toy.__api_read(<bleak.backen...002D1B76BAF90>)(bytearray(b'\...xde\xb8 \xd8'))
handle: <Handle Toy.__api_read(<bleak.backen...002D1B76BAF90>)(bytearray(b'\...xde\xb8 \xd8'))>
Traceback (most recent call last):
  File "C:\Python312\Lib\asyncio\events.py", line 88, in _run
    self._context.run(self._callback, *self._args)
  File "C:\Users\buiph\AppData\Roaming\Python\Python312\site-packages\spherov2\toy\__init__.py", line 106, in __api_read
    self.__decoder.add(data)
  File "C:\Users\buiph\AppData\Roaming\Python\Python312\site-packages\spherov2\controls\v2.py", line 174, in add
    self.__callback(Packet.parse_response(pkt))
                    ^^^^^^^^^^^^^^^^^^^^^^^^^^
  File "C:\Users\buiph\AppData\Roaming\Python\Python312\site-packages\spherov2\controls\v2.py", line 62, in parse_response
    raise PacketDecodingException('Unexpected start of packet')
spherov2.controls.PacketDecodingException: Unexpected start of packet
2024-12-12 23:35:29,432 [ERROR] Exception in callback Toy.__api_read(<bleak.backen...00280D665B140>)(bytearray(b'\xddp\x92\xd8'))
handle: <Handle Toy.__api_read(<bleak.backen...00280D665B140>)(bytearray(b'\xddp\x92\xd8'))>
Traceback (most recent call last):
  File "C:\Python312\Lib\asyncio\events.py", line 88, in _run
    self._context.run(self._callback, *self._args)
  File "C:\Users\buiph\AppData\Roaming\Python\Python312\site-packages\spherov2\toy\__init__.py", line 106, in __api_read
    self.__decoder.add(data)
  File "C:\Users\buiph\AppData\Roaming\Python\Python312\site-packages\spherov2\controls\v2.py", line 174, in add
    self.__callback(Packet.parse_response(pkt))
                    ^^^^^^^^^^^^^^^^^^^^^^^^^^
  File "C:\Users\buiph\AppData\Roaming\Python\Python312\site-packages\spherov2\controls\v2.py", line 67, in parse_response
    raise PacketDecodingException('Bad response checksum')
spherov2.controls.PacketDecodingException: Bad response checksum
2024-12-12 23:35:29,447 [ERROR] Exception in callback Toy.__api_read(<bleak.backen...0027773DA6ED0>)(bytearray(b'\xda\xe1\xca\xd8'))
handle: <Handle Toy.__api_read(<bleak.backen...0027773DA6ED0>)(bytearray(b'\xda\xe1\xca\xd8'))>
Traceback (most recent call last):
  File "C:\Python312\Lib\asyncio\events.py", line 88, in _run
    self._context.run(self._callback, *self._args)
  File "C:\Users\buiph\AppData\Roaming\Python\Python312\site-packages\spherov2\toy\__init__.py", line 106, in __api_read
    self.__decoder.add(data)
  File "C:\Users\buiph\AppData\Roaming\Python\Python312\site-packages\spherov2\controls\v2.py", line 174, in add
    self.__callback(Packet.parse_response(pkt))
                    ^^^^^^^^^^^^^^^^^^^^^^^^^^
  File "C:\Users\buiph\AppData\Roaming\Python\Python312\site-packages\spherov2\controls\v2.py", line 67, in parse_response
    raise PacketDecodingException('Bad response checksum')
spherov2.controls.PacketDecodingException: Bad response checksum
2024-12-13 00:00:14,023 [INFO] SB-2E86: Attempting to connect.
2024-12-13 00:00:17,428 [INFO] SB-4844: Attempting to connect.
2024-12-13 00:00:18,066 [ERROR] WebSocket Sender: Connection error: [WinError 1225] The remote computer refused the network connection
2024-12-13 00:00:18,066 [ERROR] WebSocket: Connection error: [WinError 1225] The remote computer refused the network connection
2024-12-13 00:00:18,066 [WARNING] WebSocket Sender: Closing connection.
2024-12-13 00:00:18,067 [WARNING] WebSocket: Closing connection.
2024-12-13 00:00:18,996 [INFO] SB-4844: Connected to Sphero.
2024-12-13 00:00:19,367 [WARNING] SB-2E86: Sphero not found. Ensure it is powered on and in range. Retrying...
2024-12-13 00:00:21,511 [INFO] SB-7104: Attempting to connect.
2024-12-13 00:00:24,057 [ERROR] SB-4844: Failed to initialize or maintain connection to Sphero: Device with address DD:D1:3C:95:48:44 was not found.
2024-12-13 00:00:24,058 [WARNING] SB-4844: Sphero connection closed. Retrying...
2024-12-13 00:00:25,680 [INFO] SB-D8B2: Attempting to connect.
2024-12-13 00:00:25,970 [INFO] SB-D8B2: Connected to Sphero.
2024-12-13 00:00:26,740 [WARNING] SB-7104: Sphero not found. Ensure it is powered on and in range. Retrying...
2024-12-13 00:00:28,398 [WARNING] SB-2E86: Sphero not found. Ensure it is powered on and in range. Retrying...
2024-12-13 00:00:29,168 [INFO] SB-4844: Connected to Sphero.
2024-12-13 00:00:29,810 [INFO] SB-E12C: Attempting to connect.
2024-12-13 00:00:30,208 [INFO] SB-E12C: Connected to Sphero.
2024-12-13 00:00:32,716 [INFO] Main: All processes started.
2024-12-13 00:00:33,334 [INFO] SB-7104: Connected to Sphero.
2024-12-13 00:00:33,551 [INFO] SB-D8B2: Calibrating compass.
2024-12-13 00:00:34,308 [INFO] SB-4844: Calibrating compass.
2024-12-13 00:00:37,098 [INFO] SB-E12C: Calibrating compass.
2024-12-13 00:00:37,457 [WARNING] SB-2E86: Sphero not found. Ensure it is powered on and in range. Retrying...
2024-12-13 00:00:38,943 [INFO] SB-D8B2: Initialization complete.
2024-12-13 00:00:38,944 [INFO] SB-D8B2: Subscribed to message bus.
2024-12-13 00:00:39,126 [INFO] SB-7104: Calibrating compass.
2024-12-13 00:00:39,720 [INFO] SB-4844: Initialization complete.
2024-12-13 00:00:39,722 [INFO] SB-4844: Subscribed to message bus.
2024-12-13 00:00:42,425 [INFO] SB-E12C: Initialization complete.
2024-12-13 00:00:42,425 [INFO] SB-E12C: Subscribed to message bus.
2024-12-13 00:00:43,377 [ERROR] Exception in callback Toy.__api_read(<bleak.backen...0027DA1A9B2F0>)(bytearray(b'\x1e\xd5\xd8'))
handle: <Handle Toy.__api_read(<bleak.backen...0027DA1A9B2F0>)(bytearray(b'\x1e\xd5\xd8'))>
Traceback (most recent call last):
  File "C:\Python312\Lib\asyncio\events.py", line 88, in _run
    self._context.run(self._callback, *self._args)
  File "C:\Users\buiph\AppData\Roaming\Python\Python312\site-packages\spherov2\toy\__init__.py", line 106, in __api_read
    self.__decoder.add(data)
  File "C:\Users\buiph\AppData\Roaming\Python\Python312\site-packages\spherov2\controls\v2.py", line 174, in add
    self.__callback(Packet.parse_response(pkt))
                    ^^^^^^^^^^^^^^^^^^^^^^^^^^
  File "C:\Users\buiph\AppData\Roaming\Python\Python312\site-packages\spherov2\controls\v2.py", line 67, in parse_response
    raise PacketDecodingException('Bad response checksum')
spherov2.controls.PacketDecodingException: Bad response checksum
2024-12-13 00:00:43,404 [ERROR] Exception in callback Toy.__api_read(<bleak.backen...0013DFF8CB380>)(bytearray(b'\x14\x03\xd8'))
handle: <Handle Toy.__api_read(<bleak.backen...0013DFF8CB380>)(bytearray(b'\x14\x03\xd8'))>
Traceback (most recent call last):
  File "C:\Python312\Lib\asyncio\events.py", line 88, in _run
    self._context.run(self._callback, *self._args)
  File "C:\Users\buiph\AppData\Roaming\Python\Python312\site-packages\spherov2\toy\__init__.py", line 106, in __api_read
    self.__decoder.add(data)
  File "C:\Users\buiph\AppData\Roaming\Python\Python312\site-packages\spherov2\controls\v2.py", line 174, in add
    self.__callback(Packet.parse_response(pkt))
                    ^^^^^^^^^^^^^^^^^^^^^^^^^^
  File "C:\Users\buiph\AppData\Roaming\Python\Python312\site-packages\spherov2\controls\v2.py", line 67, in parse_response
    raise PacketDecodingException('Bad response checksum')
spherov2.controls.PacketDecodingException: Bad response checksum
2024-12-13 00:00:43,430 [ERROR] Exception in callback Toy.__api_read(<bleak.backen...0013473486ED0>)(bytearray(b'\x14|\xd8'))
handle: <Handle Toy.__api_read(<bleak.backen...0013473486ED0>)(bytearray(b'\x14|\xd8'))>
Traceback (most recent call last):
  File "C:\Python312\Lib\asyncio\events.py", line 88, in _run
    self._context.run(self._callback, *self._args)
  File "C:\Users\buiph\AppData\Roaming\Python\Python312\site-packages\spherov2\toy\__init__.py", line 106, in __api_read
    self.__decoder.add(data)
  File "C:\Users\buiph\AppData\Roaming\Python\Python312\site-packages\spherov2\controls\v2.py", line 174, in add
    self.__callback(Packet.parse_response(pkt))
                    ^^^^^^^^^^^^^^^^^^^^^^^^^^
  File "C:\Users\buiph\AppData\Roaming\Python\Python312\site-packages\spherov2\controls\v2.py", line 67, in parse_response
    raise PacketDecodingException('Bad response checksum')
spherov2.controls.PacketDecodingException: Bad response checksum
2024-12-13 00:00:43,563 [ERROR] Exception in callback Toy.__api_read(<bleak.backen...0013DFF8CB380>)(bytearray(b'\...\xb8\x0e\xd8'))
handle: <Handle Toy.__api_read(<bleak.backen...0013DFF8CB380>)(bytearray(b'\...\xb8\x0e\xd8'))>
Traceback (most recent call last):
  File "C:\Python312\Lib\asyncio\events.py", line 88, in _run
    self._context.run(self._callback, *self._args)
  File "C:\Users\buiph\AppData\Roaming\Python\Python312\site-packages\spherov2\toy\__init__.py", line 106, in __api_read
    self.__decoder.add(data)
  File "C:\Users\buiph\AppData\Roaming\Python\Python312\site-packages\spherov2\controls\v2.py", line 174, in add
    self.__callback(Packet.parse_response(pkt))
                    ^^^^^^^^^^^^^^^^^^^^^^^^^^
  File "C:\Users\buiph\AppData\Roaming\Python\Python312\site-packages\spherov2\controls\v2.py", line 67, in parse_response
    raise PacketDecodingException('Bad response checksum')
spherov2.controls.PacketDecodingException: Bad response checksum
2024-12-13 00:00:43,565 [ERROR] Exception in callback Toy.__api_read(<bleak.backen...0013DFF8CB380>)(bytearray(b'\...x00\x04{\xd8'))
handle: <Handle Toy.__api_read(<bleak.backen...0013DFF8CB380>)(bytearray(b'\...x00\x04{\xd8'))>
Traceback (most recent call last):
  File "C:\Python312\Lib\asyncio\events.py", line 88, in _run
    self._context.run(self._callback, *self._args)
  File "C:\Users\buiph\AppData\Roaming\Python\Python312\site-packages\spherov2\toy\__init__.py", line 106, in __api_read
    self.__decoder.add(data)
  File "C:\Users\buiph\AppData\Roaming\Python\Python312\site-packages\spherov2\controls\v2.py", line 174, in add
    self.__callback(Packet.parse_response(pkt))
                    ^^^^^^^^^^^^^^^^^^^^^^^^^^
  File "C:\Users\buiph\AppData\Roaming\Python\Python312\site-packages\spherov2\controls\v2.py", line 62, in parse_response
    raise PacketDecodingException('Unexpected start of packet')
spherov2.controls.PacketDecodingException: Unexpected start of packet
2024-12-13 00:00:43,578 [ERROR] Exception in callback Toy.__api_read(<bleak.backen...0027DA1A9B2F0>)(bytearray(b'\...xc6f\xe7\xd8'))
handle: <Handle Toy.__api_read(<bleak.backen...0027DA1A9B2F0>)(bytearray(b'\...xc6f\xe7\xd8'))>
Traceback (most recent call last):
  File "C:\Python312\Lib\asyncio\events.py", line 88, in _run
    self._context.run(self._callback, *self._args)
  File "C:\Users\buiph\AppData\Roaming\Python\Python312\site-packages\spherov2\toy\__init__.py", line 106, in __api_read
    self.__decoder.add(data)
  File "C:\Users\buiph\AppData\Roaming\Python\Python312\site-packages\spherov2\controls\v2.py", line 174, in add
    self.__callback(Packet.parse_response(pkt))
                    ^^^^^^^^^^^^^^^^^^^^^^^^^^
  File "C:\Users\buiph\AppData\Roaming\Python\Python312\site-packages\spherov2\controls\v2.py", line 62, in parse_response
    raise PacketDecodingException('Unexpected start of packet')
spherov2.controls.PacketDecodingException: Unexpected start of packet
2024-12-13 00:00:43,574 [ERROR] Exception in callback Toy.__api_read(<bleak.backen...0014E7F43B620>)(bytearray(b'\xd6q\xd8'))
handle: <Handle Toy.__api_read(<bleak.backen...0014E7F43B620>)(bytearray(b'\xd6q\xd8'))>
Traceback (most recent call last):
  File "C:\Python312\Lib\asyncio\events.py", line 88, in _run
    self._context.run(self._callback, *self._args)
  File "C:\Users\buiph\AppData\Roaming\Python\Python312\site-packages\spherov2\toy\__init__.py", line 106, in __api_read
    self.__decoder.add(data)
  File "C:\Users\buiph\AppData\Roaming\Python\Python312\site-packages\spherov2\controls\v2.py", line 174, in add
    self.__callback(Packet.parse_response(pkt))
                    ^^^^^^^^^^^^^^^^^^^^^^^^^^
  File "C:\Users\buiph\AppData\Roaming\Python\Python312\site-packages\spherov2\controls\v2.py", line 67, in parse_response
    raise PacketDecodingException('Bad response checksum')
spherov2.controls.PacketDecodingException: Bad response checksum
2024-12-13 00:00:43,585 [ERROR] Exception in callback Toy.__api_read(<bleak.backen...0027DA1A9B2F0>)(bytearray(b'f\xd5\xd8'))
handle: <Handle Toy.__api_read(<bleak.backen...0027DA1A9B2F0>)(bytearray(b'f\xd5\xd8'))>
Traceback (most recent call last):
  File "C:\Python312\Lib\asyncio\events.py", line 88, in _run
    self._context.run(self._callback, *self._args)
  File "C:\Users\buiph\AppData\Roaming\Python\Python312\site-packages\spherov2\toy\__init__.py", line 106, in __api_read
    self.__decoder.add(data)
  File "C:\Users\buiph\AppData\Roaming\Python\Python312\site-packages\spherov2\controls\v2.py", line 174, in add
    self.__callback(Packet.parse_response(pkt))
                    ^^^^^^^^^^^^^^^^^^^^^^^^^^
  File "C:\Users\buiph\AppData\Roaming\Python\Python312\site-packages\spherov2\controls\v2.py", line 67, in parse_response
    raise PacketDecodingException('Bad response checksum')
spherov2.controls.PacketDecodingException: Bad response checksum
2024-12-13 00:00:43,585 [ERROR] Exception in callback Toy.__api_read(<bleak.backen...0014E7F43B620>)(bytearray(b'i...xc3\xd6<\xd8'))
handle: <Handle Toy.__api_read(<bleak.backen...0014E7F43B620>)(bytearray(b'i...xc3\xd6<\xd8'))>
Traceback (most recent call last):
  File "C:\Python312\Lib\asyncio\events.py", line 88, in _run
    self._context.run(self._callback, *self._args)
  File "C:\Users\buiph\AppData\Roaming\Python\Python312\site-packages\spherov2\toy\__init__.py", line 106, in __api_read
    self.__decoder.add(data)
  File "C:\Users\buiph\AppData\Roaming\Python\Python312\site-packages\spherov2\controls\v2.py", line 174, in add
    self.__callback(Packet.parse_response(pkt))
                    ^^^^^^^^^^^^^^^^^^^^^^^^^^
  File "C:\Users\buiph\AppData\Roaming\Python\Python312\site-packages\spherov2\controls\v2.py", line 62, in parse_response
    raise PacketDecodingException('Unexpected start of packet')
spherov2.controls.PacketDecodingException: Unexpected start of packet
2024-12-13 00:00:43,594 [ERROR] Exception in callback Toy.__api_read(<bleak.backen...0013DFF8CB380>)(bytearray(b'\x0e[\x85#\xd8'))
handle: <Handle Toy.__api_read(<bleak.backen...0013DFF8CB380>)(bytearray(b'\x0e[\x85#\xd8'))>
Traceback (most recent call last):
  File "C:\Python312\Lib\asyncio\events.py", line 88, in _run
    self._context.run(self._callback, *self._args)
  File "C:\Users\buiph\AppData\Roaming\Python\Python312\site-packages\spherov2\toy\__init__.py", line 106, in __api_read
    self.__decoder.add(data)
  File "C:\Users\buiph\AppData\Roaming\Python\Python312\site-packages\spherov2\controls\v2.py", line 174, in add
    self.__callback(Packet.parse_response(pkt))
                    ^^^^^^^^^^^^^^^^^^^^^^^^^^
  File "C:\Users\buiph\AppData\Roaming\Python\Python312\site-packages\spherov2\controls\v2.py", line 67, in parse_response
    raise PacketDecodingException('Bad response checksum')
spherov2.controls.PacketDecodingException: Bad response checksum
2024-12-13 00:00:43,640 [ERROR] Exception in callback Toy.__api_read(<bleak.backen...0013473486ED0>)(bytearray(b'#...xce\x14~\xd8'))
handle: <Handle Toy.__api_read(<bleak.backen...0013473486ED0>)(bytearray(b'#...xce\x14~\xd8'))>
Traceback (most recent call last):
  File "C:\Python312\Lib\asyncio\events.py", line 88, in _run
    self._context.run(self._callback, *self._args)
  File "C:\Users\buiph\AppData\Roaming\Python\Python312\site-packages\spherov2\toy\__init__.py", line 106, in __api_read
    self.__decoder.add(data)
  File "C:\Users\buiph\AppData\Roaming\Python\Python312\site-packages\spherov2\controls\v2.py", line 174, in add
    self.__callback(Packet.parse_response(pkt))
                    ^^^^^^^^^^^^^^^^^^^^^^^^^^
  File "C:\Users\buiph\AppData\Roaming\Python\Python312\site-packages\spherov2\controls\v2.py", line 67, in parse_response
    raise PacketDecodingException('Bad response checksum')
spherov2.controls.PacketDecodingException: Bad response checksum
2024-12-13 00:00:45,257 [ERROR] Exception in callback Toy.__api_read(<bleak.backen...0013DFF8CB380>)(bytearray(b'\xddp\n\xd8'))
handle: <Handle Toy.__api_read(<bleak.backen...0013DFF8CB380>)(bytearray(b'\xddp\n\xd8'))>
Traceback (most recent call last):
  File "C:\Python312\Lib\asyncio\events.py", line 88, in _run
    self._context.run(self._callback, *self._args)
  File "C:\Users\buiph\AppData\Roaming\Python\Python312\site-packages\spherov2\toy\__init__.py", line 106, in __api_read
    self.__decoder.add(data)
  File "C:\Users\buiph\AppData\Roaming\Python\Python312\site-packages\spherov2\controls\v2.py", line 174, in add
    self.__callback(Packet.parse_response(pkt))
                    ^^^^^^^^^^^^^^^^^^^^^^^^^^
  File "C:\Users\buiph\AppData\Roaming\Python\Python312\site-packages\spherov2\controls\v2.py", line 65, in parse_response
    *data, chk = Packet.__unescape_data(data)
                 ^^^^^^^^^^^^^^^^^^^^^^^^^^^^
  File "C:\Users\buiph\AppData\Roaming\Python\Python312\site-packages\spherov2\controls\v2.py", line 102, in __unescape_data
    raise PacketDecodingException('Unexpected escaping byte')
spherov2.controls.PacketDecodingException: Unexpected escaping byte
2024-12-13 00:00:45,268 [ERROR] Exception in callback Toy.__api_read(<bleak.backen...0027DA1A9B2F0>)(bytearray(b'fo\xd8'))
handle: <Handle Toy.__api_read(<bleak.backen...0027DA1A9B2F0>)(bytearray(b'fo\xd8'))>
Traceback (most recent call last):
  File "C:\Python312\Lib\asyncio\events.py", line 88, in _run
    self._context.run(self._callback, *self._args)
  File "C:\Users\buiph\AppData\Roaming\Python\Python312\site-packages\spherov2\toy\__init__.py", line 106, in __api_read
    self.__decoder.add(data)
  File "C:\Users\buiph\AppData\Roaming\Python\Python312\site-packages\spherov2\controls\v2.py", line 174, in add
    self.__callback(Packet.parse_response(pkt))
                    ^^^^^^^^^^^^^^^^^^^^^^^^^^
  File "C:\Users\buiph\AppData\Roaming\Python\Python312\site-packages\spherov2\controls\v2.py", line 67, in parse_response
    raise PacketDecodingException('Bad response checksum')
spherov2.controls.PacketDecodingException: Bad response checksum
2024-12-13 00:00:45,270 [ERROR] Exception in callback Toy.__api_read(<bleak.backen...0013DFF8CB380>)(bytearray(b'\\\xcc\x18\xd8'))
handle: <Handle Toy.__api_read(<bleak.backen...0013DFF8CB380>)(bytearray(b'\\\xcc\x18\xd8'))>
Traceback (most recent call last):
  File "C:\Python312\Lib\asyncio\events.py", line 88, in _run
    self._context.run(self._callback, *self._args)
  File "C:\Users\buiph\AppData\Roaming\Python\Python312\site-packages\spherov2\toy\__init__.py", line 106, in __api_read
    self.__decoder.add(data)
  File "C:\Users\buiph\AppData\Roaming\Python\Python312\site-packages\spherov2\controls\v2.py", line 174, in add
    self.__callback(Packet.parse_response(pkt))
                    ^^^^^^^^^^^^^^^^^^^^^^^^^^
  File "C:\Users\buiph\AppData\Roaming\Python\Python312\site-packages\spherov2\controls\v2.py", line 67, in parse_response
    raise PacketDecodingException('Bad response checksum')
spherov2.controls.PacketDecodingException: Bad response checksum
2024-12-13 00:00:45,265 [ERROR] Exception in callback Toy.__api_read(<bleak.backen...0014E7F43B620>)(bytearray(b'\xb5\xd8'))
handle: <Handle Toy.__api_read(<bleak.backen...0014E7F43B620>)(bytearray(b'\xb5\xd8'))>
Traceback (most recent call last):
  File "C:\Python312\Lib\asyncio\events.py", line 88, in _run
    self._context.run(self._callback, *self._args)
  File "C:\Users\buiph\AppData\Roaming\Python\Python312\site-packages\spherov2\toy\__init__.py", line 106, in __api_read
    self.__decoder.add(data)
  File "C:\Users\buiph\AppData\Roaming\Python\Python312\site-packages\spherov2\controls\v2.py", line 174, in add
    self.__callback(Packet.parse_response(pkt))
                    ^^^^^^^^^^^^^^^^^^^^^^^^^^
  File "C:\Users\buiph\AppData\Roaming\Python\Python312\site-packages\spherov2\controls\v2.py", line 67, in parse_response
    raise PacketDecodingException('Bad response checksum')
spherov2.controls.PacketDecodingException: Bad response checksum
2024-12-13 00:00:45,280 [ERROR] Exception in callback Toy.__api_read(<bleak.backen...0013473486ED0>)(bytearray(b'\xf5\xd8'))
handle: <Handle Toy.__api_read(<bleak.backen...0013473486ED0>)(bytearray(b'\xf5\xd8'))>
Traceback (most recent call last):
  File "C:\Python312\Lib\asyncio\events.py", line 88, in _run
    self._context.run(self._callback, *self._args)
  File "C:\Users\buiph\AppData\Roaming\Python\Python312\site-packages\spherov2\toy\__init__.py", line 106, in __api_read
    self.__decoder.add(data)
  File "C:\Users\buiph\AppData\Roaming\Python\Python312\site-packages\spherov2\controls\v2.py", line 174, in add
    self.__callback(Packet.parse_response(pkt))
                    ^^^^^^^^^^^^^^^^^^^^^^^^^^
  File "C:\Users\buiph\AppData\Roaming\Python\Python312\site-packages\spherov2\controls\v2.py", line 67, in parse_response
    raise PacketDecodingException('Bad response checksum')
spherov2.controls.PacketDecodingException: Bad response checksum
2024-12-13 00:00:45,323 [ERROR] Exception in callback Toy.__api_read(<bleak.backen...0013DFF8CB380>)(bytearray(b')\x7f\xd8'))
handle: <Handle Toy.__api_read(<bleak.backen...0013DFF8CB380>)(bytearray(b')\x7f\xd8'))>
Traceback (most recent call last):
  File "C:\Python312\Lib\asyncio\events.py", line 88, in _run
    self._context.run(self._callback, *self._args)
  File "C:\Users\buiph\AppData\Roaming\Python\Python312\site-packages\spherov2\toy\__init__.py", line 106, in __api_read
    self.__decoder.add(data)
  File "C:\Users\buiph\AppData\Roaming\Python\Python312\site-packages\spherov2\controls\v2.py", line 174, in add
    self.__callback(Packet.parse_response(pkt))
                    ^^^^^^^^^^^^^^^^^^^^^^^^^^
  File "C:\Users\buiph\AppData\Roaming\Python\Python312\site-packages\spherov2\controls\v2.py", line 62, in parse_response
    raise PacketDecodingException('Unexpected start of packet')
spherov2.controls.PacketDecodingException: Unexpected start of packet
2024-12-13 00:00:45,378 [ERROR] Exception in callback Toy.__api_read(<bleak.backen...0013473486ED0>)(bytearray(b'\x95\xd8'))
handle: <Handle Toy.__api_read(<bleak.backen...0013473486ED0>)(bytearray(b'\x95\xd8'))>
Traceback (most recent call last):
  File "C:\Python312\Lib\asyncio\events.py", line 88, in _run
    self._context.run(self._callback, *self._args)
  File "C:\Users\buiph\AppData\Roaming\Python\Python312\site-packages\spherov2\toy\__init__.py", line 106, in __api_read
    self.__decoder.add(data)
  File "C:\Users\buiph\AppData\Roaming\Python\Python312\site-packages\spherov2\controls\v2.py", line 174, in add
    self.__callback(Packet.parse_response(pkt))
                    ^^^^^^^^^^^^^^^^^^^^^^^^^^
  File "C:\Users\buiph\AppData\Roaming\Python\Python312\site-packages\spherov2\controls\v2.py", line 67, in parse_response
    raise PacketDecodingException('Bad response checksum')
spherov2.controls.PacketDecodingException: Bad response checksum
2024-12-13 00:00:46,512 [WARNING] SB-2E86: Sphero not found. Ensure it is powered on and in range. Retrying...
2024-12-13 00:00:55,573 [WARNING] SB-2E86: Sphero not found. Ensure it is powered on and in range. Retrying...
2024-12-13 00:01:04,628 [WARNING] SB-2E86: Sphero not found. Ensure it is powered on and in range. Retrying...
2024-12-13 00:01:13,673 [WARNING] SB-2E86: Sphero not found. Ensure it is powered on and in range. Retrying...
2024-12-13 00:01:22,707 [WARNING] SB-2E86: Sphero not found. Ensure it is powered on and in range. Retrying...
2024-12-13 00:01:31,752 [WARNING] SB-2E86: Sphero not found. Ensure it is powered on and in range. Retrying...
2024-12-13 00:01:40,807 [WARNING] SB-2E86: Sphero not found. Ensure it is powered on and in range. Retrying...
2024-12-13 00:01:49,860 [WARNING] SB-2E86: Sphero not found. Ensure it is powered on and in range. Retrying...
2024-12-13 00:01:58,909 [WARNING] SB-2E86: Sphero not found. Ensure it is powered on and in range. Retrying...
2024-12-13 00:02:07,950 [WARNING] SB-2E86: Sphero not found. Ensure it is powered on and in range. Retrying...
2024-12-13 00:02:13,856 [INFO] SB-2E86: Connected to Sphero.
2024-12-13 00:02:21,073 [ERROR] SB-2E86: Failed to initialize or maintain connection to Sphero: 
2024-12-13 00:02:21,073 [WARNING] SB-2E86: Sphero connection closed. Retrying...
2024-12-13 00:02:27,351 [INFO] SB-2E86: Connected to Sphero.
2024-12-13 00:02:33,483 [ERROR] SB-2E86: Failed to initialize or maintain connection to Sphero: 
2024-12-13 00:02:33,483 [WARNING] SB-2E86: Sphero connection closed. Retrying...
2024-12-13 00:02:41,290 [INFO] SB-2E86: Connected to Sphero.
2024-12-13 00:02:46,343 [ERROR] SB-2E86: Failed to initialize or maintain connection to Sphero: Device with address EA:80:A1:6E:2E:86 was not found.
2024-12-13 00:02:46,343 [WARNING] SB-2E86: Sphero connection closed. Retrying...
2024-12-13 00:02:55,524 [INFO] SB-2E86: Connected to Sphero.
2024-12-13 00:02:59,032 [INFO] SB-2E86: Calibrating compass.
2024-12-13 00:03:04,359 [INFO] SB-2E86: Initialization complete.
2024-12-13 00:03:04,360 [INFO] SB-2E86: Subscribed to message bus.
2024-12-13 00:07:47,432 [ERROR] Exception in callback Toy.__api_read(<bleak.backen...0013DFF8CB380>)(bytearray(b'C...\xcc\xcb\xd8'))
handle: <Handle Toy.__api_read(<bleak.backen...0013DFF8CB380>)(bytearray(b'C...\xcc\xcb\xd8'))>
Traceback (most recent call last):
  File "C:\Python312\Lib\asyncio\events.py", line 88, in _run
    self._context.run(self._callback, *self._args)
  File "C:\Users\buiph\AppData\Roaming\Python\Python312\site-packages\spherov2\toy\__init__.py", line 106, in __api_read
    self.__decoder.add(data)
  File "C:\Users\buiph\AppData\Roaming\Python\Python312\site-packages\spherov2\controls\v2.py", line 174, in add
    self.__callback(Packet.parse_response(pkt))
                    ^^^^^^^^^^^^^^^^^^^^^^^^^^
  File "C:\Users\buiph\AppData\Roaming\Python\Python312\site-packages\spherov2\controls\v2.py", line 67, in parse_response
    raise PacketDecodingException('Bad response checksum')
spherov2.controls.PacketDecodingException: Bad response checksum
2024-12-13 00:07:47,456 [ERROR] Exception in callback Toy.__api_read(<bleak.backen...002505091BD40>)(bytearray(b'\xdc\xd8'))
handle: <Handle Toy.__api_read(<bleak.backen...002505091BD40>)(bytearray(b'\xdc\xd8'))>
Traceback (most recent call last):
  File "C:\Python312\Lib\asyncio\events.py", line 88, in _run
    self._context.run(self._callback, *self._args)
  File "C:\Users\buiph\AppData\Roaming\Python\Python312\site-packages\spherov2\toy\__init__.py", line 106, in __api_read
    self.__decoder.add(data)
  File "C:\Users\buiph\AppData\Roaming\Python\Python312\site-packages\spherov2\controls\v2.py", line 174, in add
    self.__callback(Packet.parse_response(pkt))
                    ^^^^^^^^^^^^^^^^^^^^^^^^^^
  File "C:\Users\buiph\AppData\Roaming\Python\Python312\site-packages\spherov2\controls\v2.py", line 62, in parse_response
    raise PacketDecodingException('Unexpected start of packet')
spherov2.controls.PacketDecodingException: Unexpected start of packet
2024-12-13 00:07:47,529 [ERROR] Exception in callback Toy.__api_read(<bleak.backen...0013473486ED0>)(bytearray(b'\\`\xd8'))
handle: <Handle Toy.__api_read(<bleak.backen...0013473486ED0>)(bytearray(b'\\`\xd8'))>
Traceback (most recent call last):
  File "C:\Python312\Lib\asyncio\events.py", line 88, in _run
    self._context.run(self._callback, *self._args)
  File "C:\Users\buiph\AppData\Roaming\Python\Python312\site-packages\spherov2\toy\__init__.py", line 106, in __api_read
    self.__decoder.add(data)
  File "C:\Users\buiph\AppData\Roaming\Python\Python312\site-packages\spherov2\controls\v2.py", line 174, in add
    self.__callback(Packet.parse_response(pkt))
                    ^^^^^^^^^^^^^^^^^^^^^^^^^^
  File "C:\Users\buiph\AppData\Roaming\Python\Python312\site-packages\spherov2\controls\v2.py", line 67, in parse_response
    raise PacketDecodingException('Bad response checksum')
spherov2.controls.PacketDecodingException: Bad response checksum
2024-12-13 00:07:47,549 [ERROR] Exception in callback Toy.__api_read(<bleak.backen...0027DA1A9B2F0>)(bytearray(b'\x9b\xd8'))
handle: <Handle Toy.__api_read(<bleak.backen...0027DA1A9B2F0>)(bytearray(b'\x9b\xd8'))>
Traceback (most recent call last):
  File "C:\Python312\Lib\asyncio\events.py", line 88, in _run
    self._context.run(self._callback, *self._args)
  File "C:\Users\buiph\AppData\Roaming\Python\Python312\site-packages\spherov2\toy\__init__.py", line 106, in __api_read
    self.__decoder.add(data)
  File "C:\Users\buiph\AppData\Roaming\Python\Python312\site-packages\spherov2\controls\v2.py", line 174, in add
    self.__callback(Packet.parse_response(pkt))
                    ^^^^^^^^^^^^^^^^^^^^^^^^^^
  File "C:\Users\buiph\AppData\Roaming\Python\Python312\site-packages\spherov2\controls\v2.py", line 67, in parse_response
    raise PacketDecodingException('Bad response checksum')
spherov2.controls.PacketDecodingException: Bad response checksum
2024-12-13 00:07:47,738 [ERROR] Exception in callback Toy.__api_read(<bleak.backen...002505091BD40>)(bytearray(b'\x04\xd8'))
handle: <Handle Toy.__api_read(<bleak.backen...002505091BD40>)(bytearray(b'\x04\xd8'))>
Traceback (most recent call last):
  File "C:\Python312\Lib\asyncio\events.py", line 88, in _run
    self._context.run(self._callback, *self._args)
  File "C:\Users\buiph\AppData\Roaming\Python\Python312\site-packages\spherov2\toy\__init__.py", line 106, in __api_read
    self.__decoder.add(data)
  File "C:\Users\buiph\AppData\Roaming\Python\Python312\site-packages\spherov2\controls\v2.py", line 174, in add
    self.__callback(Packet.parse_response(pkt))
                    ^^^^^^^^^^^^^^^^^^^^^^^^^^
  File "C:\Users\buiph\AppData\Roaming\Python\Python312\site-packages\spherov2\controls\v2.py", line 67, in parse_response
    raise PacketDecodingException('Bad response checksum')
spherov2.controls.PacketDecodingException: Bad response checksum
2024-12-13 00:07:47,787 [ERROR] Exception in callback Toy.__api_read(<bleak.backen...0013DFF8CB380>)(bytearray(b'C...\xcc\xd3\xd8'))
handle: <Handle Toy.__api_read(<bleak.backen...0013DFF8CB380>)(bytearray(b'C...\xcc\xd3\xd8'))>
Traceback (most recent call last):
  File "C:\Python312\Lib\asyncio\events.py", line 88, in _run
    self._context.run(self._callback, *self._args)
  File "C:\Users\buiph\AppData\Roaming\Python\Python312\site-packages\spherov2\toy\__init__.py", line 106, in __api_read
    self.__decoder.add(data)
  File "C:\Users\buiph\AppData\Roaming\Python\Python312\site-packages\spherov2\controls\v2.py", line 174, in add
    self.__callback(Packet.parse_response(pkt))
                    ^^^^^^^^^^^^^^^^^^^^^^^^^^
  File "C:\Users\buiph\AppData\Roaming\Python\Python312\site-packages\spherov2\controls\v2.py", line 62, in parse_response
    raise PacketDecodingException('Unexpected start of packet')
spherov2.controls.PacketDecodingException: Unexpected start of packet
2024-12-13 00:07:47,875 [ERROR] Exception in callback Toy.__api_read(<bleak.backen...0014E7F43B620>)(bytearray(b'&\xd8'))
handle: <Handle Toy.__api_read(<bleak.backen...0014E7F43B620>)(bytearray(b'&\xd8'))>
Traceback (most recent call last):
  File "C:\Python312\Lib\asyncio\events.py", line 88, in _run
    self._context.run(self._callback, *self._args)
  File "C:\Users\buiph\AppData\Roaming\Python\Python312\site-packages\spherov2\toy\__init__.py", line 106, in __api_read
    self.__decoder.add(data)
  File "C:\Users\buiph\AppData\Roaming\Python\Python312\site-packages\spherov2\controls\v2.py", line 174, in add
    self.__callback(Packet.parse_response(pkt))
                    ^^^^^^^^^^^^^^^^^^^^^^^^^^
  File "C:\Users\buiph\AppData\Roaming\Python\Python312\site-packages\spherov2\controls\v2.py", line 62, in parse_response
    raise PacketDecodingException('Unexpected start of packet')
spherov2.controls.PacketDecodingException: Unexpected start of packet
2024-12-13 00:07:47,968 [ERROR] Exception in callback Toy.__api_read(<bleak.backen...0027DA1A9B2F0>)(bytearray(b'\x93\xd8'))
handle: <Handle Toy.__api_read(<bleak.backen...0027DA1A9B2F0>)(bytearray(b'\x93\xd8'))>
Traceback (most recent call last):
  File "C:\Python312\Lib\asyncio\events.py", line 88, in _run
    self._context.run(self._callback, *self._args)
  File "C:\Users\buiph\AppData\Roaming\Python\Python312\site-packages\spherov2\toy\__init__.py", line 106, in __api_read
    self.__decoder.add(data)
  File "C:\Users\buiph\AppData\Roaming\Python\Python312\site-packages\spherov2\controls\v2.py", line 174, in add
    self.__callback(Packet.parse_response(pkt))
                    ^^^^^^^^^^^^^^^^^^^^^^^^^^
  File "C:\Users\buiph\AppData\Roaming\Python\Python312\site-packages\spherov2\controls\v2.py", line 67, in parse_response
    raise PacketDecodingException('Bad response checksum')
spherov2.controls.PacketDecodingException: Bad response checksum
2024-12-13 00:07:48,063 [ERROR] Exception in callback Toy.__api_read(<bleak.backen...0014E7F43B620>)(bytearray(b'%\xd8'))
handle: <Handle Toy.__api_read(<bleak.backen...0014E7F43B620>)(bytearray(b'%\xd8'))>
Traceback (most recent call last):
  File "C:\Python312\Lib\asyncio\events.py", line 88, in _run
    self._context.run(self._callback, *self._args)
  File "C:\Users\buiph\AppData\Roaming\Python\Python312\site-packages\spherov2\toy\__init__.py", line 106, in __api_read
    self.__decoder.add(data)
  File "C:\Users\buiph\AppData\Roaming\Python\Python312\site-packages\spherov2\controls\v2.py", line 174, in add
    self.__callback(Packet.parse_response(pkt))
                    ^^^^^^^^^^^^^^^^^^^^^^^^^^
  File "C:\Users\buiph\AppData\Roaming\Python\Python312\site-packages\spherov2\controls\v2.py", line 62, in parse_response
    raise PacketDecodingException('Unexpected start of packet')
spherov2.controls.PacketDecodingException: Unexpected start of packet
2024-12-13 00:07:48,094 [ERROR] Exception in callback Toy.__api_read(<bleak.backen...002505091BD40>)(bytearray(b'\xba\xd8'))
handle: <Handle Toy.__api_read(<bleak.backen...002505091BD40>)(bytearray(b'\xba\xd8'))>
Traceback (most recent call last):
  File "C:\Python312\Lib\asyncio\events.py", line 88, in _run
    self._context.run(self._callback, *self._args)
  File "C:\Users\buiph\AppData\Roaming\Python\Python312\site-packages\spherov2\toy\__init__.py", line 106, in __api_read
    self.__decoder.add(data)
  File "C:\Users\buiph\AppData\Roaming\Python\Python312\site-packages\spherov2\controls\v2.py", line 174, in add
    self.__callback(Packet.parse_response(pkt))
                    ^^^^^^^^^^^^^^^^^^^^^^^^^^
  File "C:\Users\buiph\AppData\Roaming\Python\Python312\site-packages\spherov2\controls\v2.py", line 62, in parse_response
    raise PacketDecodingException('Unexpected start of packet')
spherov2.controls.PacketDecodingException: Unexpected start of packet
2024-12-13 00:07:48,151 [ERROR] Exception in callback Toy.__api_read(<bleak.backen...0013DFF8CB380>)(bytearray(b'\xddp\xc6\xd8'))
handle: <Handle Toy.__api_read(<bleak.backen...0013DFF8CB380>)(bytearray(b'\xddp\xc6\xd8'))>
Traceback (most recent call last):
  File "C:\Python312\Lib\asyncio\events.py", line 88, in _run
    self._context.run(self._callback, *self._args)
  File "C:\Users\buiph\AppData\Roaming\Python\Python312\site-packages\spherov2\toy\__init__.py", line 106, in __api_read
    self.__decoder.add(data)
  File "C:\Users\buiph\AppData\Roaming\Python\Python312\site-packages\spherov2\controls\v2.py", line 174, in add
    self.__callback(Packet.parse_response(pkt))
                    ^^^^^^^^^^^^^^^^^^^^^^^^^^
  File "C:\Users\buiph\AppData\Roaming\Python\Python312\site-packages\spherov2\controls\v2.py", line 67, in parse_response
    raise PacketDecodingException('Bad response checksum')
spherov2.controls.PacketDecodingException: Bad response checksum
2024-12-13 00:07:48,158 [ERROR] Exception in callback Toy.__api_read(<bleak.backen...0027DA1A9B2F0>)(bytearray(b'g\xd8'))
handle: <Handle Toy.__api_read(<bleak.backen...0027DA1A9B2F0>)(bytearray(b'g\xd8'))>
Traceback (most recent call last):
  File "C:\Python312\Lib\asyncio\events.py", line 88, in _run
    self._context.run(self._callback, *self._args)
  File "C:\Users\buiph\AppData\Roaming\Python\Python312\site-packages\spherov2\toy\__init__.py", line 106, in __api_read
    self.__decoder.add(data)
  File "C:\Users\buiph\AppData\Roaming\Python\Python312\site-packages\spherov2\controls\v2.py", line 174, in add
    self.__callback(Packet.parse_response(pkt))
                    ^^^^^^^^^^^^^^^^^^^^^^^^^^
  File "C:\Users\buiph\AppData\Roaming\Python\Python312\site-packages\spherov2\controls\v2.py", line 62, in parse_response
    raise PacketDecodingException('Unexpected start of packet')
spherov2.controls.PacketDecodingException: Unexpected start of packet
2024-12-13 00:07:48,167 [ERROR] Exception in callback Toy.__api_read(<bleak.backen...0014E7F43B620>)(bytearray(b'r...xc2\x8f,\xd8'))
handle: <Handle Toy.__api_read(<bleak.backen...0014E7F43B620>)(bytearray(b'r...xc2\x8f,\xd8'))>
Traceback (most recent call last):
  File "C:\Python312\Lib\asyncio\events.py", line 88, in _run
    self._context.run(self._callback, *self._args)
  File "C:\Users\buiph\AppData\Roaming\Python\Python312\site-packages\spherov2\toy\__init__.py", line 106, in __api_read
    self.__decoder.add(data)
  File "C:\Users\buiph\AppData\Roaming\Python\Python312\site-packages\spherov2\controls\v2.py", line 174, in add
    self.__callback(Packet.parse_response(pkt))
                    ^^^^^^^^^^^^^^^^^^^^^^^^^^
  File "C:\Users\buiph\AppData\Roaming\Python\Python312\site-packages\spherov2\controls\v2.py", line 67, in parse_response
    raise PacketDecodingException('Bad response checksum')
spherov2.controls.PacketDecodingException: Bad response checksum
2024-12-13 00:07:48,269 [ERROR] Exception in callback Toy.__api_read(<bleak.backen...0013473486ED0>)(bytearray(b'\...d\xcf\\+\xd8'))
handle: <Handle Toy.__api_read(<bleak.backen...0013473486ED0>)(bytearray(b'\...d\xcf\\+\xd8'))>
Traceback (most recent call last):
  File "C:\Python312\Lib\asyncio\events.py", line 88, in _run
    self._context.run(self._callback, *self._args)
  File "C:\Users\buiph\AppData\Roaming\Python\Python312\site-packages\spherov2\toy\__init__.py", line 106, in __api_read
    self.__decoder.add(data)
  File "C:\Users\buiph\AppData\Roaming\Python\Python312\site-packages\spherov2\controls\v2.py", line 174, in add
    self.__callback(Packet.parse_response(pkt))
                    ^^^^^^^^^^^^^^^^^^^^^^^^^^
  File "C:\Users\buiph\AppData\Roaming\Python\Python312\site-packages\spherov2\controls\v2.py", line 67, in parse_response
    raise PacketDecodingException('Bad response checksum')
spherov2.controls.PacketDecodingException: Bad response checksum
2024-12-13 00:07:48,300 [ERROR] Exception in callback Toy.__api_read(<bleak.backen...002505091BD40>)(bytearray(b'\xe1\x11\xd8'))
handle: <Handle Toy.__api_read(<bleak.backen...002505091BD40>)(bytearray(b'\xe1\x11\xd8'))>
Traceback (most recent call last):
  File "C:\Python312\Lib\asyncio\events.py", line 88, in _run
    self._context.run(self._callback, *self._args)
  File "C:\Users\buiph\AppData\Roaming\Python\Python312\site-packages\spherov2\toy\__init__.py", line 106, in __api_read
    self.__decoder.add(data)
  File "C:\Users\buiph\AppData\Roaming\Python\Python312\site-packages\spherov2\controls\v2.py", line 174, in add
    self.__callback(Packet.parse_response(pkt))
                    ^^^^^^^^^^^^^^^^^^^^^^^^^^
  File "C:\Users\buiph\AppData\Roaming\Python\Python312\site-packages\spherov2\controls\v2.py", line 67, in parse_response
    raise PacketDecodingException('Bad response checksum')
spherov2.controls.PacketDecodingException: Bad response checksum
2024-12-13 00:08:18,472 [ERROR] Exception in callback Toy.__api_read(<bleak.backen...0013473486ED0>)(bytearray(b'\\\xba\xd8'))
handle: <Handle Toy.__api_read(<bleak.backen...0013473486ED0>)(bytearray(b'\\\xba\xd8'))>
Traceback (most recent call last):
  File "C:\Python312\Lib\asyncio\events.py", line 88, in _run
    self._context.run(self._callback, *self._args)
  File "C:\Users\buiph\AppData\Roaming\Python\Python312\site-packages\spherov2\toy\__init__.py", line 106, in __api_read
    self.__decoder.add(data)
  File "C:\Users\buiph\AppData\Roaming\Python\Python312\site-packages\spherov2\controls\v2.py", line 174, in add
    self.__callback(Packet.parse_response(pkt))
                    ^^^^^^^^^^^^^^^^^^^^^^^^^^
  File "C:\Users\buiph\AppData\Roaming\Python\Python312\site-packages\spherov2\controls\v2.py", line 67, in parse_response
    raise PacketDecodingException('Bad response checksum')
spherov2.controls.PacketDecodingException: Bad response checksum
2024-12-13 00:08:18,502 [ERROR] Exception in callback Toy.__api_read(<bleak.backen...0013473486ED0>)(bytearray(b'\xa1\xd8'))
handle: <Handle Toy.__api_read(<bleak.backen...0013473486ED0>)(bytearray(b'\xa1\xd8'))>
Traceback (most recent call last):
  File "C:\Python312\Lib\asyncio\events.py", line 88, in _run
    self._context.run(self._callback, *self._args)
  File "C:\Users\buiph\AppData\Roaming\Python\Python312\site-packages\spherov2\toy\__init__.py", line 106, in __api_read
    self.__decoder.add(data)
  File "C:\Users\buiph\AppData\Roaming\Python\Python312\site-packages\spherov2\controls\v2.py", line 174, in add
    self.__callback(Packet.parse_response(pkt))
                    ^^^^^^^^^^^^^^^^^^^^^^^^^^
  File "C:\Users\buiph\AppData\Roaming\Python\Python312\site-packages\spherov2\controls\v2.py", line 67, in parse_response
    raise PacketDecodingException('Bad response checksum')
spherov2.controls.PacketDecodingException: Bad response checksum
2024-12-13 00:08:18,503 [ERROR] Exception in callback Toy.__api_read(<bleak.backen...0014E7F43B620>)(bytearray(b'\x19\xd8'))
handle: <Handle Toy.__api_read(<bleak.backen...0014E7F43B620>)(bytearray(b'\x19\xd8'))>
Traceback (most recent call last):
  File "C:\Python312\Lib\asyncio\events.py", line 88, in _run
    self._context.run(self._callback, *self._args)
  File "C:\Users\buiph\AppData\Roaming\Python\Python312\site-packages\spherov2\toy\__init__.py", line 106, in __api_read
    self.__decoder.add(data)
  File "C:\Users\buiph\AppData\Roaming\Python\Python312\site-packages\spherov2\controls\v2.py", line 173, in add
    raise PacketDecodingException(f'Very small packet {[hex(x) for x in pkt]}')
spherov2.controls.PacketDecodingException: Very small packet ['0xff', '0x2', '0x19', '0xd8']
2024-12-13 00:08:18,505 [ERROR] Exception in callback Toy.__api_read(<bleak.backen...0013DFF8CB380>)(bytearray(b'\xddp\xb0\xd8'))
handle: <Handle Toy.__api_read(<bleak.backen...0013DFF8CB380>)(bytearray(b'\xddp\xb0\xd8'))>
Traceback (most recent call last):
  File "C:\Python312\Lib\asyncio\events.py", line 88, in _run
    self._context.run(self._callback, *self._args)
  File "C:\Users\buiph\AppData\Roaming\Python\Python312\site-packages\spherov2\toy\__init__.py", line 106, in __api_read
    self.__decoder.add(data)
  File "C:\Users\buiph\AppData\Roaming\Python\Python312\site-packages\spherov2\controls\v2.py", line 174, in add
    self.__callback(Packet.parse_response(pkt))
                    ^^^^^^^^^^^^^^^^^^^^^^^^^^
  File "C:\Users\buiph\AppData\Roaming\Python\Python312\site-packages\spherov2\controls\v2.py", line 67, in parse_response
    raise PacketDecodingException('Bad response checksum')
spherov2.controls.PacketDecodingException: Bad response checksum
2024-12-13 00:08:18,509 [ERROR] Exception in callback Toy.__api_read(<bleak.backen...0027DA1A9B2F0>)(bytearray(b'\...xc6f\x88\xd8'))
handle: <Handle Toy.__api_read(<bleak.backen...0027DA1A9B2F0>)(bytearray(b'\...xc6f\x88\xd8'))>
Traceback (most recent call last):
  File "C:\Python312\Lib\asyncio\events.py", line 88, in _run
    self._context.run(self._callback, *self._args)
  File "C:\Users\buiph\AppData\Roaming\Python\Python312\site-packages\spherov2\toy\__init__.py", line 106, in __api_read
    self.__decoder.add(data)
  File "C:\Users\buiph\AppData\Roaming\Python\Python312\site-packages\spherov2\controls\v2.py", line 174, in add
    self.__callback(Packet.parse_response(pkt))
                    ^^^^^^^^^^^^^^^^^^^^^^^^^^
  File "C:\Users\buiph\AppData\Roaming\Python\Python312\site-packages\spherov2\controls\v2.py", line 67, in parse_response
    raise PacketDecodingException('Bad response checksum')
spherov2.controls.PacketDecodingException: Bad response checksum
2024-12-13 00:08:18,578 [ERROR] Exception in callback Toy.__api_read(<bleak.backen...002505091BD40>)(bytearray(b'\xe1\xa2\xd8'))
handle: <Handle Toy.__api_read(<bleak.backen...002505091BD40>)(bytearray(b'\xe1\xa2\xd8'))>
Traceback (most recent call last):
  File "C:\Python312\Lib\asyncio\events.py", line 88, in _run
    self._context.run(self._callback, *self._args)
  File "C:\Users\buiph\AppData\Roaming\Python\Python312\site-packages\spherov2\toy\__init__.py", line 106, in __api_read
    self.__decoder.add(data)
  File "C:\Users\buiph\AppData\Roaming\Python\Python312\site-packages\spherov2\controls\v2.py", line 174, in add
    self.__callback(Packet.parse_response(pkt))
                    ^^^^^^^^^^^^^^^^^^^^^^^^^^
  File "C:\Users\buiph\AppData\Roaming\Python\Python312\site-packages\spherov2\controls\v2.py", line 67, in parse_response
    raise PacketDecodingException('Bad response checksum')
spherov2.controls.PacketDecodingException: Bad response checksum
2024-12-13 05:08:59,698 [INFO] SB-2E86: Attempting to connect.
2024-12-13 05:09:01,666 [INFO] SB-2E86: Connected to Sphero.
2024-12-13 05:09:03,728 [INFO] SB-4844: Attempting to connect.
2024-12-13 05:09:03,789 [ERROR] WebSocket Sender: Connection error: [WinError 1225] The remote computer refused the network connection
2024-12-13 05:09:03,790 [WARNING] WebSocket Sender: Closing connection.
2024-12-13 05:09:03,789 [ERROR] WebSocket: Connection error: [WinError 1225] The remote computer refused the network connection
2024-12-13 05:09:03,791 [WARNING] WebSocket: Closing connection.
2024-12-13 05:09:04,098 [INFO] SB-4844: Connected to Sphero.
2024-12-13 05:09:06,838 [INFO] SB-2E86: Calibrating compass.
2024-12-13 05:09:07,722 [INFO] SB-7104: Attempting to connect.
2024-12-13 05:09:08,206 [INFO] SB-4844: Calibrating compass.
2024-12-13 05:09:08,712 [INFO] SB-7104: Connected to Sphero.
2024-12-13 05:09:11,760 [INFO] SB-D8B2: Attempting to connect.
2024-12-13 05:09:12,165 [INFO] SB-2E86: Initialization complete.
2024-12-13 05:09:12,166 [INFO] SB-2E86: Subscribed to message bus.
2024-12-13 05:09:13,616 [INFO] SB-4844: Initialization complete.
2024-12-13 05:09:13,616 [INFO] SB-4844: Subscribed to message bus.
2024-12-13 05:09:15,166 [INFO] SB-D8B2: Connected to Sphero.
2024-12-13 05:09:15,772 [INFO] SB-E12C: Attempting to connect.
2024-12-13 05:09:16,485 [INFO] SB-E12C: Connected to Sphero.
2024-12-13 05:09:16,580 [INFO] SB-7104: Calibrating compass.
2024-12-13 05:09:19,383 [INFO] Main: All processes started.
2024-12-13 05:09:21,517 [ERROR] SB-E12C: Failed to initialize or maintain connection to Sphero: Device with address F2:91:F9:86:E1:2C was not found.
2024-12-13 05:09:21,517 [WARNING] SB-E12C: Sphero connection closed. Retrying...
2024-12-13 05:09:21,917 [INFO] SB-7104: Initialization complete.
2024-12-13 05:09:21,918 [INFO] SB-7104: Subscribed to message bus.
2024-12-13 05:09:22,253 [INFO] SB-D8B2: Calibrating compass.
2024-12-13 05:09:27,518 [INFO] SB-D8B2: Initialization complete.
2024-12-13 05:09:27,518 [INFO] SB-D8B2: Subscribed to message bus.
2024-12-13 05:09:30,014 [INFO] SB-E12C: Connected to Sphero.
2024-12-13 05:09:35,397 [ERROR] SB-E12C: Failed to initialize or maintain connection to Sphero: 
2024-12-13 05:09:35,398 [WARNING] SB-E12C: Sphero connection closed. Retrying...
2024-12-13 05:09:45,436 [WARNING] SB-E12C: Sphero not found. Ensure it is powered on and in range. Retrying...
2024-12-13 05:09:51,725 [INFO] SB-E12C: Connected to Sphero.
2024-12-13 05:09:57,204 [INFO] SB-E12C: Calibrating compass.
2024-12-13 05:10:03,092 [INFO] SB-E12C: Initialization complete.
2024-12-13 05:10:03,095 [INFO] SB-E12C: Subscribed to message bus.
2024-12-13 05:48:46,686 [INFO] SB-7104: Attempting to connect.
2024-12-13 05:48:50,354 [INFO] SB-D8B2: Attempting to connect.
2024-12-13 05:48:50,771 [ERROR] WebSocket Sender: Connection error: [WinError 1225] The remote computer refused the network connection
2024-12-13 05:48:50,771 [ERROR] WebSocket: Connection error: [WinError 1225] The remote computer refused the network connection
2024-12-13 05:48:50,771 [WARNING] WebSocket Sender: Closing connection.
2024-12-13 05:48:50,771 [WARNING] WebSocket: Closing connection.
2024-12-13 05:48:51,936 [WARNING] SB-7104: Sphero not found. Ensure it is powered on and in range. Retrying...
2024-12-13 05:48:54,071 [INFO] Main: All processes started.
2024-12-13 05:48:54,464 [INFO] SB-D8B2: Connected to Sphero.
2024-12-13 05:48:57,521 [INFO] SB-7104: Connected to Sphero.
2024-12-13 05:48:58,462 [INFO] SB-D8B2: Calibrating compass.
2024-12-13 05:49:01,508 [INFO] SB-7104: Calibrating compass.
2024-12-13 05:49:03,769 [INFO] SB-D8B2: Initialization complete.
2024-12-13 05:49:03,770 [INFO] SB-D8B2: Subscribed to message bus.
2024-12-13 05:49:06,874 [INFO] SB-7104: Initialization complete.
2024-12-13 05:49:06,874 [INFO] SB-7104: Subscribed to message bus.
2024-12-13 06:02:25,962 [INFO] SB-7104: Attempting to connect.
2024-12-13 06:02:29,934 [INFO] SB-D8B2: Attempting to connect.
2024-12-13 06:02:30,058 [ERROR] WebSocket: Connection error: [WinError 1225] The remote computer refused the network connection
2024-12-13 06:02:30,058 [WARNING] WebSocket: Closing connection.
2024-12-13 06:02:30,074 [ERROR] WebSocket Sender: Connection error: [WinError 1225] The remote computer refused the network connection
2024-12-13 06:02:30,074 [WARNING] WebSocket Sender: Closing connection.
2024-12-13 06:02:31,067 [WARNING] SB-7104: Sphero not found. Ensure it is powered on and in range. Retrying...
2024-12-13 06:02:33,656 [INFO] Main: All processes started.
2024-12-13 06:02:34,536 [INFO] SB-D8B2: Connected to Sphero.
2024-12-13 06:02:38,549 [INFO] SB-D8B2: Calibrating compass.
2024-12-13 06:02:39,659 [INFO] SB-7104: Connected to Sphero.
2024-12-13 06:02:43,696 [INFO] SB-7104: Calibrating compass.
2024-12-13 06:02:43,963 [INFO] SB-D8B2: Initialization complete.
2024-12-13 06:02:43,963 [INFO] SB-D8B2: Subscribed to message bus.
2024-12-13 06:02:49,124 [INFO] SB-7104: Initialization complete.
2024-12-13 06:02:49,125 [INFO] SB-7104: Subscribed to message bus.
